Workbook
Name _: #REF!
Name _: #REF!
Name _: #REF!
Name _: #REF!
Name _: #REF!
Name _: #REF!
Name _1: '[5]1ST'!#REF!
Name _1: '[5]1ST'!#REF!
Name _1: '[5]1ST'!#REF!
Name _1: '[5]1ST'!#REF!
Name _1: '[5]1ST'!#REF!
Name _1: '[5]1ST'!#REF!
Name _15A: [6]금액내역서!$D$3:$D$10
Name _1차_94년: #N/A
Name _2차결제일: #N/A
Name _CVC2: [7]!StartSeller
Name _CVC2: [7]!StartSeller
Name _CVC2: [7]!StartSeller
Name _CVC2: [7]!StartSeller
Name _CVC2: [7]!StartSeller
Name _CVC2: [7]!StartSeller
Name _jak10: [7]!_xlbgnm.jak10
Name _jak10: [7]!_xlbgnm.jak10
Name _jak10: [7]!_xlbgnm.jak10
Name _jak10: [7]!_xlbgnm.jak10
Name _jak10: [7]!_xlbgnm.jak10
Name _jak10: [7]!_xlbgnm.jak10
Name _jak11: [7]!_xlbgnm.jak11
Name _jak11: [7]!_xlbgnm.jak11
Name _jak11: [7]!_xlbgnm.jak11
Name _jak11: [7]!_xlbgnm.jak11
Name _jak11: [7]!_xlbgnm.jak11
Name _jak11: [7]!_xlbgnm.jak11
Name _jak12: [7]!_xlbgnm.jak12
Name _jak12: [7]!_xlbgnm.jak12
Name _jak12: [7]!_xlbgnm.jak12
Name _jak12: [7]!_xlbgnm.jak12
Name _jak12: [7]!_xlbgnm.jak12
Name _jak12: [7]!_xlbgnm.jak12
Name _jak13: [7]!_xlbgnm.jak13
Name _jak13: [7]!_xlbgnm.jak13
Name _jak13: [7]!_xlbgnm.jak13
Name _jak13: [7]!_xlbgnm.jak13
Name _jak13: [7]!_xlbgnm.jak13
Name _jak13: [7]!_xlbgnm.jak13
Name _jak2: [7]!_xlbgnm.jak2
Name _jak2: [7]!_xlbgnm.jak2
Name _jak2: [7]!_xlbgnm.jak2
Name _jak2: [7]!_xlbgnm.jak2
Name _jak2: [7]!_xlbgnm.jak2
Name _jak2: [7]!_xlbgnm.jak2
Name _jak3: [7]!_xlbgnm.jak3
Name _jak3: [7]!_xlbgnm.jak3
Name _jak3: [7]!_xlbgnm.jak3
Name _jak3: [7]!_xlbgnm.jak3
Name _jak3: [7]!_xlbgnm.jak3
Name _jak3: [7]!_xlbgnm.jak3
Name _jak4: [7]!_xlbgnm.jak4
Name _jak4: [7]!_xlbgnm.jak4
Name _jak4: [7]!_xlbgnm.jak4

Sheet 수요시뮬레이션
X2: □ 수요 시뮬레이션
AH3: □ 관심고객 List
X4: 구분 | Y4: 기준면 | Z4: 2면 | AA4: 3면 | AB4: 4면 | AC4: 5~10면 | AD4: 11~30면 | AE4: 31~50면 | AF4: 계 | AH4: 잠재고객 | AI4: 보유면수
X5: 시장 추정* | Y5: 관심고객수 | Z5: 1 | AA5: 2 | AB5: 3 | AC5: 10 | AD5: 3 | AE5: 4 | AF5: =SUM(Z5:AE5) -> 23 | AH5: 신한은행 | AI5: 80
Z6: =Z5/$AF$5 -> 0.043478261 | AA6: =AA5/$AF$5 -> 0.086956522 | AB6: =AB5/$AF$5 -> 0.13043478 | AC6: =AC5/$AF$5 -> 0.43478261 | AD6: =AD5/$AF$5 -> 0.13043478 | AE6: =AE5/$AF$5 -> 0.17391304 | AF6: =SUM(Z6:AE6) -> 1 | AH6: WTC | AI6: 50
Y7: 관심고객보유면수 | Z7: 2 | AA7: 6 | AB7: 12 | AC7: 84 | AD7: 73 | AE7: 218 | AF7: =SUM(Z7:AE7) -> 395 | AH7: 오창에너지솔루션 | AI7: 50
Z8: =Z7/$AF$7 -> 0.0050632911 | AA8: =AA7/$AF$7 -> 0.015189873 | AB8: =AB7/$AF$7 -> 0.030379747 | AC8: =AC7/$AF$7 -> 0.21265823 | AD8: =AD7/$AF$7 -> 0.18481013 | AE8: =AE7/$AF$7 -> 0.55189873 | AF8: =SUM(Z8:AE8) -> 1 | AH8: BIFC | AI8: 38
X9: 목표 추정** | Y9: 판매목표면수(a) | Z9: =ROUND(Z10*$AF$9,0) -> 12 | AA9: =ROUND(AA10*$AF$9,0) -> 26 | AB9: =ROUND(AB10*$AF$9,0) -> 40 | AC9: =ROUND(AC10*$AF$9,0) -> 162 | AD9: =ROUND(AD10*$AF$9,0) -> 79 | AE9: =ROUND(AE10*$AF$9,0) -> 181 | AF9: 500 | AH9: 한국타이어테크노링 | AI9: 30
Y10: 판매추정비율** | Z10: =(Z6+Z8)/2 -> 0.024270776 | AA10: =(AA6+AA8)/2 -> 0.051073198 | AB10: =(AB6+AB8)/2 -> 0.080407265 | AC10: =(AC6+AC8)/2 -> 0.32372042 | AD10: =(AD6+AD8)/2 -> 0.15762245 | AE10: =(AE6+AE8)/2 -> 0.36290589 | AF10: =(AF6+AF8)/2 -> 1 | AH10: 카카오판교아지트 | AI10: 26
X11: 재무 추정 | Y11: 면당 판매단가(b) | Z11: 14000 | AA11: 11000 | AB11: 10000 | AC11: 10000 | AD11: 10000 | AE11: 10000 | AF11: 노즐플레이트 설치 | AH11: SK서린빌딩 | AI11: 17
Y12: 면당 판매단가(C) | Z12: 2000 | AA12: 2000 | AB12: 2000 | AC12: 2000 | AD12: 2000 | AE12: 2000 | AF12: 원격관제,AI CCTV, 점검 (2개년) | AH12: KCC오토타워 | AI12: 10
X13: (단위, 천원) | Y13: 매입평균단가 | Z13: =Z27 -> 15200 | AA13: =AA27 -> 12150 | AB13: =AB27 -> 10880 | AC13: =AC27 -> 9040 | AD13: =AD27 -> 8390 | AE13: =AE27 -> 8640 | AH13: 엘지가산디지털센터 | AI13: 10
Y14: 판매총액(a x (b+c)) | Z14: =Z9*(Z11+Z12) -> 192000 | AA14: =AA9*(AA11+AA12) -> 338000 | AB14: =AB9*(AB11+AB12) -> 480000 | AC14: =AC9*(AC11+AC12) -> 1944000 | AD14: =AD9*(AD11+AD12) -> 948000 | AE14: =AE9*(AE11+AE12) -> 2172000 | AF14: =SUM(Z14:AE14) -> 6074000 | AH14: 강서사옥 | AI14: 9
Y15: 판매원가 | Z15: =Z9*Z13 -> 182400 | AA15: =AA9*AA13 -> 315900 | AB15: =AB9*AB13 -> 435200 | AC15: =AC9*AC13 -> 1464480 | AD15: =AD9*AD13 -> 662810 | AE15: =AE9*AE13 -> 1563840 | AF15: =SUM(Z15:AE15) -> 4624630 | AH15: 서울역빌딩 | AI15: 9
Y16: 매총1이익 | Z16: =Z14-Z15 -> 9600 | AA16: =AA14-AA15 -> 22100 | AB16: =AB14-AB15 -> 44800 | AC16: =AC14-AC15 -> 479520 | AD16: =AD14-AD15 -> 285190 | AE16: =AE14-AE15 -> 608160 | AF16: =SUM(Z16:AE16) -> 1449370 | AH16: 인화원 | AI16: 9
Y17: 매총1이익율 | Z17: =Z16/Z14 -> 0.05 | AA17: =AA16/AA14 -> 0.065384615 | AB17: =AB16/AB14 -> 0.093333333 | AC17: =AC16/AC14 -> 0.24666667 | AD17: =AD16/AD14 -> 0.30083333 | AE17: =AE16/AE14 -> 0.28 | AF17: =AF16/AF14 -> 0.2386187 | AH17: 건양대학교 | AI17: 8
X18: 공사 추정 ① | Y18: 판매평균단가(실질) | Z18: 14680 | AA18: 12260 | AB18: 11360 | AC18: 10020 | AD18: 9530 | AE18: 9850 | AH18: 마포운영센터 | AI18: 8
X19: (단위, 천원) | Y19: 매입평균단가(실질) | Z19: 12000 | AA19: 9990 | AB19: 9230 | AC19: 8120 | AD19: 7710 | AE19: 7980 | AH19: 부산진구청 | AI19: 8
Y20: 매총1이익 | Z20: =Z18-Z19 -> 2680 | AA20: =AA18-AA19 -> 2270 | AB20: =AB18-AB19 -> 2130 | AC20: =AC18-AC19 -> 1900 | AD20: =AD18-AD19 -> 1820 | AE20: =AE18-AE19 -> 1870 | AH20: sk가스사옥 | AI20: 7
Y21: 매총1이익율 | Z21: =Z20/Z18 -> 0.18256131 | AA21: =AA20/AA18 -> 0.18515498 | AB21: =AB20/AB18 -> 0.1875 | AC21: =AC20/AC18 -> 0.18962076 | AD21: =AD20/AD18 -> 0.19097587 | AE21: =AE20/AE18 -> 0.18984772 | AH21: 메리츠화재 | AI21: 6
X22: 용역 추정 ② | Y22: 판매평균단가(실질) | Z22: 3870 | AA22: 2620 | AB22: 1990 | AC22: 1110 | AD22: 790 | AE22: 770 | AH22: 광화문빌딩 | AI22: 4
X23: (단위, 천원, 2개년분) | Y23: 매입평균단가(실질) | Z23: 3190 | AA23: 2160 | AB23: 1640 | AC23: 920 | AD23: 670 | AE23: 650 | AH23: 금융투자협회 | AI23: 4
Y24: 매총1이익 | Z24: =Z22-Z23 -> 680 | AA24: =AA22-AA23 -> 460 | AB24: =AB22-AB23 -> 350 | AC24: =AC22-AC23 -> 190 | AD24: =AD22-AD23 -> 120 | AE24: =AE22-AE23 -> 120 | AH24: 상암CNS | AI24: 4
Y25: 매총1이익율 | Z25: =Z24/Z22 -> 0.17571059 | AA25: =AA24/AA22 -> 0.17557252 | AB25: =AB24/AB22 -> 0.1758794 | AC25: =AC24/AC22 -> 0.17117117 | AD25: =AD24/AD22 -> 0.15189873 | AE25: =AE24/AE22 -> 0.15584416 | AH25: JW과천 | AI25: 3
X26: 총괄 (① + ②) | Y26: 판매평균단가(실질) | Z26: 18550 | AA26: 14890 | AB26: 13350 | AC26: 11130 | AD26: 10320 | AE26: 10630 | AH26: 각화골드클래스 | AI26: 3
X27: (단위, 천원) | Y27: 매입평균단가(실질) | Z27: 15200 | AA27: 12150 | AB27: 10880 | AC27: 9040 | AD27: 8390 | AE27: 8640 | AH27: 대신증권(위례) | AI27: 2
Y28: 매총1이익 | Z28: =Z26-Z27 -> 3350 | AA28: =AA26-AA27 -> 2740 | AB28: =AB26-AB27 -> 2470 | AC28: =AC26-AC27 -> 2090 | AD28: =AD26-AD27 -> 1930 | AE28: =AE26-AE27 -> 1990
Y29: 매총1이익율 | Z29: =Z28/Z26 -> 0.18059299 | AA29: =AA28/AA26 -> 0.18401612 | AB29: =AB28/AB26 -> 0.18501873 | AC29: =AC28/AC26 -> 0.18778077 | AD29: =AD28/AD26 -> 0.1870155 | AE29: =AE28/AE26 -> 0.18720602
X30: * 시장 추정은 당사에 접수된 관심고객 정보로 추정
X31: ** 목표 추정은 관심고객수비율과 관심고객보유면수를 5:5비율로 추정

Sheet 가격시뮬레이션
B2: □ 가격 시뮬레이션
C4: ● 판매면수 | H4: ● 결합솔루션
D5: 4 | G5: =IF(D5>50,"※ 50면을 초과하는 경우는 PO에게 문의 필요", "") | H5: FALSE | I5: FALSE | J5: TRUE
C7: ● 판매 견적가
J8: (단위:천원, VAT별도)
D9: 서비스 구분 | F9: 월간 금액 | G9: 년간 금액 | H9: 계약 금액 | I9: 비 고
D10: 1. 설치 공사 | H10: =ROUNDDOWN(H11+H12,0) -> 40000 | I10: * 기본 공사 조건( 급수배관거리 50m, 분전반거리 50m )으로 진행되며,
E11: 노즐플레이트 설치 | H11: =(VLOOKUP($D$5,가격테이블!$B$4:$L$54,2,0))/1000 -> 40000 | I11: 배관 및 분전반의 거리가 기본 공사 조건을 초과 시에는 추가 비용이
E12: 원격관제장비 설치 | H12: =(IF(H5=TRUE,VLOOKUP($D$5,가격테이블!$B$4:$L$54,4,0),0))/1000 -> 0 | I12: 발생됩니다.
D13: 2. 월 유지 관리 | F13: =F14+F15+F16 -> 100 | G13: =G14+G15+G16 -> 1200 | H13: =H14+H15+H16 -> 2400 | I13: * 2년 약정 조건이며, 2년 이후의 월 유지 관리 서비스는 별도의 계약 체결이
E14: 원격관제 | F14: =ROUNDDOWN(IF(H5=TRUE,VLOOKUP($D$5,가격테이블!$B$4:$L$54,6,0),0)/1000,0) -> 0 | G14: =F14*12 -> 0 | H14: =F14*24 -> 0 | I14: 필요합니다.
E15: AI CCTV 모니터링 | F15: =ROUNDDOWN(IF(I5=TRUE,VLOOKUP($D$5,가격테이블!$B$4:$L$54,8,0),0)/1000,0) -> 0 | G15: =F15*12 -> 0 | H15: =F15*24 -> 0
E16: 작동 점검 (분기) | F16: =ROUNDDOWN(IF(J5=TRUE,VLOOKUP($D$5,가격테이블!$B$4:$L$54,10,0),0)/1000,0) -> 100 | G16: =F16*12 -> 1200 | H16: =F16*24 -> 2400
D17: 총 계약 금액 | H17: =ROUNDDOWN(H10+H13,0) -> 42400 | I17: * 천원 단위 절사
C19: ● 재무 추정
I20: (단위:천원, VAT별도)
D21: 서비스 구분 | F21: 판매 견적가 | G21: 매출 원가 | H21: 매총익 | I21: 매총율
D22: 1. 설치 공사 | F22: =ROUNDDOWN(F23+F24,0) -> 40000 | G22: =ROUNDDOWN(G23+G24,0) -> 32400 | H22: =ROUNDDOWN(H23+H24,0) -> 7600 | I22: =IFERROR(H22/F22,0) -> 0.19
E23: 노즐플레이트 설치 | F23: =H11 -> 40000 | G23: =(VLOOKUP($D$5,가격테이블!$B$4:$L$54,3,0))/1000 -> 32400 | H23: =F23-G23 -> 7600 | I23: =IFERROR(H23/F23,0) -> 0.19
E24: 원격관제장비 설치 | F24: =H12 -> 0 | G24: =(IF(H5=TRUE,VLOOKUP($D$5,가격테이블!$B$4:$L$54,5,0),0))/1000 -> 0 | H24: =F24-G24 -> 0 | I24: =IFERROR(H24/F24,0) -> 0
D25: 2. 월 유지 관리 | F25: =F26+F27+F28 -> 2400 | G25: =G26+G27+G28 -> 1920 | H25: =H26+H27+H28 -> 480 | I25: =IFERROR(H25/F25,0) -> 0.2
E26: 원격관제 | F26: =H14 -> 0 | G26: =ROUNDDOWN(IF(H5=TRUE,VLOOKUP($D$5,가격테이블!$B$4:$L$54,7,0),0)/1000,0)*24 -> 0 | H26: =F26-G26 -> 0 | I26: =IFERROR(H26/F26,0) -> 0
E27: AI CCTV 모니터링 | F27: =H15 -> 0 | G27: =ROUNDDOWN(IF(I5=TRUE,VLOOKUP($D$5,가격테이블!$B$4:$L$54,9,0),0)/1000,0)*24 -> 0 | H27: =F27-G27 -> 0 | I27: =IFERROR(H27/F27,0) -> 0
E28: 작동 점검 (분기) | F28: =H16 -> 2400 | G28: =ROUNDDOWN(IF(J5=TRUE,VLOOKUP($D$5,가격테이블!$B$4:$L$54,11,0),0)/1000,0)*24 -> 1920 | H28: =F28-G28 -> 480 | I28: =IFERROR(H28/F28,0) -> 0.2
D29: 총 계약 금액 | F29: =ROUNDDOWN(F22+F25,0) -> 42400 | G29: =ROUNDDOWN(G22+G25,0) -> 34320 | H29: =ROUNDDOWN(H22+H25,0) -> 8080 | I29: =IFERROR(H29/F29,0) -> 0.19056604

Sheet 참고>>

Sheet 가격테이블
B2: (부가세별도, 급수배관거리 50m, 분전반거리 50m 기준)
C3: 노즐플레이트 공사 | E3: 원격관제 | I3: AI CCTV | K3: 작동점검 | M3: 설치 공사 재무 | Q3: 리커링 재무(2년 약정) | U3: 판매금액 계 | W3: 면당재무
B4: 면수 | C4: 공사매출 | D4: 공사원가 | E4: 공사매출 | F4: 공사원가 | G4: 월매출 | H4: 월원가 | I4: 월매출 | J4: 월원가 | K4: 월매출 | L4: 월원가 | M4: 일시 매출 | N4: 일시 원가 | O4: 매총 | P4: 매총률 | Q4: 2년 매출 | R4: 2년 원가 | S4: 매총 | T4: 매총률 | U4: 매출계 | V4: 원가계 | W4: 면수 | X4: 면당평균공사매출 | Y4: 면당평균공사원가 | Z4: 면당평균리커링매출 | AA4: 면당평균리커링원가 | AB4: 합산평균매출 | AC4: 합산평균원가
B5: 1 | C5: 18600000 | D5: 15200000 | E5: 3541200 | F5: =E5/1.2 -> 2951000 | G5: =18400+((B5-1)*4700) -> 18400 | H5: =ROUND(G5/1.2,-2) -> 15300 | I5: =IF(B5 <= 12, 200000, ROUNDUP(B5/3,0) * 50000) -> 200000 | J5: =IF(B5 <= 12, (35200+6500)*4, ROUNDUP(B5/3,0) * (35200+6500)) -> 166800 | K5: =IF(B5 <= 12, 100000, ROUNDUP(B5/3,0) * 30000) -> 100000 | L5: =IF(B5 <= 12, 80000, ROUNDUP(B5/3,0) * 26000) -> 80000 | M5: =C5+E5 -> 22141200 | N5: =D5+F5 -> 18151000 | O5: =M5-N5 -> 3990200 | P5: =O5/M5 -> 0.18021607 | Q5: =(G5+I5+K5)*24 -> 7641600 | R5: =(H5+J5+L5)*24 -> 6290400 | S5: =Q5-R5 -> 1351200 | T5: =S5/Q5 -> 0.17682161 | U5: =M5+Q5 -> 29782800 | V5: =N5+R5 -> 24441400 | W5: 1 | X5: =M5/$W$5 -> 22141200 | Y5: =N5/$W$5 -> 18151000 | Z5: =Q5/$W$5 -> 7641600 | AA5: =R5/$W$5 -> 6290400 | AB5: =U5/W5 -> 29782800 | AC5: =V5/W5 -> 24441400
B6: 2 | C6: 25500000 | D6: 20800000 | E6: 3863200 | F6: =E6/1.2 -> 3219333.3 | G6: =18400+((B6-1)*4700) -> 23100 | H6: =ROUND(G6/1.2,-2) -> 19300 | I6: =IF(B6 <= 12, 200000, ROUNDUP(B6/3,0) * 50000) -> 200000 | J6: =IF(B6 <= 12, (35200+6500)*4, ROUNDUP(B6/3,0) * (35200+6500)) -> 166800 | K6: =IF(B6 <= 12, 100000, ROUNDUP(B6/3,0) * 30000) -> 100000 | L6: =IF(B6 <= 12, 80000, ROUNDUP(B6/3,0) * 26000) -> 80000 | M6: =C6+E6 -> 29363200 | N6: =D6+F6 -> 24019333 | O6: =M6-N6 -> 5343866.7 | P6: =O6/M6 -> 0.18199197 | Q6: =(G6+I6+K6)*24 -> 7754400 | R6: =(H6+J6+L6)*24 -> 6386400 | S6: =Q6-R6 -> 1368000 | T6: =S6/Q6 -> 0.17641597 | U6: =M6+Q6 -> 37117600 | V6: =N6+R6 -> 30405733 | W6: 2 | X6: =M6/$W$6 -> 14681600 | Y6: =N6/$W$6 -> 12009667 | Z6: =Q6/$W$6 -> 3877200 | AA6: =R6/$W$6 -> 3193200 | AB6: =U6/W6 -> 18558800 | AC6: =V6/W6 -> 15202867
B7: 3 | C7: 32400000 | D7: 26300000 | E7: 4406400 | F7: =E7/1.2 -> 3672000 | G7: =18400+((B7-1)*4700) -> 27800 | H7: =ROUND(G7/1.2,-2) -> 23200 | I7: =IF(B7 <= 12, 200000, ROUNDUP(B7/3,0) * 50000) -> 200000 | J7: =IF(B7 <= 12, (35200+6500)*4, ROUNDUP(B7/3,0) * (35200+6500)) -> 166800 | K7: =IF(B7 <= 12, 100000, ROUNDUP(B7/3,0) * 30000) -> 100000 | L7: =IF(B7 <= 12, 80000, ROUNDUP(B7/3,0) * 26000) -> 80000 | M7: =C7+E7 -> 36806400 | N7: =D7+F7 -> 29972000 | O7: =M7-N7 -> 6834400 | P7: =O7/M7 -> 0.1856851 | Q7: =(G7+I7+K7)*24 -> 7867200 | R7: =(H7+J7+L7)*24 -> 6480000 | S7: =Q7-R7 -> 1387200 | T7: =S7/Q7 -> 0.17632703 | U7: =M7+Q7 -> 44673600 | V7: =N7+R7 -> 36452000 | W7: 3 | X7: =M7/$W$7 -> 12268800 | Y7: =N7/$W$7 -> 9990666.7 | Z7: =Q7/$W$7 -> 2622400 | AA7: =R7/$W$7 -> 2160000 | AB7: =U7/W7 -> 14891200 | AC7: =V7/W7 -> 12150667
B8: 4 | C8: 40000000 | D8: 32400000 | E8: 5456400 | F8: =E8/1.2 -> 4547000 | G8: =18400+((B8-1)*4700) -> 32500 | H8: =ROUND(G8/1.2,-2) -> 27100 | I8: =IF(B8 <= 12, 200000, ROUNDUP(B8/3,0) * 50000) -> 200000 | J8: =IF(B8 <= 12, (35200+6500)*4, ROUNDUP(B8/3,0) * (35200+6500)) -> 166800 | K8: =IF(B8 <= 12, 100000, ROUNDUP(B8/3,0) * 30000) -> 100000 | L8: =IF(B8 <= 12, 80000, ROUNDUP(B8/3,0) * 26000) -> 80000 | M8: =C8+E8 -> 45456400 | N8: =D8+F8 -> 36947000 | O8: =M8-N8 -> 8509400 | P8: =O8/M8 -> 0.18719916 | Q8: =(G8+I8+K8)*24 -> 7980000 | R8: =(H8+J8+L8)*24 -> 6573600 | S8: =Q8-R8 -> 1406400 | T8: =S8/Q8 -> 0.1762406 | U8: =M8+Q8 -> 53436400 | V8: =N8+R8 -> 43520600 | W8: 4 | X8: =M8/$W$8 -> 11364100 | Y8: =N8/$W$8 -> 9236750 | Z8: =Q8/$W$8 -> 1995000 | AA8: =R8/$W$8 -> 1643400 | AB8: =U8/W8 -> 13359100 | AC8: =V8/W8 -> 10880150
B9: 5 | C9: 46900000 | D9: 38000000 | E9: 6946800 | F9: =E9/1.2 -> 5789000 | G9: =18400+((B9-1)*4700) -> 37200 | H9: =ROUND(G9/1.2,-2) -> 31000 | I9: =IF(B9 <= 12, 200000, ROUNDUP(B9/3,0) * 50000) -> 200000 | J9: =IF(B9 <= 12, (35200+6500)*4, ROUNDUP(B9/3,0) * (35200+6500)) -> 166800 | K9: =IF(B9 <= 12, 100000, ROUNDUP(B9/3,0) * 30000) -> 100000 | L9: =IF(B9 <= 12, 80000, ROUNDUP(B9/3,0) * 26000) -> 80000 | M9: =C9+E9 -> 53846800 | N9: =D9+F9 -> 43789000 | O9: =M9-N9 -> 10057800 | P9: =O9/M9 -> 0.18678547 | Q9: =(G9+I9+K9)*24 -> 8092800 | R9: =(H9+J9+L9)*24 -> 6667200 | S9: =Q9-R9 -> 1425600 | T9: =S9/Q9 -> 0.17615658 | U9: =M9+Q9 -> 61939600 | V9: =N9+R9 -> 50456200 | W9: 5 | X9: =SUM(M9:M14)/SUM($W$9:$W$14) -> 10023342 | Y9: =SUM(N9:N14)/SUM($W$9:$W$14) -> 8128711.1 | Z9: =SUM(Q9:Q14)/SUM($W$9:$W$14) -> 1116640 | AA9: =SUM(R9:R14)/SUM($W$9:$W$14) -> 920320 | AB9: =SUM(U9:U14)/SUM($W$9:$W$14) -> 11139982 | AC9: =SUM(V9:V14)/SUM($W$9:$W$14) -> 9049031.1
B10: 6 | C10: 53800000 | D10: 43500000 | E10: 7380000 | F10: =E10/1.2 -> 6150000 | G10: =18400+((B10-1)*4700) -> 41900 | H10: =ROUND(G10/1.2,-2) -> 34900 | I10: =IF(B10 <= 12, 200000, ROUNDUP(B10/3,0) * 50000) -> 200000 | J10: =IF(B10 <= 12, (35200+6500)*4, ROUNDUP(B10/3,0) * (35200+6500)) -> 166800 | K10: =IF(B10 <= 12, 100000, ROUNDUP(B10/3,0) * 30000) -> 100000 | L10: =IF(B10 <= 12, 80000, ROUNDUP(B10/3,0) * 26000) -> 80000 | M10: =C10+E10 -> 61180000 | N10: =D10+F10 -> 49650000 | O10: =M10-N10 -> 11530000 | P10: =O10/M10 -> 0.18846028 | Q10: =(G10+I10+K10)*24 -> 8205600 | R10: =(H10+J10+L10)*24 -> 6760800 | S10: =Q10-R10 -> 1444800 | T10: =S10/Q10 -> 0.17607488 | U10: =M10+Q10 -> 69385600 | V10: =N10+R10 -> 56410800 | W10: 6
B11: 7 | C11: 61400000 | D11: 49600000 | E11: 8430000 | F11: =E11/1.2 -> 7025000 | G11: =18400+((B11-1)*4700) -> 46600 | H11: =ROUND(G11/1.2,-2) -> 38800 | I11: =IF(B11 <= 12, 200000, ROUNDUP(B11/3,0) * 50000) -> 200000 | J11: =IF(B11 <= 12, (35200+6500)*4, ROUNDUP(B11/3,0) * (35200+6500)) -> 166800 | K11: =IF(B11 <= 12, 100000, ROUNDUP(B11/3,0) * 30000) -> 100000 | L11: =IF(B11 <= 12, 80000, ROUNDUP(B11/3,0) * 26000) -> 80000 | M11: =C11+E11 -> 69830000 | N11: =D11+F11 -> 56625000 | O11: =M11-N11 -> 13205000 | P11: =O11/M11 -> 0.18910211 | Q11: =(G11+I11+K11)*24 -> 8318400 | R11: =(H11+J11+L11)*24 -> 6854400 | S11: =Q11-R11 -> 1464000 | T11: =S11/Q11 -> 0.17599538 | U11: =M11+Q11 -> 78148400 | V11: =N11+R11 -> 63479400 | W11: 7
B12: 8 | C12: 68300000 | D12: 55100000 | E12: 8862000 | F12: =E12/1.2 -> 7385000 | G12: =18400+((B12-1)*4700) -> 51300 | H12: =ROUND(G12/1.2,-2) -> 42800 | I12: =IF(B12 <= 12, 200000, ROUNDUP(B12/3,0) * 50000) -> 200000 | J12: =IF(B12 <= 12, (35200+6500)*4, ROUNDUP(B12/3,0) * (35200+6500)) -> 166800 | K12: =IF(B12 <= 12, 100000, ROUNDUP(B12/3,0) * 30000) -> 100000 | L12: =IF(B12 <= 12, 80000, ROUNDUP(B12/3,0) * 26000) -> 80000 | M12: =C12+E12 -> 77162000 | N12: =D12+F12 -> 62485000 | O12: =M12-N12 -> 14677000 | P12: =O12/M12 -> 0.19021021 | Q12: =(G12+I12+K12)*24 -> 8431200 | R12: =(H12+J12+L12)*24 -> 6950400 | S12: =Q12-R12 -> 1480800 | T12: =S12/Q12 -> 0.17563336 | U12: =M12+Q12 -> 85593200 | V12: =N12+R12 -> 69435400 | W12: 8
B13: 9 | C13: 79500000 | D13: 64200000 | E13: 9295200 | F13: =E13/1.2 -> 7746000 | G13: =18400+((B13-1)*4700) -> 56000 | H13: =ROUND(G13/1.2,-2) -> 46700 | I13: =IF(B13 <= 12, 200000, ROUNDUP(B13/3,0) * 50000) -> 200000 | J13: =IF(B13 <= 12, (35200+6500)*4, ROUNDUP(B13/3,0) * (35200+6500)) -> 166800 | K13: =IF(B13 <= 12, 100000, ROUNDUP(B13/3,0) * 30000) -> 100000 | L13: =IF(B13 <= 12, 80000, ROUNDUP(B13/3,0) * 26000) -> 80000 | M13: =C13+E13 -> 88795200 | N13: =D13+F13 -> 71946000 | O13: =M13-N13 -> 16849200 | P13: =O13/M13 -> 0.1897535 | Q13: =(G13+I13+K13)*24 -> 8544000 | R13: =(H13+J13+L13)*24 -> 7044000 | S13: =Q13-R13 -> 1500000 | T13: =S13/Q13 -> 0.1755618 | U13: =M13+Q13 -> 97339200 | V13: =N13+R13 -> 78990000 | W13: 9
B14: 10 | C14: 87400000 | D14: 70600000 | E14: =E5+$E$13 -> 12836400 | F14: =E14/1.2 -> 10697000 | G14: =18400+((B14-1)*4700) -> 60700 | H14: =ROUND(G14/1.2,-2) -> 50600 | I14: =IF(B14 <= 12, 200000, ROUNDUP(B14/3,0) * 50000) -> 200000 | J14: =IF(B14 <= 12, (35200+6500)*4, ROUNDUP(B14/3,0) * (35200+6500)) -> 166800 | K14: =IF(B14 <= 12, 100000, ROUNDUP(B14/3,0) * 30000) -> 100000 | L14: =IF(B14 <= 12, 80000, ROUNDUP(B14/3,0) * 26000) -> 80000 | M14: =C14+E14 -> 100236400 | N14: =D14+F14 -> 81297000 | O14: =M14-N14 -> 18939400 | P14: =O14/M14 -> 0.18894733 | Q14: =(G14+I14+K14)*24 -> 8656800 | R14: =(H14+J14+L14)*24 -> 7137600 | S14: =Q14-R14 -> 1519200 | T14: =S14/Q14 -> 0.1754921 | U14: =M14+Q14 -> 108893200 | V14: =N14+R14 -> 88434600 | W14: 10
B15: 11 | C15: 94500000 | D15: 76300000 | E15: =E6+$E$13 -> 13158400 | F15: =E15/1.2 -> 10965333 | G15: =18400+((B15-1)*4700) -> 65400 | H15: =ROUND(G15/1.2,-2) -> 54500 | I15: =IF(B15 <= 12, 200000, ROUNDUP(B15/3,0) * 50000) -> 200000 | J15: =IF(B15 <= 12, (35200+6500)*4, ROUNDUP(B15/3,0) * (35200+6500)) -> 166800 | K15: =IF(B15 <= 12, 100000, ROUNDUP(B15/3,0) * 30000) -> 100000 | L15: =IF(B15 <= 12, 80000, ROUNDUP(B15/3,0) * 26000) -> 80000 | M15: =C15+E15 -> 107658400 | N15: =D15+F15 -> 87265333 | O15: =M15-N15 -> 20393067 | P15: =O15/M15 -> 0.18942383 | Q15: =(G15+I15+K15)*24 -> 8769600 | R15: =(H15+J15+L15)*24 -> 7231200 | S15: =Q15-R15 -> 1538400 | T15: =S15/Q15 -> 0.17542419 | U15: =M15+Q15 -> 116428000 | V15: =N15+R15 -> 94496533 | W15: 11 | X15: =SUM(M15:M34)/SUM($W$15:$W$34) -> 9533082.9 | Y15: =SUM(N15:N34)/SUM($W$15:$W$34) -> 7719195.1 | Z15: =SUM(Q15:Q34)/SUM($W$15:$W$34) -> 796156.1 | AA15: =SUM(R15:R34)/SUM($W$15:$W$34) -> 671262.44 | AB15: =SUM(U15:U34)/SUM($W$15:$W$34) -> 10329239 | AC15: =SUM(V15:V34)/SUM($W$15:$W$34) -> 8390457.6
B16: 12 | C16: 101700000 | D16: 82100000 | E16: =E7+$E$13 -> 13701600 | F16: =E16/1.2 -> 11418000 | G16: =18400+((B16-1)*4700) -> 70100 | H16: =ROUND(G16/1.2,-2) -> 58400 | I16: =IF(B16 <= 12, 200000, ROUNDUP(B16/3,0) * 50000) -> 200000 | J16: =IF(B16 <= 12, (35200+6500)*4, ROUNDUP(B16/3,0) * (35200+6500)) -> 166800 | K16: =IF(B16 <= 12, 100000, ROUNDUP(B16/3,0) * 30000) -> 100000 | L16: =IF(B16 <= 12, 80000, ROUNDUP(B16/3,0) * 26000) -> 80000 | M16: =C16+E16 -> 115401600 | N16: =D16+F16 -> 93518000 | O16: =M16-N16 -> 21883600 | P16: =O16/M16 -> 0.18962995 | Q16: =(G16+I16+K16)*24 -> 8882400 | R16: =(H16+J16+L16)*24 -> 7324800 | S16: =Q16-R16 -> 1557600 | T16: =S16/Q16 -> 0.17535801 | U16: =M16+Q16 -> 124284000 | V16: =N16+R16 -> 100842800 | W16: 12
B17: 13 | C17: 109600000 | D17: 88400000 | E17: =E8+$E$13 -> 14751600 | F17: =E17/1.2 -> 12293000 | G17: =18400+((B17-1)*4700) -> 74800 | H17: =ROUND(G17/1.2,-2) -> 62300 | I17: =IF(B17 <= 12, 200000, ROUNDUP(B17/3,0) * 50000) -> 250000 | J17: =IF(B17 <= 12, (35200+6500)*4, ROUNDUP(B17/3,0) * (35200+6500)) -> 208500 | K17: =IF(B17 <= 12, 100000, ROUNDUP(B17/3,0) * 30000) -> 150000 | L17: =IF(B17 <= 12, 80000, ROUNDUP(B17/3,0) * 26000) -> 130000 | M17: =C17+E17 -> 124351600 | N17: =D17+F17 -> 100693000 | O17: =M17-N17 -> 23658600 | P17: =O17/M17 -> 0.19025569 | Q17: =(G17+I17+K17)*24 -> 11395200 | R17: =(H17+J17+L17)*24 -> 9619200 | S17: =Q17-R17 -> 1776000 | T17: =S17/Q17 -> 0.1558551 | U17: =M17+Q17 -> 135746800 | V17: =N17+R17 -> 110312200 | W17: 13
B18: 14 | C18: 116700000 | D18: 94100000 | E18: =E9+$E$13 -> 16242000 | F18: =E18/1.2 -> 13535000 | G18: =18400+((B18-1)*4700) -> 79500 | H18: =ROUND(G18/1.2,-2) -> 66300 | I18: =IF(B18 <= 12, 200000, ROUNDUP(B18/3,0) * 50000) -> 250000 | J18: =IF(B18 <= 12, (35200+6500)*4, ROUNDUP(B18/3,0) * (35200+6500)) -> 208500 | K18: =IF(B18 <= 12, 100000, ROUNDUP(B18/3,0) * 30000) -> 150000 | L18: =IF(B18 <= 12, 80000, ROUNDUP(B18/3,0) * 26000) -> 130000 | M18: =C18+E18 -> 132942000 | N18: =D18+F18 -> 107635000 | O18: =M18-N18 -> 25307000 | P18: =O18/M18 -> 0.19036121 | Q18: =(G18+I18+K18)*24 -> 11508000 | R18: =(H18+J18+L18)*24 -> 9715200 | S18: =Q18-R18 -> 1792800 | T18: =S18/Q18 -> 0.15578728 | U18: =M18+Q18 -> 144450000 | V18: =N18+R18 -> 117350200 | W18: 14
B19: 15 | C19: 123900000 | D19: 99900000 | E19: =E10+$E$13 -> 16675200 | F19: =E19/1.2 -> 13896000 | G19: =18400+((B19-1)*4700) -> 84200 | H19: =ROUND(G19/1.2,-2) -> 70200 | I19: =IF(B19 <= 12, 200000, ROUNDUP(B19/3,0) * 50000) -> 250000 | J19: =IF(B19 <= 12, (35200+6500)*4, ROUNDUP(B19/3,0) * (35200+6500)) -> 208500 | K19: =IF(B19 <= 12, 100000, ROUNDUP(B19/3,0) * 30000) -> 150000 | L19: =IF(B19 <= 12, 80000, ROUNDUP(B19/3,0) * 26000) -> 130000 | M19: =C19+E19 -> 140575200 | N19: =D19+F19 -> 113796000 | O19: =M19-N19 -> 26779200 | P19: =O19/M19 -> 0.19049733 | Q19: =(G19+I19+K19)*24 -> 11620800 | R19: =(H19+J19+L19)*24 -> 9808800 | S19: =Q19-R19 -> 1812000 | T19: =S19/Q19 -> 0.1559273 | U19: =M19+Q19 -> 152196000 | V19: =N19+R19 -> 123604800 | W19: 15
B20: 16 | C20: 131700000 | D20: 106200000 | E20: =E11+$E$13 -> 17725200 | F20: =E20/1.2 -> 14771000 | G20: =18400+((B20-1)*4700) -> 88900 | H20: =ROUND(G20/1.2,-2) -> 74100 | I20: =IF(B20 <= 12, 200000, ROUNDUP(B20/3,0) * 50000) -> 300000 | J20: =IF(B20 <= 12, (35200+6500)*4, ROUNDUP(B20/3,0) * (35200+6500)) -> 250200 | K20: =IF(B20 <= 12, 100000, ROUNDUP(B20/3,0) * 30000) -> 180000 | L20: =IF(B20 <= 12, 80000, ROUNDUP(B20/3,0) * 26000) -> 156000 | M20: =C20+E20 -> 149425200 | N20: =D20+F20 -> 120971000 | O20: =M20-N20 -> 28454200 | P20: =O20/M20 -> 0.19042437 | Q20: =(G20+I20+K20)*24 -> 13653600 | R20: =(H20+J20+L20)*24 -> 11527200 | S20: =Q20-R20 -> 2126400 | T20: =S20/Q20 -> 0.15573915 | U20: =M20+Q20 -> 163078800 | V20: =N20+R20 -> 132498200 | W20: 16
B21: 17 | C21: 145200000 | D21: 117100000 | E21: =E12+$E$13 -> 18157200 | F21: =E21/1.2 -> 15131000 | G21: =18400+((B21-1)*4700) -> 93600 | H21: =ROUND(G21/1.2,-2) -> 78000 | I21: =IF(B21 <= 12, 200000, ROUNDUP(B21/3,0) * 50000) -> 300000 | J21: =IF(B21 <= 12, (35200+6500)*4, ROUNDUP(B21/3,0) * (35200+6500)) -> 250200 | K21: =IF(B21 <= 12, 100000, ROUNDUP(B21/3,0) * 30000) -> 180000 | L21: =IF(B21 <= 12, 80000, ROUNDUP(B21/3,0) * 26000) -> 156000 | M21: =C21+E21 -> 163357200 | N21: =D21+F21 -> 132231000 | O21: =M21-N21 -> 31126200 | P21: =O21/M21 -> 0.19054073 | Q21: =(G21+I21+K21)*24 -> 13766400 | R21: =(H21+J21+L21)*24 -> 11620800 | S21: =Q21-R21 -> 2145600 | T21: =S21/Q21 -> 0.15585774 | U21: =M21+Q21 -> 177123600 | V21: =N21+R21 -> 143851800 | W21: 17
B22: 18 | C22: 152600000 | D22: 123100000 | E22: =E13+$E$13 -> 18590400 | F22: =E22/1.2 -> 15492000 | G22: =18400+((B22-1)*4700) -> 98300 | H22: =ROUND(G22/1.2,-2) -> 81900 | I22: =IF(B22 <= 12, 200000, ROUNDUP(B22/3,0) * 50000) -> 300000 | J22: =IF(B22 <= 12, (35200+6500)*4, ROUNDUP(B22/3,0) * (35200+6500)) -> 250200 | K22: =IF(B22 <= 12, 100000, ROUNDUP(B22/3,0) * 30000) -> 180000 | L22: =IF(B22 <= 12, 80000, ROUNDUP(B22/3,0) * 26000) -> 156000 | M22: =C22+E22 -> 171190400 | N22: =D22+F22 -> 138592000 | O22: =M22-N22 -> 32598400 | P22: =O22/M22 -> 0.19042189 | Q22: =(G22+I22+K22)*24 -> 13879200 | R22: =(H22+J22+L22)*24 -> 11714400 | S22: =Q22-R22 -> 2164800 | T22: =S22/Q22 -> 0.15597441 | U22: =M22+Q22 -> 185069600 | V22: =N22+R22 -> 150306400 | W22: 18
B23: 19 | C23: 160700000 | D23: 129600000 | E23: =E14+$E$13 -> 22131600 | F23: =E23/1.2 -> 18443000 | G23: =18400+((B23-1)*4700) -> 103000 | H23: =ROUND(G23/1.2,-2) -> 85800 | I23: =IF(B23 <= 12, 200000, ROUNDUP(B23/3,0) * 50000) -> 350000 | J23: =IF(B23 <= 12, (35200+6500)*4, ROUNDUP(B23/3,0) * (35200+6500)) -> 291900 | K23: =IF(B23 <= 12, 100000, ROUNDUP(B23/3,0) * 30000) -> 210000 | L23: =IF(B23 <= 12, 80000, ROUNDUP(B23/3,0) * 26000) -> 182000 | M23: =C23+E23 -> 182831600 | N23: =D23+F23 -> 148043000 | O23: =M23-N23 -> 34788600 | P23: =O23/M23 -> 0.19027674 | Q23: =(G23+I23+K23)*24 -> 15912000 | R23: =(H23+J23+L23)*24 -> 13432800 | S23: =Q23-R23 -> 2479200 | T23: =S23/Q23 -> 0.15580694 | U23: =M23+Q23 -> 198743600 | V23: =N23+R23 -> 161475800 | W23: 19
B24: 20 | C24: 168100000 | D24: 135600000 | E24: =E15+$E$13 -> 22453600 | F24: =E24/1.2 -> 18711333 | G24: =18400+((B24-1)*4700) -> 107700 | H24: =ROUND(G24/1.2,-2) -> 89800 | I24: =IF(B24 <= 12, 200000, ROUNDUP(B24/3,0) * 50000) -> 350000 | J24: =IF(B24 <= 12, (35200+6500)*4, ROUNDUP(B24/3,0) * (35200+6500)) -> 291900 | K24: =IF(B24 <= 12, 100000, ROUNDUP(B24/3,0) * 30000) -> 210000 | L24: =IF(B24 <= 12, 80000, ROUNDUP(B24/3,0) * 26000) -> 182000 | M24: =C24+E24 -> 190553600 | N24: =D24+F24 -> 1.5431133e+08 | O24: =M24-N24 -> 36242267 | P24: =O24/M24 -> 0.1901946 | Q24: =(G24+I24+K24)*24 -> 16024800 | R24: =(H24+J24+L24)*24 -> 13528800 | S24: =Q24-R24 -> 2496000 | T24: =S24/Q24 -> 0.15575857 | U24: =M24+Q24 -> 206578400 | V24: =N24+R24 -> 1.6784013e+08 | W24: 20
B25: 21 | C25: 175500000 | D25: 141500000 | E25: =E16+$E$13 -> 22996800 | F25: =E25/1.2 -> 19164000 | G25: =18400+((B25-1)*4700) -> 112400 | H25: =ROUND(G25/1.2,-2) -> 93700 | I25: =IF(B25 <= 12, 200000, ROUNDUP(B25/3,0) * 50000) -> 350000 | J25: =IF(B25 <= 12, (35200+6500)*4, ROUNDUP(B25/3,0) * (35200+6500)) -> 291900 | K25: =IF(B25 <= 12, 100000, ROUNDUP(B25/3,0) * 30000) -> 210000 | L25: =IF(B25 <= 12, 80000, ROUNDUP(B25/3,0) * 26000) -> 182000 | M25: =C25+E25 -> 198496800 | N25: =D25+F25 -> 160664000 | O25: =M25-N25 -> 37832800 | P25: =O25/M25 -> 0.19059652 | Q25: =(G25+I25+K25)*24 -> 16137600 | R25: =(H25+J25+L25)*24 -> 13622400 | S25: =Q25-R25 -> 2515200 | T25: =S25/Q25 -> 0.15585961 | U25: =M25+Q25 -> 214634400 | V25: =N25+R25 -> 174286400 | W25: 21
B26: 22 | C26: 183600000 | D26: 148100000 | E26: =E17+$E$13 -> 24046800 | F26: =E26/1.2 -> 20039000 | G26: =18400+((B26-1)*4700) -> 117100 | H26: =ROUND(G26/1.2,-2) -> 97600 | I26: =IF(B26 <= 12, 200000, ROUNDUP(B26/3,0) * 50000) -> 400000 | J26: =IF(B26 <= 12, (35200+6500)*4, ROUNDUP(B26/3,0) * (35200+6500)) -> 333600 | K26: =IF(B26 <= 12, 100000, ROUNDUP(B26/3,0) * 30000) -> 240000 | L26: =IF(B26 <= 12, 80000, ROUNDUP(B26/3,0) * 26000) -> 208000 | M26: =C26+E26 -> 207646800 | N26: =D26+F26 -> 168139000 | O26: =M26-N26 -> 39507800 | P26: =O26/M26 -> 0.19026443 | Q26: =(G26+I26+K26)*24 -> 18170400 | R26: =(H26+J26+L26)*24 -> 15340800 | S26: =Q26-R26 -> 2829600 | T26: =S26/Q26 -> 0.1557258 | U26: =M26+Q26 -> 225817200 | V26: =N26+R26 -> 183479800 | W26: 22
B27: 23 | C27: 191000000 | D27: 154000000 | E27: =E18+$E$13 -> 25537200 | F27: =E27/1.2 -> 21281000 | G27: =18400+((B27-1)*4700) -> 121800 | H27: =ROUND(G27/1.2,-2) -> 101500 | I27: =IF(B27 <= 12, 200000, ROUNDUP(B27/3,0) * 50000) -> 400000 | J27: =IF(B27 <= 12, (35200+6500)*4, ROUNDUP(B27/3,0) * (35200+6500)) -> 333600 | K27: =IF(B27 <= 12, 100000, ROUNDUP(B27/3,0) * 30000) -> 240000 | L27: =IF(B27 <= 12, 80000, ROUNDUP(B27/3,0) * 26000) -> 208000 | M27: =C27+E27 -> 216537200 | N27: =D27+F27 -> 175281000 | O27: =M27-N27 -> 41256200 | P27: =O27/M27 -> 0.19052708 | Q27: =(G27+I27+K27)*24 -> 18283200 | R27: =(H27+J27+L27)*24 -> 15434400 | S27: =Q27-R27 -> 2848800 | T27: =S27/Q27 -> 0.15581517 | U27: =M27+Q27 -> 234820400 | V27: =N27+R27 -> 190715400 | W27: 23
... B34: 30 | C34: 253700000 | D34: 204700000 | E34: =E25+$E$13 -> 32292000 | F34: =E34/1.2 -> 26910000 | G34: =18400+((B34-1)*4700) -> 154700 | H34: =ROUND(G34/1.2,-2) -> 128900 | I34: =IF(B34 <= 12, 200000, ROUNDUP(B34/3,0) * 50000) -> 500000 | J34: =IF(B34 <= 12, (35200+6500)*4, ROUNDUP(B34/3,0) * (35200+6500)) -> 417000 | K34: =IF(B34 <= 12, 100000, ROUNDUP(B34/3,0) * 30000) -> 300000 | L34: =IF(B34 <= 12, 80000, ROUNDUP(B34/3,0) * 26000) -> 260000 | M34: =C34+E34 -> 285992000 | N34: =D34+F34 -> 231610000 | O34: =M34-N34 -> 54382000 | P34: =O34/M34 -> 0.19015217 | Q34: =(G34+I34+K34)*24 -> 22912800 | R34: =(H34+J34+L34)*24 -> 19341600 | S34: =Q34-R34 -> 3571200 | T34: =S34/Q34 -> 0.15586048 | U34: =M34+Q34 -> 308904800 | V34: =N34+R34 -> 250951600 | W34: 30
B35: 31 | C35: 262100000 | D35: 211400000 | E35: =E26+$E$13 -> 33342000 | F35: =E35/1.2 -> 27785000 | G35: =18400+((B35-1)*4700) -> 159400 | H35: =ROUND(G35/1.2,-2) -> 132800 | I35: =IF(B35 <= 12, 200000, ROUNDUP(B35/3,0) * 50000) -> 550000 | J35: =IF(B35 <= 12, (35200+6500)*4, ROUNDUP(B35/3,0) * (35200+6500)) -> 458700 | K35: =IF(B35 <= 12, 100000, ROUNDUP(B35/3,0) * 30000) -> 330000 | L35: =IF(B35 <= 12, 80000, ROUNDUP(B35/3,0) * 26000) -> 286000 | M35: =C35+E35 -> 295442000 | N35: =D35+F35 -> 239185000 | O35: =M35-N35 -> 56257000 | P35: =O35/M35 -> 0.19041639 | Q35: =(G35+I35+K35)*24 -> 24945600 | R35: =(H35+J35+L35)*24 -> 21060000 | S35: =Q35-R35 -> 3885600 | T35: =S35/Q35 -> 0.15576294 | U35: =M35+Q35 -> 320387600 | V35: =N35+R35 -> 260245000 | W35: 31 | X35: =SUM(M35:M54)/SUM($W$35:$W$54) -> 9854057.3 | Y35: =SUM(N35:N54)/SUM($W$35:$W$54) -> 7986467.5 | Z35: =SUM(Q35:Q54)/SUM($W$35:$W$54) -> 777511.11 | AA35: =SUM(R35:R54)/SUM($W$35:$W$54) -> 656411.85 | AB35: =SUM(U35:U54)/SUM($W$35:$W$54) -> 10631568 | AC35: =SUM(V35:V54)/SUM($W$35:$W$54) -> 8642879.3
B36: 32 | C36: 269700000 | D36: 217600000 | E36: =E27+$E$13 -> 34832400 | F36: =E36/1.2 -> 29027000 | G36: =18400+((B36-1)*4700) -> 164100 | H36: =ROUND(G36/1.2,-2) -> 136800 | I36: =IF(B36 <= 12, 200000, ROUNDUP(B36/3,0) * 50000) -> 550000 | J36: =IF(B36 <= 12, (35200+6500)*4, ROUNDUP(B36/3,0) * (35200+6500)) -> 458700 | K36: =IF(B36 <= 12, 100000, ROUNDUP(B36/3,0) * 30000) -> 330000 | L36: =IF(B36 <= 12, 80000, ROUNDUP(B36/3,0) * 26000) -> 286000 | M36: =C36+E36 -> 304532400 | N36: =D36+F36 -> 246627000 | O36: =M36-N36 -> 57905400 | P36: =O36/M36 -> 0.19014529 | Q36: =(G36+I36+K36)*24 -> 25058400 | R36: =(H36+J36+L36)*24 -> 21156000 | S36: =Q36-R36 -> 3902400 | T36: =S36/Q36 -> 0.15573221 | U36: =M36+Q36 -> 329590800 | V36: =N36+R36 -> 267783000 | W36: 32
B37: 33 | C37: 287600000 | D37: 232200000 | E37: =E28+$E$13 -> 35265600 | F37: =E37/1.2 -> 29388000 | G37: =18400+((B37-1)*4700) -> 168800 | H37: =ROUND(G37/1.2,-2) -> 140700 | I37: =IF(B37 <= 12, 200000, ROUNDUP(B37/3,0) * 50000) -> 550000 | J37: =IF(B37 <= 12, (35200+6500)*4, ROUNDUP(B37/3,0) * (35200+6500)) -> 458700 | K37: =IF(B37 <= 12, 100000, ROUNDUP(B37/3,0) * 30000) -> 330000 | L37: =IF(B37 <= 12, 80000, ROUNDUP(B37/3,0) * 26000) -> 286000 | M37: =C37+E37 -> 322865600 | N37: =D37+F37 -> 261588000 | O37: =M37-N37 -> 61277600 | P37: =O37/M37 -> 0.1897929 | Q37: =(G37+I37+K37)*24 -> 25171200 | R37: =(H37+J37+L37)*24 -> 21249600 | S37: =Q37-R37 -> 3921600 | T37: =S37/Q37 -> 0.1557971 | U37: =M37+Q37 -> 348036800 | V37: =N37+R37 -> 282837600 | W37: 33
B38: 34 | C38: 296200000 | D38: 239200000 | E38: =E29+$E$13 -> 36315600 | F38: =E38/1.2 -> 30263000 | G38: =18400+((B38-1)*4700) -> 173500 | H38: =ROUND(G38/1.2,-2) -> 144600 | I38: =IF(B38 <= 12, 200000, ROUNDUP(B38/3,0) * 50000) -> 600000 | J38: =IF(B38 <= 12, (35200+6500)*4, ROUNDUP(B38/3,0) * (35200+6500)) -> 500400 | K38: =IF(B38 <= 12, 100000, ROUNDUP(B38/3,0) * 30000) -> 360000 | L38: =IF(B38 <= 12, 80000, ROUNDUP(B38/3,0) * 26000) -> 312000 | M38: =C38+E38 -> 332515600 | N38: =D38+F38 -> 269463000 | O38: =M38-N38 -> 63052600 | P38: =O38/M38 -> 0.18962298 | Q38: =(G38+I38+K38)*24 -> 27204000 | R38: =(H38+J38+L38)*24 -> 22968000 | S38: =Q38-R38 -> 4236000 | T38: =S38/Q38 -> 0.1557124 | U38: =M38+Q38 -> 359719600 | V38: =N38+R38 -> 292431000 | W38: 34
B39: 35 | C39: 304100000 | D39: 245500000 | E39: =E30+$E$13 -> 36747600 | F39: =E39/1.2 -> 30623000 | G39: =18400+((B39-1)*4700) -> 178200 | H39: =ROUND(G39/1.2,-2) -> 148500 | I39: =IF(B39 <= 12, 200000, ROUNDUP(B39/3,0) * 50000) -> 600000 | J39: =IF(B39 <= 12, (35200+6500)*4, ROUNDUP(B39/3,0) * (35200+6500)) -> 500400 | K39: =IF(B39 <= 12, 100000, ROUNDUP(B39/3,0) * 30000) -> 360000 | L39: =IF(B39 <= 12, 80000, ROUNDUP(B39/3,0) * 26000) -> 312000 | M39: =C39+E39 -> 340847600 | N39: =D39+F39 -> 276123000 | O39: =M39-N39 -> 64724600 | P39: =O39/M39 -> 0.18989308 | Q39: =(G39+I39+K39)*24 -> 27316800 | R39: =(H39+J39+L39)*24 -> 23061600 | S39: =Q39-R39 -> 4255200 | T39: =S39/Q39 -> 0.15577227 | U39: =M39+Q39 -> 368164400 | V39: =N39+R39 -> 299184600 | W39: 35
B40: 36 | C40: 312000000 | D40: 251900000 | E40: =E31+$E$13 -> 37180800 | F40: =E40/1.2 -> 30984000 | G40: =18400+((B40-1)*4700) -> 182900 | H40: =ROUND(G40/1.2,-2) -> 152400 | I40: =IF(B40 <= 12, 200000, ROUNDUP(B40/3,0) * 50000) -> 600000 | J40: =IF(B40 <= 12, (35200+6500)*4, ROUNDUP(B40/3,0) * (35200+6500)) -> 500400 | K40: =IF(B40 <= 12, 100000, ROUNDUP(B40/3,0) * 30000) -> 360000 | L40: =IF(B40 <= 12, 80000, ROUNDUP(B40/3,0) * 26000) -> 312000 | M40: =C40+E40 -> 349180800 | N40: =D40+F40 -> 282884000 | O40: =M40-N40 -> 66296800 | P40: =O40/M40 -> 0.18986382 | Q40: =(G40+I40+K40)*24 -> 27429600 | R40: =(H40+J40+L40)*24 -> 23155200 | S40: =Q40-R40 -> 4274400 | T40: =S40/Q40 -> 0.15583166 | U40: =M40+Q40 -> 376610400 | V40: =N40+R40 -> 306039200 | W40: 36
B41: 37 | C41: 320600000 | D41: 258800000 | E41: =E32+$E$13 -> 40722000 | F41: =E41/1.2 -> 33935000 | G41: =18400+((B41-1)*4700) -> 187600 | H41: =ROUND(G41/1.2,-2) -> 156300 | I41: =IF(B41 <= 12, 200000, ROUNDUP(B41/3,0) * 50000) -> 650000 | J41: =IF(B41 <= 12, (35200+6500)*4, ROUNDUP(B41/3,0) * (35200+6500)) -> 542100 | K41: =IF(B41 <= 12, 100000, ROUNDUP(B41/3,0) * 30000) -> 390000 | L41: =IF(B41 <= 12, 80000, ROUNDUP(B41/3,0) * 26000) -> 338000 | M41: =C41+E41 -> 361322000 | N41: =D41+F41 -> 292735000 | O41: =M41-N41 -> 68587000 | P41: =O41/M41 -> 0.18982237 | Q41: =(G41+I41+K41)*24 -> 29462400 | R41: =(H41+J41+L41)*24 -> 24873600 | S41: =Q41-R41 -> 4588800 | T41: =S41/Q41 -> 0.15575106 | U41: =M41+Q41 -> 390784400 | V41: =N41+R41 -> 317608600 | W41: 37
B42: 38 | C42: 328500000 | D42: 265200000 | E42: =E33+$E$13 -> 41044000 | F42: =E42/1.2 -> 34203333 | G42: =18400+((B42-1)*4700) -> 192300 | H42: =ROUND(G42/1.2,-2) -> 160300 | I42: =IF(B42 <= 12, 200000, ROUNDUP(B42/3,0) * 50000) -> 650000 | J42: =IF(B42 <= 12, (35200+6500)*4, ROUNDUP(B42/3,0) * (35200+6500)) -> 542100 | K42: =IF(B42 <= 12, 100000, ROUNDUP(B42/3,0) * 30000) -> 390000 | L42: =IF(B42 <= 12, 80000, ROUNDUP(B42/3,0) * 26000) -> 338000 | M42: =C42+E42 -> 369544000 | N42: =D42+F42 -> 2.9940333e+08 | O42: =M42-N42 -> 70140667 | P42: =O42/M42 -> 0.18980329 | Q42: =(G42+I42+K42)*24 -> 29575200 | R42: =(H42+J42+L42)*24 -> 24969600 | S42: =Q42-R42 -> 4605600 | T42: =S42/Q42 -> 0.15572507 | U42: =M42+Q42 -> 399119200 | V42: =N42+R42 -> 3.2437293e+08 | W42: 38
B43: 39 | C43: 336400000 | D43: 271500000 | E43: =E34+$E$13 -> 41587200 | F43: =E43/1.2 -> 34656000 | G43: =18400+((B43-1)*4700) -> 197000 | H43: =ROUND(G43/1.2,-2) -> 164200 | I43: =IF(B43 <= 12, 200000, ROUNDUP(B43/3,0) * 50000) -> 650000 | J43: =IF(B43 <= 12, (35200+6500)*4, ROUNDUP(B43/3,0) * (35200+6500)) -> 542100 | K43: =IF(B43 <= 12, 100000, ROUNDUP(B43/3,0) * 30000) -> 390000 | L43: =IF(B43 <= 12, 80000, ROUNDUP(B43/3,0) * 26000) -> 338000 | M43: =C43+E43 -> 377987200 | N43: =D43+F43 -> 306156000 | O43: =M43-N43 -> 71831200 | P43: =O43/M43 -> 0.19003606 | Q43: =(G43+I43+K43)*24 -> 29688000 | R43: =(H43+J43+L43)*24 -> 25063200 | S43: =Q43-R43 -> 4624800 | T43: =S43/Q43 -> 0.15578011 | U43: =M43+Q43 -> 407675200 | V43: =N43+R43 -> 331219200 | W43: 39
B44: 40 | C44: 345000000 | D44: 278500000 | E44: =E35+$E$13 -> 42637200 | F44: =E44/1.2 -> 35531000 | G44: =18400+((B44-1)*4700) -> 201700 | H44: =ROUND(G44/1.2,-2) -> 168100 | I44: =IF(B44 <= 12, 200000, ROUNDUP(B44/3,0) * 50000) -> 700000 | J44: =IF(B44 <= 12, (35200+6500)*4, ROUNDUP(B44/3,0) * (35200+6500)) -> 583800 | K44: =IF(B44 <= 12, 100000, ROUNDUP(B44/3,0) * 30000) -> 420000 | L44: =IF(B44 <= 12, 80000, ROUNDUP(B44/3,0) * 26000) -> 364000 | M44: =C44+E44 -> 387637200 | N44: =D44+F44 -> 314031000 | O44: =M44-N44 -> 73606200 | P44: =O44/M44 -> 0.18988425 | Q44: =(G44+I44+K44)*24 -> 31720800 | R44: =(H44+J44+L44)*24 -> 26781600 | S44: =Q44-R44 -> 4939200 | T44: =S44/Q44 -> 0.15570856 | U44: =M44+Q44 -> 419358000 | V44: =N44+R44 -> 340812600 | W44: 40
B45: 41 | C45: 365100000 | D45: 295000000 | E45: =E36+$E$13 -> 44127600 | F45: =E45/1.2 -> 36773000 | G45: =18400+((B45-1)*4700) -> 206400 | H45: =ROUND(G45/1.2,-2) -> 172000 | I45: =IF(B45 <= 12, 200000, ROUNDUP(B45/3,0) * 50000) -> 700000 | J45: =IF(B45 <= 12, (35200+6500)*4, ROUNDUP(B45/3,0) * (35200+6500)) -> 583800 | K45: =IF(B45 <= 12, 100000, ROUNDUP(B45/3,0) * 30000) -> 420000 | L45: =IF(B45 <= 12, 80000, ROUNDUP(B45/3,0) * 26000) -> 364000 | M45: =C45+E45 -> 409227600 | N45: =D45+F45 -> 331773000 | O45: =M45-N45 -> 77454600 | P45: =O45/M45 -> 0.18927023 | Q45: =(G45+I45+K45)*24 -> 31833600 | R45: =(H45+J45+L45)*24 -> 26875200 | S45: =Q45-R45 -> 4958400 | T45: =S45/Q45 -> 0.15575995 | U45: =M45+Q45 -> 441061200 | V45: =N45+R45 -> 358648200 | W45: 41
B46: 42 | C46: 373200000 | D46: 301600000 | E46: =E37+$E$13 -> 44560800 | F46: =E46/1.2 -> 37134000 | G46: =18400+((B46-1)*4700) -> 211100 | H46: =ROUND(G46/1.2,-2) -> 175900 | I46: =IF(B46 <= 12, 200000, ROUNDUP(B46/3,0) * 50000) -> 700000 | J46: =IF(B46 <= 12, (35200+6500)*4, ROUNDUP(B46/3,0) * (35200+6500)) -> 583800 | K46: =IF(B46 <= 12, 100000, ROUNDUP(B46/3,0) * 30000) -> 420000 | L46: =IF(B46 <= 12, 80000, ROUNDUP(B46/3,0) * 26000) -> 364000 | M46: =C46+E46 -> 417760800 | N46: =D46+F46 -> 338734000 | O46: =M46-N46 -> 79026800 | P46: =O46/M46 -> 0.18916758 | Q46: =(G46+I46+K46)*24 -> 31946400 | R46: =(H46+J46+L46)*24 -> 26968800 | S46: =Q46-R46 -> 4977600 | T46: =S46/Q46 -> 0.15581098 | U46: =M46+Q46 -> 449707200 | V46: =N46+R46 -> 365702800 | W46: 42
B47: 43 | C47: 382100000 | D47: 308700000 | E47: =E38+$E$13 -> 45610800 | F47: =E47/1.2 -> 38009000 | G47: =18400+((B47-1)*4700) -> 215800 | H47: =ROUND(G47/1.2,-2) -> 179800 | I47: =IF(B47 <= 12, 200000, ROUNDUP(B47/3,0) * 50000) -> 750000 | J47: =IF(B47 <= 12, (35200+6500)*4, ROUNDUP(B47/3,0) * (35200+6500)) -> 625500 | K47: =IF(B47 <= 12, 100000, ROUNDUP(B47/3,0) * 30000) -> 450000 | L47: =IF(B47 <= 12, 80000, ROUNDUP(B47/3,0) * 26000) -> 390000 | M47: =C47+E47 -> 427710800 | N47: =D47+F47 -> 346709000 | O47: =M47-N47 -> 81001800 | P47: =O47/M47 -> 0.18938451 | Q47: =(G47+I47+K47)*24 -> 33979200 | R47: =(H47+J47+L47)*24 -> 28687200 | S47: =Q47-R47 -> 5292000 | T47: =S47/Q47 -> 0.15574234 | U47: =M47+Q47 -> 461690000 | V47: =N47+R47 -> 375396200 | W47: 43
...

Sheet 노즐공사갑지
A1: 견 적 서
C2: 귀중 | E2: 사업자등록번호 : 707 - 86 - 02404
A3: 견적 금액 : | E3: 상호 : ㈜에스앤아이코퍼레이션 대표자 : 형 원 준 | O3: 주차면수 | P3: 급수배관 거리(M) | Q3: 분전반 거리(M) | R3: 원격관제 비용/월 | S3: CCTV 대수 | T3: AI CCTV 비용/월
A4: 견적 제출일자 : | E4: 주소 : 서울 강서구 마곡중앙로 150 D&O강서사옥 | O4: 5 | P4: 50 | Q4: 50 | R4: =18400+((노즐공사갑지!O4-1)*4700) -> 37200 | S4: =ROUNDUP(O4/3, 0) -> 2 | T4: =IF(S4 <= 4, 280000, 280000 + (S4 - 4) * 70000) -> 280000
A5: 견적 유효기간 : | B5: 견적 제출일로부터 30일 | E5: T. 1661-1119 www.sni.co.kr | O5: ※AICCTV는 주차면수 12면까지는 28만원/월 고정, 3면에 1대 설치
A7: (VAT별도) | B7: =E20 -> 46900000 | M7: 원가내역
A8: 공 종 명 | C8: 규 격 | E8: 합 계 | F8: 비 고 | I8: 공 종 명 | K8: 규 격 | M8: 합 계
A9: 1. 전기차 화재 진압 솔루션 | E9: =SUM(E10:E11) -> 43846234 | I9: 1. 전기차 화재 진압 솔루션 | M9: =SUM(M10:M11) -> 35439937
A10: 자재비 | E10: =노즐공사매출!G61 -> 29826211 | I10: 자재비 | M10: =노즐공사원가!G61 -> 23698597
A11: 노무비 | E11: =노즐공사매출!I61 -> 14020023 | I11: 노무비 | M11: =노즐공사원가!I61 -> 11741340
A12: 2. 간접비 | E12: =SUM(E13:E18) -> 3117683.3 | I12: 2. 간접비 | M12: =SUM(M13:M18) -> 2573462
A13: =노즐공사매출!B54 -> 산재보험료 | C13: 노무비 x 3.56% | E13: =노즐공사매출!K54 -> 499112.82 | I13: =노즐공사매출!J54 -> 499112.82 | K13: 노무비 x 3.56% | M13: =노즐공사원가!K54 -> 417991.69
A14: =노즐공사매출!B55 -> 고용보험료 | C14: 노무비 x 1.01% | E14: =노즐공사매출!K55 -> 141602.23 | I14: =노즐공사매출!J55 -> 141602.23 | K14: 노무비 x 1.01% | M14: =노즐공사원가!K55 -> 118587.53
A15: =노즐공사매출!B56 -> 건강보험료 | C15: 노무비 x 3.545% | E15: =노즐공사매출!K56 -> 497009.81 | I15: =노즐공사매출!J56 -> 497009.81 | K15: 노무비 x 3.545% | M15: =노즐공사원가!K56 -> 416230.49
A16: =노즐공사매출!B57 -> 장기요양보험료 | C16: 건강보험료 x 12.95% | E16: =노즐공사매출!K57 -> 64362.771 | I16: =노즐공사매출!J57 -> 64362.771 | K16: 건강보험료 x 12.95% | M16: =노즐공사원가!K57 -> 53901.848
A17: =노즐공사매출!B58 -> 연금보험료 | C17: 노무비 x 4.5% | E17: =노즐공사매출!K58 -> 630901.03 | I17: =노즐공사매출!J58 -> 630901.03 | K17: 노무비 x 4.5% | M17: =노즐공사원가!K58 -> 528360.28
A18: =노즐공사매출!B59 -> 안전관리비 | C18: (재료비+노무비) x 2.93% | E18: =노즐공사매출!K59 -> 1284694.7 | I18: =노즐공사매출!J59 -> 1284694.7 | K18: (재료비+노무비) x 2.93% | M18: =노즐공사원가!K59 -> 1038390.2
A19: 절 삭 | E19: =SUM(E9,E12)-E20 -> 63917.754 | I19: 절 삭 | M19: =SUM(M9,M12)-M20 -> 13398.863
A20: 공사 비용 | E20: =ROUNDDOWN(SUM(E9,E12), -5) -> 46900000 | I20: 공사 비용 | M20: =ROUNDDOWN(SUM(M9,M12), -5) -> 38000000
A21: 유지보수 항목 | E21: 비용 / 월 | M21: AI CCTV 원가 제외
A22: 1. 원격관제 | E22: =R4 -> 37200 | F22: 관제 및 설비 작동
A23: 2. AI CCTV | E23: =T4 -> 280000 | F23: 전기차 화재 연기 감지
A24: 3. 작동/불량 정기점검 | E24: 50000 | F24: 반기 1회 현장 방문
A25: 유지보수 비용 | E25: =SUM(E22:E24) -> 367200
A26: 참고사항 | B26: 1. 부가세 별도 2. 급수배관이 적정압력(4kg/㎠) 이하일 경우 가압펌프 설치 필요(현장에 따라 추가견적 필요) 3. 포함내역 : 현장 공사 비용, CCTV 설치비용(현장에 설치되어 있을 시 견적 제외), 원격감시시스템 구축비용 - AI CCTV는 2년 약정 1. AI CCTV 1대 당 주차 3면 감지 가능 2. 1대~4대 : 28만원, 추가 1대당 7만원씩 발생
A27: 담당자

Sheet 노즐공사매출
A1: 내 역 서
A3: 순 번 | B3: 품 명 | C3: 규 격 | D3: 단 위 | E3: 수 량 | F3: Material Cost | H3: Labor Cost | J3: Total | L3: 비 고
F4: Unit | G4: Sum | H4: Unit | I4: Sum | J4: Unit | K4: Sum
A5: 1 | B5: 전기차 충전소 화재 대응 솔루션
B6: Nozzle PLATE | C6: STS 4T | D6: SET | E6: =노즐공사갑지!O4 -> 5 | F6: 3500000 | G6: =TRUNC(F6*E6,0) -> 17500000 | H6: 150000 | I6: =TRUNC(H6*E6,0) -> 750000 | J6: =F6+H6 -> 3650000 | K6: =G6+I6 -> 18250000
I7: =TRUNC(H7*E7,0) -> 0 | J7: =F7+H7 -> 0 | K7: =G7+I7 -> 0 | M7: RMS 구축표
G8: =SUM(G6:G7) -> 17500000 | I8: =SUM(I6:I7) -> 750000 | K8: =SUM(K6:K7) -> 18250000 | M8: 면수 | N8: 금액 | O8: 원가
A9: 2 | B9: 주차면 배관 구축 | M9: 1 | N9: 3541200 | O9: =N9/1.2 -> 2951000
B10: STS관(K-TYPE) | C10: D32 | D10: M | E10: =E6*6 -> 30 | F10: 22356 | G10: =TRUNC(F10*E10,0) -> 670680 | H10: 35434.8 | I10: =TRUNC(H10*E10,0) -> 1063044 | J10: =F10+H10 -> 57790.8 | K10: =G10+I10 -> 1733724 | M10: 2 | N10: 3863200 | O10: =N10/1.2 -> 3219333.3
B11: 관부속(SR) | C11: 관의 75% | D11: 식 | E11: 1 | F11: =G10*0.75 -> 503010 | G11: =TRUNC(F11*E11,0) -> 503010 | H11: 0 | I11: =TRUNC(H11*E11,0) -> 0 | J11: =F11+H11 -> 503010 | K11: =G11+I11 -> 503010 | M11: 3 | N11: 4406400 | O11: =N11/1.2 -> 3672000
B12: 볼 밸브(STS, Drain) | C12: D32 | D12: EA | E12: =E6 -> 5 | F12: 39821.976 | G12: =TRUNC(F12*E12,0) -> 199109 | H12: 19014 | I12: =TRUNC(H12*E12,0) -> 95070 | J12: =F12+H12 -> 58835.976 | K12: =G12+I12 -> 294179 | M12: 4 | N12: 5456400 | O12: =N12/1.2 -> 4547000
B13: 전자변(ON/OFF) , AC220 | C13: D32 | D13: 개소 | E13: =E6 -> 5 | F13: 282788.03 | G13: =TRUNC(F13*E13,0) -> 1413940 | H13: 19014 | I13: =TRUNC(H13*E13,0) -> 95070 | J13: =F13+H13 -> 301802.03 | K13: =G13+I13 -> 1509010 | M13: 5 | N13: 6946800 | O13: =N13/1.2 -> 5789000
B14: 지지철물 및 잡재료비 | C14: 관의 15% | D14: 식 | E14: 1 | F14: =G10*0.15 -> 100602 | G14: =TRUNC(F14*E14,0) -> 100602 | H14: 0 | I14: =TRUNC(H14*E14,0) -> 0 | J14: =F14+H14 -> 100602 | K14: =G14+I14 -> 100602 | M14: 6 | N14: 7380000 | O14: =N14/1.2 -> 6150000
B15: 파이프덮개 | C15: 제작물 | D15: 식 | E15: =E6 -> 5 | F15: 360000 | G15: =TRUNC(F15*E15,0) -> 1800000 | H15: 9481.2 | I15: =TRUNC(H15*E15,0) -> 47406 | J15: =F15+H15 -> 369481.2 | K15: =G15+I15 -> 1847406 | M15: 7 | N15: 8430000 | O15: =N15/1.2 -> 7025000
B16: 공구손료 | C16: 노무비의 3% | D16: 식 | E16: 1 | H16: =SUM(I9:I15)*0.03 -> 39017.7 | I16: =H16*E16 -> 39017.7 | J16: =F16+H16 -> 39017.7 | K16: =G16+I16 -> 39017.7 | M16: 8 | N16: 8862000 | O16: =N16/1.2 -> 7385000
F17: 0 | G17: =SUM(G9:G16) -> 4687341 | H17: 0 | I17: =SUM(I9:I16) -> 1339607.7 | K17: =SUM(K9:K16) -> 6026948.7 | M17: 9 | N17: 9295200 | O17: =N17/1.2 -> 7746000
A18: 3 | B18: 메인배관구축 | F18: 0 | H18: 0 | M18: 10 | N18: =$N$17+N9 -> 12836400 | O18: =N18/1.2 -> 10697000
B19: STS관(K-TYPE) | C19: D50 | D19: M | E19: =노즐공사갑지!P4 -> 50 | F19: 26846 | G19: =TRUNC(F19*E19,0) -> 1342300 | H19: 41371.2 | I19: =TRUNC(H19*E19,0) -> 2068560 | J19: =F19+H19 -> 68217.2 | K19: =G19+I19 -> 3410860 | M19: 11 | N19: =$N$17+N10 -> 13158400 | O19: =N19/1.2 -> 10965333
B20: 관부속(SR) | C20: 관의 75% | D20: 식 | E20: 1 | F20: =G19*0.75 -> 1006725 | G20: =TRUNC(F20*E20,0) -> 1006725 | H20: 0 | I20: =TRUNC(H20*E20,0) -> 0 | J20: =F20+H20 -> 1006725 | K20: =G20+I20 -> 1006725 | M20: 12 | N20: =$N$17+N11 -> 13701600 | O20: =N20/1.2 -> 11418000
B21: 코어천공 | C21: D40 | D21: 식 | E21: 1 | F21: 1171.7784 | G21: =TRUNC(F21*E21,0) -> 1171 | H21: 60879.6 | I21: =TRUNC(H21*E21,0) -> 60879 | J21: =F21+H21 -> 62051.378 | K21: =G21+I21 -> 62050 | M21: 13 | N21: =$N$17+N12 -> 14751600 | O21: =N21/1.2 -> 12293000
B22: 볼 밸브(STS, By pass) | C22: D40 | D22: EA | E22: 3 | F22: 50245.488 | G22: =TRUNC(F22*E22,0) -> 150736 | H22: 19014 | I22: =TRUNC(H22*E22,0) -> 57042 | J22: =F22+H22 -> 69259.488 | K22: =G22+I22 -> 207778 | M22: 14 | N22: =$N$17+N13 -> 16242000 | O22: =N22/1.2 -> 13535000
B23: 압력계설치 | C23: 2 - 15㎏/㎠ | D23: 개소 | E23: 3 | F23: 13140.328 | G23: =TRUNC(F23*E23,0) -> 39420 | H23: 10560 | I23: =TRUNC(H23*E23,0) -> 31680 | J23: =F23+H23 -> 23700.328 | K23: =G23+I23 -> 71100 | M23: 15 | N23: =$N$17+N14 -> 16675200 | O23: =N23/1.2 -> 13896000
B24: 메인배관 분기공사 | C24: D40 | D24: 식 | E24: 1 | F24: 346680 | G24: =TRUNC(F24*E24,0) -> 346680 | H24: 0 | I24: =TRUNC(H24*E24,0) -> 0 | J24: =F24+H24 -> 346680 | K24: =G24+I24 -> 346680 | M24: 16 | N24: =$N$17+N15 -> 17725200 | O24: =N24/1.2 -> 14771000
B25: 전자변(ON/OFF) , AC220 | C25: D40 | D25: 개소 | E25: 1 | F25: 299935.98 | G25: =TRUNC(F25*E25,0) -> 299935 | H25: 19014 | I25: =TRUNC(H25*E25,0) -> 19014 | J25: =F25+H25 -> 318949.98 | K25: =G25+I25 -> 318949 | M25: 17 | N25: =$N$17+N16 -> 18157200 | O25: =N25/1.2 -> 15131000
B26: 지지철물 및 잡재료비 | C26: 관의 15% | D26: 식 | E26: 1 | F26: =G19*0.15 -> 201345 | G26: =TRUNC(F26*E26,0) -> 201345 | H26: 0 | I26: =TRUNC(H26*E26,0) -> 0 | J26: =F26+H26 -> 201345 | K26: =G26+I26 -> 201345 | M26: 18 | N26: =$N$17+N17 -> 18590400 | O26: =N26/1.2 -> 15492000
B27: 공구손료 | C27: 노무비의 3% | D27: 식 | E27: 1 | H27: =SUM(I18:I26)*0.03 -> 67115.25 | I27: =TRUNC(H27*G27,0) -> 0 | J27: =F27+H27 -> 67115.25 | K27: =G27+I27 -> 0 | M27: 19 | N27: =$N$17+N18 -> 22131600 | O27: =N27/1.2 -> 18443000
F28: 0 | G28: =SUM(G18:G27) -> 3388312 | H28: 0 | I28: =SUM(I18:I27) -> 2237175 | K28: =SUM(K18:K27) -> 5625487 | M28: 20 | N28: =$N$17+N19 -> 22453600 | O28: =N28/1.2 -> 18711333
A29: 4 | B29: 전기설비공사 | F29: 0 | H29: 0 | M29: 21 | N29: =$N$17+N20 -> 22996800 | O29: =N29/1.2 -> 19164000
B30: 분전반 설치작업 | F30: 0 | H30: 0 | M30: 22 | N30: =$N$17+N21 -> 24046800 | O30: =N30/1.2 -> 20039000
B31: 강제전선관 | C31: 아연도 28 mm | D31: M | E31: =E33/1.2 -> 41.666667 | F31: 6070.3668 | G31: =F31*E31 -> 252931.95 | H31: 32689.2 | I31: =H31*E31 -> 1362050 | J31: =F31+H31 -> 38759.567 | K31: =G31+I31 -> 1614982 | M31: 23 | N31: =$N$17+N22 -> 25537200 | O31: =N31/1.2 -> 21281000
B32: 관부속(SR) | C32: 전선관의 15 % | D32: 식 | E32: 1 | F32: =G31*0.15 -> 37939.793 | G32: =F32*E32 -> 37939.793 | H32: 0 | I32: =H32*E32 -> 0 | J32: =F32+H32 -> 37939.793 | K32: =G32+I32 -> 37939.793 | M32: 24 | N32: =$N$17+N23 -> 25970400 | O32: =N32/1.2 -> 21642000
B33: F-CV케이블 | C33: 6㎟ ＊ 0.6/1KV 3C 6㎟ | D33: M | E33: =노즐공사갑지!Q4 -> 50 | F33: 4465.2384 | G33: =F33*E33 -> 223261.92 | H33: 4239.203 | I33: =H33*E33 -> 211960.15 | J33: =F33+H33 -> 8704.4414 | K33: =G33+I33 -> 435222.07 | M33: 25 | N33: =$N$17+N24 -> 27020400 | O33: =N33/1.2 -> 22517000
B34: 셋트앵커 | C34: M8×L70mm | D34: 개 | E34: =4+(E31/1.5) -> 31.777778 | F34: 528 | G34: =F34*E34 -> 16778.667 | H34: 12608.4 | I34: =H34*E34 -> 400666.93 | J34: =F34+H34 -> 13136.4 | K34: =G34+I34 -> 417445.6 | M34: 26 | N34: =$N$17+N25 -> 27452400 | O34: =N34/1.2 -> 22877000
B35: 분전함 | C35: 소방컨트롤 판넬 | D35: 면 | E35: =ROUNDUP(E6/8,0) -> 1 | F35: =(1500000+(E6*200000))*1.2 -> 3000000 | G35: =F35*E35 -> 3000000 | H35: 194581.2 | I35: =H35*E35 -> 194581.2 | J35: =F35+H35 -> 3194581.2 | K35: =G35+I35 -> 3194581.2 | M35: 27 | N35: =$N$17+N26 -> 27885600 | O35: =N35/1.2 -> 23238000
B36: 밸브 전원 포설 | F36: 0 | H36: 0 | M36: 28 | N36: =$N$17+N27 -> 31426800 | O36: =N36/1.2 -> 26189000
B37: 강제전선관 | C37: 아연도 16 mm | D37: M | E37: =INT(176/10*노즐공사원가!E6) -> 88 | F37: 3238.8 | G37: =F37*E37 -> 285014.4 | H37: 18679.2 | I37: =H37*E37 -> 1643769.6 | J37: =F37+H37 -> 21918 | K37: =G37+I37 -> 1928784 | M37: 29 | N37: =$N$17+N28 -> 31748800 | O37: =N37/1.2 -> 26457333
B38: 관부속(SR) | C38: 전선관의 15 % | D38: 식 | E38: 1 | F38: =G37*0.15 -> 42752.16 | G38: =F38*E38 -> 42752.16 | H38: 0 | I38: =H38*E38 -> 0 | J38: =F38+H38 -> 42752.16 | K38: =G38+I38 -> 42752.16 | M38: 30 | N38: =$N$17+N29 -> 32292000 | O38: =N38/1.2 -> 26910000
B39: 450/750V 내열비닐절연전선 | C39: HFIX 1.78mm(2.5㎟) | D39: M | E39: =E37*1.2 -> 105.6 | F39: 684 | G39: =F39*E39 -> 72230.4 | H39: 1946.4 | I39: =H39*E39 -> 205539.84 | J39: =F39+H39 -> 2630.4 | K39: =G39+I39 -> 277770.24 | M39: 31 | N39: =$N$17+N30 -> 33342000 | O39: =N39/1.2 -> 27785000
B40: 아우트렛박스 | C40: 중형4각 54㎜ | D40: 개 | E40: =노즐공사원가!E6 -> 5 | F40: 1209.3585 | G40: =F40*E40 -> 6046.7926 | H40: 47698.478 | I40: =H40*E40 -> 238492.39 | J40: =F40+H40 -> 48907.836 | K40: =G40+I40 -> 244539.18 | M40: 32 | N40: =$N$17+N31 -> 34832400 | O40: =N40/1.2 -> 29027000
B41: 아우트렛박스 커버 | C41: 4각 1개용 | D41: 개 | E41: =노즐공사원가!E6 -> 5 | F41: 376.77182 | G41: =F41*E41 -> 1883.8591 | H41: 5962.3097 | I41: =H41*E41 -> 29811.548 | J41: =F41+H41 -> 6339.0815 | K41: =G41+I41 -> 31695.408 | M41: 33 | N41: =$N$17+N32 -> 35265600 | O41: =N41/1.2 -> 29388000
...

Sheet 노즐공사원가
A1: 내 역 서
A3: 순 번 | B3: 품 명 | C3: 규 격 | D3: 단 위 | E3: 수 량 | F3: Material Cost | H3: Labor Cost | J3: Total | L3: 비 고
F4: Unit | G4: Sum | H4: Unit | I4: Sum | J4: Unit | K4: Sum
A5: 1 | B5: 전기차 충전소 화재 대응 솔루션
B6: Nozzle PLATE | C6: STS 4T | D6: SET | E6: =노즐공사갑지!O4 -> 5 | F6: 2700000 | G6: =TRUNC(F6*E6,0) -> 13500000 | I6: =TRUNC(H6*E6,0) -> 0 | J6: =F6+H6 -> 2700000 | K6: =G6+I6 -> 13500000
I7: =TRUNC(H7*E7,0) -> 0 | J7: =F7+H7 -> 0 | K7: =G7+I7 -> 0 | M7: RMS 구축표
G8: =SUM(G6:G7) -> 13500000 | I8: =SUM(I6:I7) -> 0 | K8: =SUM(K6:K7) -> 13500000 | M8: 면수 | N8: 금액
A9: 2 | B9: 주차면 배관 구축 | M9: 1 | N9: 3541200 | O9: =N9/1.2 -> 2951000
B10: STS관(K-TYPE) | C10: D32 | D10: M | E10: =E6*6 -> 30 | F10: 16539 | G10: =TRUNC(F10*E10,0) -> 496170 | H10: 29529 | I10: =TRUNC(H10*E10,0) -> 885870 | J10: =F10+H10 -> 46068 | K10: =G10+I10 -> 1382040 | M10: 2 | N10: 3863200 | O10: =N10/1.2 -> 3219333.3
B11: 관부속(SR) | C11: 관의 75% | D11: 식 | E11: 1 | F11: =G10*0.75 -> 372127.5 | G11: =TRUNC(F11*E11,0) -> 372127 | H11: 0 | I11: =TRUNC(H11*E11,0) -> 0 | J11: =F11+H11 -> 372127.5 | K11: =G11+I11 -> 372127 | M11: 3 | N11: 4406400 | O11: =N11/1.2 -> 3672000
B12: 볼 밸브(STS, Drain) | C12: D32 | D12: EA | E12: =E6 -> 5 | F12: 34460 | G12: =TRUNC(F12*E12,0) -> 172300 | H12: 15845 | I12: =TRUNC(H12*E12,0) -> 79225 | J12: =F12+H12 -> 50305 | K12: =G12+I12 -> 251525 | M12: 4 | N12: 5456400 | O12: =N12/1.2 -> 4547000
B13: 전자변(ON/OFF) , AC220 | C13: D32 | D13: 개소 | E13: =E6 -> 5 | F13: 244711 | G13: =TRUNC(F13*E13,0) -> 1223555 | H13: 15845 | I13: =TRUNC(H13*E13,0) -> 79225 | J13: =F13+H13 -> 260556 | K13: =G13+I13 -> 1302780 | M13: 5 | N13: 6946800 | O13: =N13/1.2 -> 5789000
B14: 지지철물 및 잡재료비 | C14: 관의 15% | D14: 식 | E14: 1 | F14: =G10*0.15 -> 74425.5 | G14: =TRUNC(F14*E14,0) -> 74425 | H14: 0 | I14: =TRUNC(H14*E14,0) -> 0 | J14: =F14+H14 -> 74425.5 | K14: =G14+I14 -> 74425 | M14: 6 | N14: 7380000 | O14: =N14/1.2 -> 6150000
B15: 파이프덮개 | C15: 제작물 | D15: 식 | E15: =E6 -> 5 | F15: 300000 | G15: =TRUNC(F15*E15,0) -> 1500000 | H15: 7901 | I15: =TRUNC(H15*E15,0) -> 39505 | J15: =F15+H15 -> 307901 | K15: =G15+I15 -> 1539505 | M15: 7 | N15: 8430000 | O15: =N15/1.2 -> 7025000
B16: 공구손료 | C16: 노무비의 3% | D16: 식 | E16: 1 | H16: =SUM(I9:I15)*0.03 -> 32514.75 | I16: =H16*E16 -> 32514.75 | J16: =F16+H16 -> 32514.75 | K16: =G16+I16 -> 32514.75 | M16: 8 | N16: 8862000 | O16: =N16/1.2 -> 7385000
F17: 0 | G17: =SUM(G9:G16) -> 3838577 | H17: 0 | I17: =SUM(I9:I16) -> 1116339.8 | K17: =SUM(K9:K16) -> 4954916.8 | M17: 9 | N17: 9295200 | O17: =N17/1.2 -> 7746000
A18: 3 | B18: 메인배관구축 | F18: 0 | H18: 0 | M18: 10 | N18: =$N$17+N9 -> 12836400 | O18: =N18/1.2 -> 10697000
B19: STS관(K-TYPE) | C19: D50 | D19: M | E19: =노즐공사갑지!P4 -> 50 | F19: 22372 | G19: =TRUNC(F19*E19,0) -> 1118600 | H19: 34476 | I19: =TRUNC(H19*E19,0) -> 1723800 | J19: =F19+H19 -> 56848 | K19: =G19+I19 -> 2842400 | M19: 11 | N19: =$N$17+N10 -> 13158400 | O19: =N19/1.2 -> 10965333
B20: 관부속(SR) | C20: 관의 75% | D20: 식 | E20: 1 | F20: =G19*0.75 -> 838950 | G20: =TRUNC(F20*E20,0) -> 838950 | H20: 0 | I20: =TRUNC(H20*E20,0) -> 0 | J20: =F20+H20 -> 838950 | K20: =G20+I20 -> 838950 | M20: 12 | N20: =$N$17+N11 -> 13701600 | O20: =N20/1.2 -> 11418000
B21: 코어천공 | C21: D40 | D21: 식 | E21: 1 | F21: 1014 | G21: =TRUNC(F21*E21,0) -> 1014 | H21: 50733 | I21: =TRUNC(H21*E21,0) -> 50733 | J21: =F21+H21 -> 51747 | K21: =G21+I21 -> 51747 | M21: 13 | N21: =$N$17+N12 -> 14751600 | O21: =N21/1.2 -> 12293000
B22: 볼 밸브(STS, By pass) | C22: D40 | D22: EA | E22: 3 | F22: 43480 | G22: =TRUNC(F22*E22,0) -> 130440 | H22: 15845 | I22: =TRUNC(H22*E22,0) -> 47535 | J22: =F22+H22 -> 59325 | K22: =G22+I22 -> 177975 | M22: 14 | N22: =$N$17+N13 -> 16242000 | O22: =N22/1.2 -> 13535000
B23: 압력계설치 | C23: 2 - 15㎏/㎠ | D23: 개소 | E23: 3 | F23: 11371 | G23: =TRUNC(F23*E23,0) -> 34113 | H23: 8800 | I23: =TRUNC(H23*E23,0) -> 26400 | J23: =F23+H23 -> 20171 | K23: =G23+I23 -> 60513 | M23: 15 | N23: =$N$17+N14 -> 16675200 | O23: =N23/1.2 -> 13896000
B24: 메인배관 분기공사 | C24: D40 | D24: 식 | E24: 1 | F24: 300000 | G24: =TRUNC(F24*E24,0) -> 300000 | H24: 0 | I24: =TRUNC(H24*E24,0) -> 0 | J24: =F24+H24 -> 300000 | K24: =G24+I24 -> 300000 | M24: 16 | N24: =$N$17+N15 -> 17725200 | O24: =N24/1.2 -> 14771000
B25: 전자변(ON/OFF) , AC220 | C25: D40 | D25: 개소 | E25: 1 | F25: 259550 | G25: =TRUNC(F25*E25,0) -> 259550 | H25: 15845 | I25: =TRUNC(H25*E25,0) -> 15845 | J25: =F25+H25 -> 275395 | K25: =G25+I25 -> 275395 | M25: 17 | N25: =$N$17+N16 -> 18157200 | O25: =N25/1.2 -> 15131000
B26: 지지철물 및 잡재료비 | C26: 관의 15% | D26: 식 | E26: 1 | F26: =G19*0.15 -> 167790 | G26: =TRUNC(F26*E26,0) -> 167790 | H26: 0 | I26: =TRUNC(H26*E26,0) -> 0 | J26: =F26+H26 -> 167790 | K26: =G26+I26 -> 167790 | M26: 18 | N26: =$N$17+N17 -> 18590400 | O26: =N26/1.2 -> 15492000
B27: 공구손료 | C27: 노무비의 3% | D27: 식 | E27: 1 | H27: =SUM(I18:I26)*0.03 -> 55929.39 | I27: =TRUNC(H27*G27,0) -> 0 | J27: =F27+H27 -> 55929.39 | K27: =G27+I27 -> 0 | M27: 19 | N27: =$N$17+N18 -> 22131600 | O27: =N27/1.2 -> 18443000
F28: 0 | G28: =SUM(G18:G27) -> 2850457 | H28: 0 | I28: =SUM(I18:I27) -> 1864313 | K28: =SUM(K18:K27) -> 4714770 | M28: 20 | N28: =$N$17+N19 -> 22453600 | O28: =N28/1.2 -> 18711333
A29: 4 | B29: 전기설비공사 | F29: 0 | H29: 0 | M29: 21 | N29: =$N$17+N20 -> 22996800 | O29: =N29/1.2 -> 19164000
B30: 분전반 설치작업 | F30: 0 | H30: 0 | M30: 22 | N30: =$N$17+N21 -> 24046800 | O30: =N30/1.2 -> 20039000
B31: 강제전선관 | C31: 아연도 28 mm | D31: M | E31: =E33/1.2 -> 41.666667 | F31: 4567 | G31: =F31*E31 -> 190291.67 | H31: 27241 | I31: =H31*E31 -> 1135041.7 | J31: =F31+H31 -> 31808 | K31: =G31+I31 -> 1325333.3 | M31: 23 | N31: =$N$17+N22 -> 25537200 | O31: =N31/1.2 -> 21281000
B32: 관부속(SR) | C32: 전선관의 15 % | D32: 식 | E32: 1 | F32: =G31*0.15 -> 28543.75 | G32: =F32*E32 -> 28543.75 | H32: 0 | I32: =H32*E32 -> 0 | J32: =F32+H32 -> 28543.75 | K32: =G32+I32 -> 28543.75 | M32: 24 | N32: =$N$17+N23 -> 25970400 | O32: =N32/1.2 -> 21642000
B33: F-CV케이블 | C33: 6㎟ ＊ 0.6/1KV 3C 6㎟ | D33: M | E33: =노즐공사갑지!Q4 -> 50 | F33: 3721.032 | G33: =F33*E33 -> 186051.6 | H33: 3532.6692 | I33: =H33*E33 -> 176633.46 | J33: =F33+H33 -> 7253.7012 | K33: =G33+I33 -> 362685.06 | M33: 25 | N33: =$N$17+N24 -> 27020400 | O33: =N33/1.2 -> 22517000
B34: 셋트앵커 | C34: M8×L70mm | D34: 개 | E34: =4+(E31/1.5) -> 31.777778 | F34: 440 | G34: =F34*E34 -> 13982.222 | H34: 10507 | I34: =H34*E34 -> 333889.11 | J34: =F34+H34 -> 10947 | K34: =G34+I34 -> 347871.33 | M34: 26 | N34: =$N$17+N25 -> 27452400 | O34: =N34/1.2 -> 22877000
B35: 분전함 | C35: 소방컨트롤 판넬 | D35: 면 | E35: =ROUNDUP(E6/8,0) -> 1 | F35: =(1500000+(E6*200000)) -> 2500000 | G35: =F35*E35 -> 2500000 | H35: 162151 | I35: =H35*E35 -> 162151 | J35: =F35+H35 -> 2662151 | K35: =G35+I35 -> 2662151 | M35: 27 | N35: =$N$17+N26 -> 27885600 | O35: =N35/1.2 -> 23238000
B36: 밸브 전원 포설 | F36: 0 | G36: =F36*E36 -> 0 | H36: 0 | I36: =H36*E36 -> 0 | K36: =G36+I36 -> 0 | M36: 28 | N36: =$N$17+N27 -> 31426800 | O36: =N36/1.2 -> 26189000
B37: 강제전선관 | C37: 아연도 16 mm | D37: M | E37: =INT(176/10*노즐공사원가!E6) -> 88 | F37: 2699 | G37: =F37*E37 -> 237512 | H37: 15566 | I37: =H37*E37 -> 1369808 | J37: =F37+H37 -> 18265 | K37: =G37+I37 -> 1607320 | M37: 29 | N37: =$N$17+N28 -> 31748800 | O37: =N37/1.2 -> 26457333
B38: 관부속(SR) | C38: 전선관의 15 % | D38: 식 | E38: 1 | F38: =G37*0.15 -> 35626.8 | G38: =F38*E38 -> 35626.8 | H38: 0 | I38: =H38*E38 -> 0 | J38: =F38+H38 -> 35626.8 | K38: =G38+I38 -> 35626.8 | M38: 30 | N38: =$N$17+N29 -> 32292000 | O38: =N38/1.2 -> 26910000
B39: 450/750V 내열비닐절연전선 | C39: HFIX 1.78mm(2.5㎟) | D39: M | E39: =E37*1.2 -> 105.6 | F39: 570 | G39: =F39*E39 -> 60192 | H39: 1622 | I39: =H39*E39 -> 171283.2 | J39: =F39+H39 -> 2192 | K39: =G39+I39 -> 231475.2 | M39: 31 | N39: =$N$17+N30 -> 33342000 | O39: =N39/1.2 -> 27785000
B40: 아우트렛박스 | C40: 중형4각 54㎜ | D40: 개 | E40: =노즐공사원가!E6 -> 5 | F40: 1007.7988 | G40: =F40*E40 -> 5038.9938 | H40: 39748.731 | I40: =H40*E40 -> 198743.66 | J40: =F40+H40 -> 40756.53 | K40: =G40+I40 -> 203782.65 | M40: 32 | N40: =$N$17+N31 -> 34832400 | O40: =N40/1.2 -> 29027000
B41: 아우트렛박스 커버 | C41: 4각 1개용 | D41: 개 | E41: =노즐공사원가!E6 -> 5 | F41: 313.97652 | G41: =F41*E41 -> 1569.8826 | H41: 4968.5914 | I41: =H41*E41 -> 24842.957 | J41: =F41+H41 -> 5282.5679 | K41: =G41+I41 -> 26412.84 | M41: 33 | N41: =$N$17+N32 -> 35265600 | O41: =N41/1.2 -> 29388000
...

Sheet 노즐공사가격테이블
B2: (부가세별도, 급수배관거리 50m, 분전반거리 50m 기준)
C3: 노즐플레이트 공사 | M3: 설치 공사 재무 | Q3: 면당재무
B4: 면수 | C4: 공사매출 | D4: 공사원가 | M4: 일시 매출 | N4: 일시 원가 | O4: 매총 | P4: 매총률 | Q4: 면수 | R4: 면당평균공사매출 | S4: 면당평균공사원가
B5: 1 | C5: 18600000 | D5: 15200000 | M5: =C5+E5 -> 18600000 | N5: =D5+F5 -> 15200000 | O5: =M5-N5 -> 3400000 | P5: =O5/M5 -> 0.1827957 | Q5: 1 | R5: =M5/$Q$5 -> 18600000 | S5: =N5/$Q$5 -> 15200000
B6: 2 | C6: 25500000 | D6: 20800000 | M6: =C6+E6 -> 25500000 | N6: =D6+F6 -> 20800000 | O6: =M6-N6 -> 4700000 | P6: =O6/M6 -> 0.18431373 | Q6: 2 | R6: =M6/$Q$6 -> 12750000 | S6: =N6/$Q$6 -> 10400000
B7: 3 | C7: 32400000 | D7: 26300000 | M7: =C7+E7 -> 32400000 | N7: =D7+F7 -> 26300000 | O7: =M7-N7 -> 6100000 | P7: =O7/M7 -> 0.1882716 | Q7: 3 | R7: =M7/$Q$7 -> 10800000 | S7: =N7/$Q$7 -> 8766666.7
B8: 4 | C8: 40000000 | D8: 32400000 | M8: =C8+E8 -> 40000000 | N8: =D8+F8 -> 32400000 | O8: =M8-N8 -> 7600000 | P8: =O8/M8 -> 0.19 | Q8: 4 | R8: =M8/$Q$8 -> 10000000 | S8: =N8/$Q$8 -> 8100000
B9: 5 | C9: 46900000 | D9: 38000000 | M9: =C9+E9 -> 46900000 | N9: =D9+F9 -> 38000000 | O9: =M9-N9 -> 8900000 | P9: =O9/M9 -> 0.18976546 | Q9: 5 | R9: =SUM(M9:M14)/SUM($Q$9:$Q$14) -> 8828888.9 | S9: =SUM(N9:N14)/SUM($Q$9:$Q$14) -> 7133333.3
B10: 6 | C10: 53800000 | D10: 43500000 | M10: =C10+E10 -> 53800000 | N10: =D10+F10 -> 43500000 | O10: =M10-N10 -> 10300000 | P10: =O10/M10 -> 0.19144981 | Q10: 6
