Workbook
Name _________________PRN2: [1]내역서!#REF!
Name _________________PRN3: [1]내역서!#REF!
Name _________________PRN4: [1]내역서!#REF!
Name _________________PRN6: [1]내역서!#REF!
Name _________________PRN7: [1]내역서!#REF!
Name ________________PRN2: [1]내역서!#REF!
Name ________________PRN3: [1]내역서!#REF!
Name ________________PRN4: [1]내역서!#REF!
Name ________________PRN6: [1]내역서!#REF!
Name ________________PRN7: [1]내역서!#REF!
Name _______________PRN2: [1]내역서!#REF!
Name _______________PRN3: [1]내역서!#REF!
Name _______________PRN4: [1]내역서!#REF!
Name _______________PRN6: [1]내역서!#REF!
Name _______________PRN7: [1]내역서!#REF!
Name ______________PRN2: [1]내역서!#REF!
Name ______________PRN3: [1]내역서!#REF!
Name ______________PRN4: [1]내역서!#REF!
Name ______________PRN6: [1]내역서!#REF!
Name ______________PRN7: [1]내역서!#REF!
Name _____________PRN2: [1]내역서!#REF!
Name _____________PRN3: [1]내역서!#REF!
Name _____________PRN4: [1]내역서!#REF!
Name _____________PRN6: [1]내역서!#REF!
Name _____________PRN7: [1]내역서!#REF!
Name ____________PRN2: [1]내역서!#REF!
Name ____________PRN3: [1]내역서!#REF!
Name ____________PRN4: [1]내역서!#REF!
Name ____________PRN6: [1]내역서!#REF!
Name ____________PRN7: [1]내역서!#REF!
Name ___________PRN2: [1]내역서!#REF!
Name ___________PRN3: [1]내역서!#REF!
Name ___________PRN4: [1]내역서!#REF!
Name ___________PRN6: [1]내역서!#REF!
Name ___________PRN7: [1]내역서!#REF!
Name __________PRN2: [1]내역서!#REF!
Name __________PRN3: [1]내역서!#REF!
Name __________PRN4: [1]내역서!#REF!
Name __________PRN6: [1]내역서!#REF!
Name __________PRN7: [1]내역서!#REF!
Name _________PRN2: [1]내역서!#REF!
Name _________PRN3: [1]내역서!#REF!
Name _________PRN4: [1]내역서!#REF!
Name _________PRN6: [1]내역서!#REF!
Name _________PRN7: [1]내역서!#REF!
Name ________PRN2: [1]내역서!#REF!
Name ________PRN3: [1]내역서!#REF!
Name ________PRN4: [1]내역서!#REF!
Name ________PRN6: [1]내역서!#REF!
Name ________PRN7: [1]내역서!#REF!
Name _______DOG1: #REF!
Name _______DOG2: #REF!
Name _______DOG22: #REF!
Name _______DOG3: #REF!
Name _______DOG33: #REF!
Name _______DOG4: #REF!
Name _______IL1: #REF!
Name _______PI48: #REF!
Name _______PI60: #REF!
Name _______PRN2: [1]내역서!#REF!

Sheet Sheet1
B2: RMS 관제 List
B4: 구분 | C4: 분류 | D4: 설비명 | E4: 관제점 | F4: 10층이하 권장관제점 | G4: 참고 | H4: 추정금액
A5: =(4500000*3)/10000 -> 1350 | B5: 1 | C5: 소방 | D5: 화재수신반 | E5: 화재수신기 통합화재신호 | F5: 1 | G5: 지멘스 수신기 모델은 프로그램 수정이 필요함. (70~100만원 비용발생)
A6: 80 | B6: 2 | E6: 연동정지 스위치 조작 (소방업체공사) | F6: 1 | G6: 소방전문업체 별도발주 공사 (수도권 65만원/지방권 90만원)
A7: 250 | B7: 3 | E7: 1~10층 화재신호 (소방업체공사) | F7: 1 | G7: 수신기 제조사에 따라 인출(프로그램 수정)이 불가 할 수 있음 | H7: 월 73만원 / 년 876만원
A8: =SUM(A5:A7) -> 1680 | B8: 4 | D8: 소방펌프 | E8: 소방 주펌프 기동신호 | F8: 1 | G8: 층별대표신호와 동일하나 기계실 펌프 MCC반에서 인출은 가능함 (주장비 추가필요) | H8: - LTE통신장비(G/W) 3대 제공 기준 (총 2,628만원, 3년 분할 약정)
A9: =ROUNDUP(A8/36,0) -> 47 | B9: 5 | D9: 가스누설감지기 | E9: 가스누설감지기동작신호
A10: =A9*12 -> 564 | B10: 6 | C10: 전기 | D10: 발전기 | E10: 발전기 UVR 정전신호 | F10: 1 | H10: ※ 견적 참고
A11: =A10*3 -> 1692 | B11: 7 | E11: 발전기 이상경보 | F11: 1 | H11: - 설비 자체에서 관제점 인출을 제공하는 모델에 한하여 서비스 제공 가능
B12: 8 | E12: 발전기 기동신호 | F12: 1 | H12: - 현장의 구축환경(벽체, 철제문 등 통신거리 단축 또는 설비간 이격거리가 긴 경우)에
B13: 9 | D13: 누전경보기 | E13: 누전경보기 동작신호 | H13: 따라서는 통신장비의 추가 설치로 인하여 상기 금액이 변경될 수 있음
B14: 10 | D14: 누수경보기 | E14: 누수경보기 동작신호 | H14: ▷ 일반적인 통신환경이 아니거나 통신장비가 5대 이상 소요되는 경우는 현장실사를
B15: 11 | C15: 위생 | D15: 저수조 | E15: 저수조 고수위신호 | F15: 1 | G15: 오뚜기센서로 설치할 경우 배선공사 별도 | H15: 통한 견적 필요
B16: 12 | E16: 저수조 저수위신호 | F16: 1
B17: 13 | D17: 집수정 | E17: 집수정 고수위경보 | F17: 1
B18: 14 | D18: 정화조 | E18: 정화조 고수위경보
B19: 15 | C19: 기계 | D19: 부스터펌프 | E19: 부스터펌프 이상경보 | F19: 2
B20: 16 | D20: 졸라펌프 | E20: 졸라펌프 이상경보
B21: 17 | D21: 항온항습기 | E21: 항온항습기 이상경보
B22: 18 | D22: 스크류냉동기 | E22: 스크류냉동기 이상경보
B23: 19 | D23: 터보냉동기 | E23: 터보냉동기 이상경보
B24: 20 | D24: 빙축열냉동기 | E24: 빙축열냉동기 이상경보
B25: 21 | D25: 흡수식냉동기 | E25: 흡수식냉동기 이상경보
B26: 22 | D26: 냉온수기 | E26: 냉온수기 이상경보 | F26: 2
B27: 23 | D27: 보일러 | E27: 보일러 이상경보 | F27: 1
B28: 24 | D28: 지열시스템 | E28: 지열시스템 이상경보

Sheet 1.구축견적
B2: =CONCATENATE(P6,Q7,R7) -> 1. 중소형빌딩 표준현장 원격감시시스템 구축견적
B4: 원격감시 Monitoring service 시스템 구축 비용 | H4: 원격감시 Monitoring service 운영비용(월)
B6: 구분 | C6: 수량 | D6: 단가 | E6: 합계 | H6: 구분 | I6: 개소/Point | K6: 통신비용 | L6: 이용/유지비용 | M6: 합계 | P6: 1. | Q6: 현장명 입력 | S6: 월 | U6: 일 | V6: 일)
B7: 원격감시 구축공사 | C7: 1 | D7: ='3.공사예산내역서(갑)'!G27 -> 7455000 | E7: =SUM(C7*D7) -> 7455000 | H7: 통신비 | I7: 3 | J7: 개소 | K7: 15000 | M7: =I7*K7 -> 45000 | P7: 2. | Q7: 중소형빌딩 표준현장 | R7: 원격감시시스템 구축견적 | S7: 01 | T7: 월 | U7: 20
B8: 관제 PC | C8: 1 | D8: 900000 | E8: =SUM(C8*D8) -> 900000 | H8: 원격관제 SVC 비용 | I8: =COUNTA('2.관제점리스트'!B:B)-2 -> 20 | J8: Point | L8: =IF(I8=0,"0",'11.21년 원격관제SVC 비용'!L22) -> 100000 | M8: =SUM(K8:L8) -> 100000 | P8: 공사명 : | Q8: =Q7 -> 중소형빌딩 표준현장 | R8: 설비관제점 List
B9: Engineering | C9: 0 | E9: =SUM(C9*D9) -> 0 | H9: 정기점검비 | I9: =I8 -> 20 | J9: Point | L9: ='12.정기점검비 산출근거'!I3+('10.정기점검 출장경비'!K6*2) -> 572459.76 | M9: =L9/12 -> 47704.98 | P9: (작성일자:`22년 | Q9: =Q7 -> 중소형빌딩 표준현장 | R9: 원격감시시스템 구축공사
B10: 구축비 계 | E10: =SUM(E7:E9) -> 8355000 | H10: 유지보수비 | I10: =I8 -> 20 | J10: Point | L10: =739000+'10.정기점검 출장경비'!K6 -> 889000 | M10: =L10/12 -> 74083.333 | Q10: 건물 연면적 입력(㎡)
B11: ※ 원격감시 구축공사는 원격감시시스템 자재, 인건비 등 현장 구축 공사 비용임. ※ 관제 PC는 LG전자 24V50N-GR5SK 모델 선정함. ※ Engineering 비용은 S&I 전문구축 고급인력 투입비용임 (프로그램 세팅, 시운전 등) | H11: 총합계 | M11: =ROUND(SUM(M7:M10),-3) -> 267000 | Q11: 9999
H12: ※ 통신비는 Smart Gateway 1개소당 U+ LTE 무선 라우터 설치기준 ※ 원격관제 SVC 비용은는 AWS solution 서버사용, 통합운영센터 24시간 이중감시 서비스 합계 금액임 ※ 정기점검은 반기1회 원격감시시스템 장비 점검 및 연동 test 수행 ※ 유지보수비는 원격감시시스템 부품 보수 및 고장 시 교체 비용임 비용은 '유지보수 비용산출 Tool' 기준 주장비 1대 교체 작업과 출장비용 합산금액.
B17: 원격감시 Monitoring service 비용
M18: 단위: 부가세별도,원
B19: 구분 | D19: 월비용 | F19: 년간비용 | I19: 비고
B20: 구축비용 | D20: =ROUND(E10/24,-3) -> 348000 | F20: =D20*12 -> 4176000 | I20: 원격감시 구축공사 (감가상각 3년 기준)
B21: 운영유지비 | D21: =M11 -> 267000 | F21: =D21*12 -> 3204000 | I21: 통신비
B22: 기업이윤(20%) | D22: =(D20+D21)*20% -> 123000 | F22: =D22*12 -> 1476000 | I22: 구축비용 + 운영유지비 월비용 합계금액의 20% 적용
B23: 비용계 | D23: =D20+D21+D22 -> 738000 | F23: =D23*12 -> 8856000
B26: 고객제안 매출(월) | D26: 470000
B27: 이익율 | D27: =(D26-D23)/D26 -> -0.57021277

Sheet 2.관제점리스트
B2: =CONCATENATE('1.구축견적'!P7,'1.구축견적'!Q8,'1.구축견적'!R8) -> 2. 중소형빌딩 표준현장 설비관제점 List
B4: No. | C4: 인출위치 | E4: SETUP_BOX | F4: 인출장비명 | G4: 관제명 | H4: 기타
B5: 1 | C5: 지상/지하층 | D5: 방재실(경비실) | E5: SGW1 | F5: 화재수신반 | G5: 화재수신기 통합화재신호
B6: 2 | G6: 화재수신반 연동정지 스위치 조작
B7: 3 | G7: 1F 화재신호
B8: 4 | G8: 2F 화재신호
B9: 5 | G9: 3F 화재신호
B10: 6 | G10: 4F 화재신호
B11: 7 | G11: 5F 화재신호
B12: 8 | G12: 6F 화재신호
B13: 9 | G13: 7F 화재신호
B14: 10 | G14: 8F 화재신호
B15: 11 | G15: 9F 화재신호
B16: 12 | G16: 10F 화재신호
B17: 13 | G17: 소방 주펌프 기동신호
B18: 14 | D18: 발전기실(전기실) | E18: SGW2 | F18: 발전기 제어반 | G18: 발전기 UVR 정전신호
B19: 15 | G19: 발전기 가동신호
B20: 16 | G20: 발전기 이상신호
B21: 17 | D21: 기계실 | E21: SGW3 | F21: DDC | G21: 저수조 저수위
B22: 18 | G22: 저수조 고수위
B23: 19 | G23: 지하 배수 집수정 고수위
B24: 20 | G24: 급수 부스터펌프 이상경보

Sheet 3.공사예산내역서(갑)
B2: 공사예산내역서(갑)
B4: =CONCATENATE('1.구축견적'!P8,'1.구축견적'!Q9,'1.구축견적'!R9) -> 공사명 : 중소형빌딩 표준현장 원격감시시스템 구축공사 | H4: =CONCATENATE('1.구축견적'!P9,'1.구축견적'!S7,'1.구축견적'!T7,'1.구축견적'!U7,'1.구축견적'!V6) -> (작성일자:`22년 01월 20일)
H5: (단위:원, VAT별도)
B6: 구 분 | C6: 공 사 항 목 | D6: 자 재 비 | E6: 인 건 비 | F6: 기계/기타경비 | G6: 합 계 | H6: 비 고
B7: 직접공사비
C8: 원격감시시시스템 구축공사 | D8: ='4.공사예산내역서(을)'!H8+'4.공사예산내역서(을)'!H9+'4.공사예산내역서(을)'!H10 -> 4606400 | E8: ='4.공사예산내역서(을)'!J8+'4.공사예산내역서(을)'!J9+'4.공사예산내역서(을)'!J10 -> 1514770.4 | G8: =D8+E8+F8 -> 6121170.4 | H8: 내역서 (을) 1~3항
C9: 잡자재비 / 공구손료 | D9: ='4.공사예산내역서(을)'!H15 -> 138192 | F9: ='4.공사예산내역서(을)'!L13 -> 45443.112 | G9: =D9+E9+F9 -> 183635.11 | H9: 내역서 (을) 4~5항
C10: 출장경비 | F10: ='4.공사예산내역서(을)'!L14 -> 200000 | G10: =D10+E10+F10 -> 200000 | H10: 내역서 (을) 6항
C12: 소 계 | D12: =SUM(D7:D11) -> 4744592 | E12: =SUM(E7:E11) -> 1514770.4 | F12: =SUM(F7:F11) -> 245443.11 | G12: =SUM(G7:G11) -> 6504805.5
B13: 간접비
C14: 안전 관리비 (자재비+인건비의 2.93%) | G14: =SUM(D12+E12)*2.93% -> 183399.32
C15: 산재 보험료 (인건비의 3.70%) | G15: =E12*3.7% -> 56046.505
C16: 고용 보험료 (인건비의 1.01%) | G16: =E12*1.01% -> 15299.181
C17: 국민건강 보험료 (인건비의 3.495%) | G17: =E12*3.495% -> 52941.226
C18: 국민연금 보험료 (인건비의 4.5%) | G18: =E12*4.5% -> 68164.669
C19: 노인장기요양 보험료 (건강보험료의 12.27%) | G19: =G17*12.27% -> 6495.8884
C21: 소 계 | G21: =SUM(G13:G20) -> 382346.79
B23: 일반 관리비 | C23: (직접공사비+간접공사비)의 5% | G23: =SUM(G12,G21)*5% -> 344357.62
B24: 이 윤 | C24: (인건비+간접공사비+일반관리비)의 10% | G24: =SUM(E12,G21,G23)*10% -> 224147.48
C26: 소 계 | G26: =SUM(G22:G25) -> 568505.1
B27: 공 사 금 액 | C27: 합 계 | D27: =SUM(D12) -> 4744592 | E27: =SUM(E12) -> 1514770.4 | F27: =SUM(F12) -> 245443.11 | G27: =ROUNDDOWN(SUM(G26,G21,G12),-3) -> 7455000 | H27: (▶천단위 절삭)

Sheet 4.공사예산내역서(을)
B2: 공사예산내역서(을)
B4: ='3.공사예산내역서(갑)'!$B$4 -> 공사명 : 중소형빌딩 표준현장 원격감시시스템 구축공사 | N4: ='3.공사예산내역서(갑)'!$H$4 -> (작성일자:`22년 01월 20일)
N5: (단위 : 원,VAT별도)
B6: NO | C6: 항 목 | D6: 규 격 | E6: 단위 | F6: 수량 | G6: 자 재 비 | I6: 인 건 비 | K6: 기계/기타경비 | M6: 합 계 | N6: 비 고
G7: 단가 | H7: 금액 | I7: 단가 | J7: 금액 | K7: 단가 | L7: 금액
B8: 1 | C8: 원격감시시스템 장비설치 | E8: 식 | F8: 1 | G8: ='5.일위대가'!H29 -> 4250000 | H8: =G8*F8 -> 4250000 | I8: ='5.일위대가'!K29 -> 636792.75 | J8: =I8*F8 -> 636792.75 | M8: =SUM(H8,J8,L8) -> 4886792.8 | N8: ▶일위대가 참조
B9: 2 | C9: 원격감시시스템 배관/배선작업 | E9: 식 | F9: 1 | G9: ='5.일위대가'!H51 -> 348900 | H9: =G9*F9 -> 348900 | I9: ='5.일위대가'!K51 -> 795232.41 | J9: =I9*F9 -> 795232.41 | M9: =SUM(H9,J9,L9) -> 1144132.4 | N9: ▶일위대가 참조
B10: 3 | C10: 원격감시시스템 연동작업 | E10: 식 | F10: 1 | G10: ='5.일위대가'!H57 -> 7500 | H10: =G10*F10 -> 7500 | I10: ='5.일위대가'!K57 -> 82745.25 | J10: =I10*F10 -> 82745.25 | M10: =SUM(H10,J10,L10) -> 90245.25 | N10: ▶일위대가 참조
D11: 소 계 | H11: =SUM(H8:H10) -> 4606400 | J11: =SUM(J8:J10) -> 1514770.4 | M11: =SUM(M8:M10) -> 6121170.4
B12: 4 | C12: 잡자재비 | D12: 자재비 계의 3% 이내 | E12: % | F12: 0.03 | H12: =H11*F12 -> 138192 | M12: =SUM(H12,J12,L12) -> 138192
B13: 5 | C13: 공구손료 | D13: 인건비 계의 3% 이내 | E13: % | F13: 0.03 | L13: =J11*F13 -> 45443.112 | M13: =SUM(H13,J13,L13) -> 45443.112
B14: 6 | C14: 출장경비 | E14: 식 | F14: 1 | K14: ='9.공사업체 출장경비'!K6 -> 200000 | L14: =K14*F14 -> 200000 | M14: =SUM(H14,J14,L14) -> 200000
D15: 소 계 | H15: =SUM(H12:H14) -> 138192 | J15: =SUM(J12:J13) -> 0 | L15: =SUM(L12:L14) -> 245443.11 | M15: =SUM(M12:M14) -> 383635.11
D16: 합 계 | H16: =SUM(H11,H15) -> 4744592 | J16: =SUM(J11,J15) -> 1514770.4 | L16: =SUM(L11,L15) -> 245443.11 | M16: =SUM(M15,M11) -> 6504805.5

Sheet 5.일위대가
B2: 일위대가
B4: ='3.공사예산내역서(갑)'!$B$4 -> 공사명 : 중소형빌딩 표준현장 원격감시시스템 구축공사 | M4: ='3.공사예산내역서(갑)'!$H$4 -> (작성일자:`22년 01월 20일)
M5: (단위 : 원,VAT별도)
B6: NO | C6: 항 목 | D6: 규 격 | E6: 단위 | F6: 수량 | G6: 자 재 비 | I6: 인 건 비 | L6: 합 계 | M6: 비 고
G7: 단가 | H7: 금액 | I7: M/P | J7: 단가 | K7: 금액
B8: 1. 원격감시시스템 장비설치
C9: Smart Gateway | D9: WI-SUN/LECIM, S&I RMS연동, DI 8CH | E9: 대 | F9: 3 | G9: 500000 | H9: =F9*G9 -> 1500000 | L9: =H9+K9 -> 1500000 | M9: 개별자산관리 대상
C10: Smart End Device | D10: WI-SUN/LECIM, 4CH I/O | E10: 대 | F10: 1 | G10: 250000 | H10: =F10*G10 -> 250000 | L10: =H10+K10 -> 250000
C11: Smart DI Module | D11: DI INPUT [I/O 4ch] | E11: EA | F11: 0 | G11: 25000 | H11: =F11*G11 -> 0 | L11: =H11+K11 -> 0 | M11: 단순설치 자재납품 건
C12: Smart DO Module | D12: Relay OUTPUT [I/O 4ch] | E12: EA | F12: 0 | G12: 25000 | H12: =F12*G12 -> 0 | L12: =H12+K12 -> 0 | M12: 단순설치 자재납품 건
C13: Smart AI Module | D13: VDC/ADC INPUT [I/O 4ch] | E13: EA | F13: 2 | G13: 25000 | H13: =F13*G13 -> 50000 | L13: =H13+K13 -> 50000 | M13: 단순설치 자재납품 건
C14: Smart LED Detector Device | D14: Arduino Nano 10CH Board | E14: 대 | F14: 1 | G14: 350000 | H14: =G14*F14 -> 350000 | L14: =H14+K14 -> 350000
C15: Smart CDS Sensor Module | D15: High sensitivity CDS/3D Printing Cap | E15: 대 | F15: 10 | G15: 10000 | H15: =G15*F15 -> 100000 | L15: =H15+K15 -> 100000
C16: Mini DC-UPS | D16: MPS-L24 / DC24V 3.0A Adapter 포함 | E16: 대 | F16: 0 | G16: 230000 | H16: =F16*G16 -> 0 | L16: =H16+K16 -> 0 | M16: 단순설치 자재납품 건
C17: AC UPS | D17: APC BACK-UPS 650 (BX650LI-GR) | E17: 대 | F17: 0 | G17: 110000 | H17: =F17*G17 -> 0 | L17: =H17+K17 -> 0 | M17: 단순설치 자재납품 건
C18: Modbus RTU DI Board | D18: KM6054[I/O 13ch] - Digital INPUT | E18: EA | F18: 0 | G18: 107800 | H18: =F18*G18 -> 0 | L18: =H18+K18 -> 0 | M18: 단순교체 자재납품 건
C19: Modbus RTU AI Board | D19: KM6412[I/O 8ch] - Analog INPUT | E19: EA | F19: 0 | G19: 107800 | H19: =F19*G19 -> 0 | L19: =H19+K19 -> 0 | M19: 단순교체 자재납품 건
C20: 화재수신반 프로그램 수정작업 | D20: 프로그램 수정, 중계기 모듈 | E20: EA | F20: 1 | G20: 2000000 | H20: =F20*G20 -> 2000000 | L20: =H20+K20 -> 2000000
C21: NTC 저항식 온도센서 | D21: FS-200N | E21: EA | F21: 0 | G21: 5000 | H21: =F21*G21 -> 0 | L21: =H21+K21 -> 0 | M21: 단순교체 자재납품 건
C22: Smart Gateway 설치 | D22: 내선전공 | E22: 인 | I22: ='7.MP산출근거'!O9 -> 0.125 | J22: ='7.MP산출근거'!D42 -> 258917 | K22: =F9*I22*J22 -> 97093.875 | L22: =H22+K22 -> 97093.875 | M22: MP산출근거 1항 참조 | O22: =I22*F9 -> 0.375
C23: Smart End Device 설치 | D23: 내선전공 | E23: 인 | I23: ='7.MP산출근거'!O11 -> 0.125 | J23: ='7.MP산출근거'!D42 -> 258917 | K23: =F10*I23*J23 -> 32364.625 | L23: =H23+K23 -> 32364.625 | M23: MP산출근거 2항 참조
C24: Smart LED Detector Device 설치 | D24: 내선전공 | E24: 인 | I24: ='7.MP산출근거'!O15 -> 0.25 | J24: ='7.MP산출근거'!D42 -> 258917 | K24: =F14*I24*J24 -> 64729.25 | L24: =H24+K24 -> 64729.25 | M24: MP산출근거 4항 참조
C25: Smart CDS Sensor Module 설치 | D25: H/W 시험사 | E25: 인 | I25: ='7.MP산출근거'!O17 -> 0.0625 | J25: ='7.MP산출근거'!D46 -> 330981 | K25: =F15*I25*J25 -> 206863.12 | L25: =H25+K25 -> 206863.12 | M25: MP산출근거 5항 참조
C26: Smart Gateway SET-UP | D26: S/W 시험사 | E26: 인 | I26: ='7.MP산출근거'!O21 -> 0.0625 | J26: ='7.MP산출근거'!D47 -> 377187 | K26: =F9*I26*J26 -> 70722.562 | L26: =H26+K26 -> 70722.562 | M26: MP산출근거 6항 참조 | O26: =I26*F9 -> 0.1875
C27: Smart End Device SET-UP | D27: S/W 시험사 | E27: 인 | I27: ='7.MP산출근거'!O23 -> 0.0625 | J27: ='7.MP산출근거'!D47 -> 377187 | K27: =F10*I27*J27 -> 23574.188 | L27: =H27+K27 -> 23574.188 | M27: MP산출근거 7항 참조
C28: Smart LED Detector Device SET-UP | D28: S/W 시험사 | E28: 인 | I28: ='7.MP산출근거'!O27 -> 0.375 | J28: ='7.MP산출근거'!D47 -> 377187 | K28: =F14*I28*J28 -> 141445.12 | L28: =H28+K28 -> 141445.12 | M28: MP산출근거 9항 참조
D29: 소 계 | H29: =SUM(H8:H28) -> 4250000 | K29: =SUM(K8:K28) -> 636792.75 | L29: =SUM(L8:L28) -> 4886792.8
B30: 2. 원격감시시스템 배관/배선작업
C31: 합성수지 전선관(CD) | D31: 16mm | E31: M | F31: 100 | G31: 300 | H31: =F31*G31 -> 30000 | L31: =H31+K31 -> 30000
C32: 합성수지 전선관 커넥터 | D32: 16mm | E32: EA | F32: 20 | G32: 200 | H32: =F32*G32 -> 4000 | L32: =H32+K32 -> 4000
C33: 절연난연 PVC 시스케이블 | D33: 0.6/1kv F-CV 3Cx1.5mm | E33: M | F33: 50 | G33: 1100 | H33: =F33*G33 -> 55000 | L33: =H33+K33 -> 55000
C34: 신호용 케이블 | D34: 4C x 0.5mm | E34: M | F34: 60 | G34: 650 | H34: =F34*G34 -> 39000 | L34: =H34+K34 -> 39000
C35: 신호용 케이블 | D35: 6C x 0.5mm | E35: M | F35: 30 | G35: 1930 | H35: =F35*G35 -> 57900 | L35: =H35+K35 -> 57900
C36: 신호용 케이블 | D36: 10C x 0.5mm | E36: M | F36: 10 | G36: 4900 | H36: =F36*G36 -> 49000 | L36: =H36+K36 -> 49000
C37: 소형계전기 | D37: Relay AC24V 4a4c (SOCKET 포함) | E37: EA | F37: 0 | G37: 5000 | H37: =F37*G37 -> 0 | L37: =H37+K37 -> 0 | M37: 자재납품(단순설치용)
C38: 소형계전기 | D38: Relay DC24V 4a4c (SOCKET 포함) | E38: EA | F38: 3 | G38: 5000 | H38: =F38*G38 -> 15000 | L38: =H38+K38 -> 15000 | M38: 자재납품(단순설치용)
C39: 소형계전기 | D39: Relay AC220V 4a4c (SOCKET 포함) | E39: EA | F39: 3 | G39: 5000 | H39: =F39*G39 -> 15000 | L39: =H39+K39 -> 15000 | M39: 자재납품(단순설치용)
C40: HI-BOX (Relay SET-UP) | D40: 190(W) X 280 (H) X 180(D) | E40: EA | F40: 1 | G40: 15000 | H40: =F40*G40 -> 15000 | L40: =H40+K40 -> 15000 | M40: 자재납품(단순설치용)
C41: HI-BOX (SGW 외부시공 방수용) | D41: 300(W) X 400 (H) X 180(D) | E41: EA | F41: 0 | G41: 25000 | H41: =F41*G41 -> 0 | L41: =H41+K41 -> 0
C42: 수위감지센서 | D42: YQ-1 A/B접점 | E42: EA | F42: 3 | G42: 13000 | H42: =F42*G42 -> 39000 | L42: =H42+K42 -> 39000
...

Sheet 6.일위대가 산출근거
B2: 일위대가 산출근거
B6: 1. 옥내배선 | H6: (M당)
B7: 품 명/직 종 | C7: 단가 | D7: 6㎟ 이하 | F7: 16㎟ 이하 | H7: 비고
D8: M/P | E8: 금액 | F8: M/P | G8: 금액
B9: 내선전공 | C9: ='7.MP산출근거'!$D$42 -> 258917 | D9: 0.01 | E9: =C9*D9 -> 2589.17 | F9: 0.023 | G9: =C9*F9 -> 5955.091
B10: 합 계 | E10: =E9 -> 2589.17 | G10: =G9 -> 5955.091
B11: 1) 옥내케이블 관내배선은 "전력케이블 구내설치" 준용
B12: 2) 통신장비 전원인입용 단순공사로 품셈의 50% 적용.
B14: 2. 제어용 케이블 설치 | L14: (M당)
B15: 품 명/직 종 | C15: 단가 | D15: 4C 2.5㎟ 이하 | F15: 6C 2.5㎟ 이하 | H15: 10C 2.5㎟ 이하 | J15: 20C 2.5㎟ 이하 | L15: 비고
D16: M/P | E16: 금액 | F16: M/P | G16: 금액 | H16: M/P | I16: 금액 | J16: M/P | K16: 금액
B17: 저압케이블전공 | C17: ='7.MP산출근거'!D43 -> 271717 | D17: 0.026 | E17: =C17*D17 -> 7064.642 | F17: 0.035 | G17: =C17*F17 -> 9510.095 | H17: 0.048 | I17: =C17*H17 -> 13042.416 | J17: 0.074 | K17: =C17*J17 -> 20107.058
B18: 합 계 | E18: =E17 -> 7064.642 | G18: =G17 -> 9510.095 | I18: =I17 -> 13042.416 | K18: =K17 -> 20107.058
B19: 1) 다음 작업 포함기준
B20: ① 케이블 부설 정돈, 청소.
B21: ② 단자처리, 도입선 넣기, 결선, Mark 취부 포함.
B22: 2) 통신장비 신호선 인입용 단순공사로 품셈의 50% 적용.
B24: 3. 전선관 배관 | P24: (M당)
B25: 품 명/직 종 | C25: 단가 | D25: 합성수지 16mm | F25: 합성수지 22mm | H25: 후강 16mm | J25: 후강 22㎜ | L25: 금속가요 16mm | N25: 금속가요 22㎜ | P25: 비고
D26: M/P | E26: 금액 | F26: M/P | G26: 금액 | H26: M/P | I26: 금액 | J26: M/P | K26: 금액 | L26: M/P | M26: 금액 | N26: M/P | O26: 금액
B27: 내선전공 | C27: ='7.MP산출근거'!$D$42 -> 258917 | D27: 0.05 | E27: =$C$27*D27 -> 12945.85 | F27: 0.06 | G27: =$C$27*F27 -> 15535.02 | H27: 0.08 | I27: =$C$27*H27 -> 20713.36 | J27: 0.11 | K27: =$C$27*J27 -> 28480.87 | L27: 0.044 | M27: =$C$27*L27 -> 11392.348 | N27: 0.059 | O27: =$C$27*N27 -> 15276.103
B28: 합 계 | E28: =E27 -> 12945.85 | G28: =G27 -> 15535.02 | I28: =I27 -> 20713.36 | K28: =K27 -> 28480.87 | M28: =M27 -> 11392.348 | O28: =O27 -> 15276.103
B29: 1) 폴리에틸렌 전선관 및 합성수지제 가요전선관(CD관)은 합성수지 전선관 품의 80% 다만, 지름이 100mm 이상의 직관은 100%
B30: 2) 소모 재료비는 본품에 포함되어 있다.
B31: 3) 계수, 보조재의 제작 및 설치품 포함한다.
B32: 4) 통신장비 전원인입용 노출배관 단순공사로 품셈의 30% 적용.
B34: 4. 차단기 및 개폐기 설치 | F34: (개)
B35: 품 명/직 종 | C35: 단가 | D35: 배선용차단기 30AF | F35: 비고
D36: M/P | E36: 금액
B37: 내선전공 | C37: ='7.MP산출근거'!$D$42 -> 258917 | D37: 0.19 | E37: =C37*D37 -> 49194.23
B38: 합 계 | E38: =E37 -> 49194.23
B39: 1) 3P 단투 기준, 1P 50%, 2P 70%, 4P는 130%
B40: 2) 접속, 시험 품 포함
B41: 3) 철거 50%, 재사용 철거 80%
B42: 4) 통신장비 전원인입용 단순공사로 품셈의 50% 적용.
B44: 5. 금속덕트 설치 | F44: (M당)
B45: 품 명/직 종 | C45: 단가 | D45: 60mm x 30mm 이하 | F45: 비고
D46: M/P | E46: 금액
B47: 내선전공 | C47: ='7.MP산출근거'!$D$42 -> 258917 | D47: 0.15 | E47: =$C$47*D47 -> 38837.55
B48: 합 계 | E48: =E47 -> 38837.55
...

Sheet 7.MP산출근거
B2: M/P 산출근거
B4: ='3.공사예산내역서(갑)'!$B$4 -> 공사명 : 중소형빌딩 표준현장 원격감시시스템 구축공사 | Q4: ='3.공사예산내역서(갑)'!$H$4 -> (작성일자:`22년 01월 20일)
B6: 공 정 | D6: 품 명(직 종) | E6: 인원 | F6: 소요시간(분) | G6: 산출식 | O6: M/P | P6: 비 고
B7: ▶ OOO 원격감시시스템 설치공사
C8: 원격감시시스템 장비설치
B9: 1 | C9: Smart Gateway | D9: 내선전공 | E9: 2 | F9: 30 | G9: ( | H9: =E9 -> 2 | I9: 인 Ⅹ | J9: =F9 -> 30 | K9: 분/ | L9: 480 | M9: 분 ) = | N9: =H9*J9/L9 -> 0.125 | O9: =N9 -> 0.125
C10: (전원포설 작업포함)
B11: 2 | C11: Smart End Device | D11: 내선전공 | E11: 2 | F11: 30 | G11: ( | H11: =E11 -> 2 | I11: 인 Ⅹ | J11: =F11 -> 30 | K11: 분/ | L11: 480 | M11: 분 ) = | N11: =H11*J11/L11 -> 0.125 | O11: =N11 -> 0.125
C12: (전원포설 작업포함)
B13: 3 | C13: Smart Mesh Router | D13: 내선전공 | E13: 1 | F13: 20 | G13: ( | H13: =E13 -> 1 | I13: 인 Ⅹ | J13: =F13 -> 20 | K13: 분/ | L13: 480 | M13: 분 ) = | N13: =H13*J13/L13 -> 0.041666667 | O13: =N13 -> 0.041666667
C14: (전원포설 작업포함)
B15: 4 | C15: Smart LED Detector Device | D15: 내선전공 | E15: 1 | F15: 120 | G15: ( | H15: =E15 -> 1 | I15: 인 Ⅹ | J15: =F15 -> 120 | K15: 분/ | L15: 480 | M15: 분 ) = | N15: =H15*J15/L15 -> 0.25 | O15: =N15 -> 0.25
C16: (전원포설 작업포함)
B17: 5 | C17: Smart CDS Sensor Module | D17: H/W 시험사 | E17: 1 | F17: 30 | G17: ( | H17: =E17 -> 1 | I17: 인 Ⅹ | J17: =F17 -> 30 | K17: 분/ | L17: 480 | M17: 분 ) = | N17: =H17*J17/L17 -> 0.0625 | O17: =N17 -> 0.0625
C18: (전원포설 작업포함)
O19: =SUM(O7:O18) -> 0.60416667
C20: 원격감시시스템 SET-UP
B21: 6 | C21: Smart Gateway | D21: S/W 시험사 | E21: 1 | F21: 30 | G21: ( | H21: =E21 -> 1 | I21: 인 Ⅹ | J21: =F21 -> 30 | K21: 분/ | L21: 480 | M21: 분 ) = | N21: =H21*J21/L21 -> 0.0625 | O21: =N21 -> 0.0625
C22: (GUI 셋팅, SERVER 연동 작업포함)
B23: 7 | C23: Smart End Device | D23: S/W 시험사 | E23: 1 | F23: 30 | G23: ( | H23: =E23 -> 1 | I23: 인 Ⅹ | J23: =F23 -> 30 | K23: 분/ | L23: 480 | M23: 분 ) = | N23: =H23*J23/L23 -> 0.0625 | O23: =N23 -> 0.0625
C24: (GUI 셋팅, SERVER 연동 작업포함)
B25: 8 | C25: Smart Mesh Router | D25: S/W 시험사 | E25: 1 | F25: 30 | G25: ( | H25: =E25 -> 1 | I25: 인 Ⅹ | J25: =F25 -> 30 | K25: 분/ | L25: 480 | M25: 분 ) = | N25: =H25*J25/L25 -> 0.0625 | O25: =N25 -> 0.0625
C26: (GUI 셋팅, 로컬연동 작업포함)
B27: 9 | C27: Smart LED Detector Device | D27: S/W 시험사 | E27: 1 | F27: 180 | G27: ( | H27: =E27 -> 1 | I27: 인 Ⅹ | J27: =F27 -> 180 | K27: 분/ | L27: 480 | M27: 분 ) = | N27: =H27*J27/L27 -> 0.375 | O27: =N27 -> 0.375
C28: (Arduino 셋팅, 로컬연동 작업포함)
O29: =SUM(O20:O28) -> 0.5625
C30: 빌딩자동제어 연동작업
B31: 10 | C31: 회로결선 및 연동 테스트 | D31: H/W 시험사 | E31: 1 | F31: 30 | G31: ( | H31: =E31 -> 1 | I31: 인 Ⅹ | J31: =F31 -> 30 | K31: 분/ | L31: 480 | M31: 분 ) = | N31: =H31*J31/L31 -> 0.0625 | O31: =N31 -> 0.0625
O32: =SUM(O30:O31) -> 0.0625
B33: ▣대가 산출기준
B34: 1)상기 인건비는 `22년 상반기 노임(공사부문)단가 기준함.
B35: 2)1일 8시간(480분) 기준함.
B36: 3)자재비는 한국물가정보 및 MRO 단가 기준임.
B37: 4)잡자재 및 공구손료는 별도 계산함.
B38: 6)상기 7항은 원격감시시스템 장비수량 별 기준작업임.
B40: ▣인건비 근거 | P40: (단위:원,VAT별도)
C41: 직 종 | D41: 단 가 | E41: 해설
C42: 내선전공 | D42: 258917 | E42: 옥내전선관, 배선 및 등기구류 설비의 시공 및 보수에 종사하는 사람
C43: 저압케이블전공 | D43: 271717 | E43: 저압케이블 및 제어용 케이블 설비의 시공 및 보수에 종사하는 사람(교류 600V이하, 직류 750V이하)
C44: 계장공 | D44: 259947 | E44: 기계, 급배수, 전기, 가스, 위생, 냉난방 및 기타공사에 있어서 계기(공업제어장치, 공업계측 및 컴퓨터, 자동제어장치 등)를 전문으로 설치, 부착 및 점검하는 사람
...

Sheet 8.공사물량산출서
B2: 물량산출서
B4: ='3.공사예산내역서(갑)'!$B$4 -> 공사명 : 중소형빌딩 표준현장 원격감시시스템 구축공사 | I4: ='3.공사예산내역서(갑)'!$H$4 -> (작성일자:`22년 01월 20일)
B6: NO | C6: 항 목 | D6: 규 격 | E6: 단 위 | F6: 수 량 | G6: 산출근거 | I6: 비 고
C7: 1.원격감시시시스템 구축공사
B8: 1 | C8: ='5.일위대가'!C9 -> Smart Gateway | D8: ='5.일위대가'!D9 -> WI-SUN/LECIM, S&I RMS연동, DI 8CH | E8: ='5.일위대가'!E9 -> 대 | F8: ='5.일위대가'!F9 -> 3
B9: 2 | C9: ='5.일위대가'!C10 -> Smart End Device | D9: ='5.일위대가'!D10 -> WI-SUN/LECIM, 4CH I/O | E9: ='5.일위대가'!E10 -> 대 | F9: ='5.일위대가'!F10 -> 1
B10: 3 | C10: ='5.일위대가'!C11 -> Smart DI Module | D10: ='5.일위대가'!D11 -> DI INPUT [I/O 4ch] | E10: ='5.일위대가'!E11 -> EA | F10: ='5.일위대가'!F11 -> 0
B11: 4 | C11: ='5.일위대가'!C12 -> Smart DO Module | D11: ='5.일위대가'!D12 -> Relay OUTPUT [I/O 4ch] | E11: ='5.일위대가'!E12 -> EA | F11: ='5.일위대가'!F12 -> 0
B12: 5 | C12: ='5.일위대가'!C13 -> Smart AI Module | D12: ='5.일위대가'!D13 -> VDC/ADC INPUT [I/O 4ch] | E12: ='5.일위대가'!E13 -> EA | F12: ='5.일위대가'!F13 -> 2
B13: 6 | C13: ='5.일위대가'!C14 -> Smart LED Detector Device | D13: ='5.일위대가'!D14 -> Arduino Nano 10CH Board | E13: ='5.일위대가'!E14 -> 대 | F13: ='5.일위대가'!F14 -> 1
B14: 7 | C14: ='5.일위대가'!C15 -> Smart CDS Sensor Module | D14: ='5.일위대가'!D15 -> High sensitivity CDS/3D Printing Cap | E14: ='5.일위대가'!E15 -> 대 | F14: ='5.일위대가'!F15 -> 10
B15: 8 | C15: ='5.일위대가'!C16 -> Mini DC-UPS | D15: ='5.일위대가'!D16 -> MPS-L24 / DC24V 3.0A Adapter 포함 | E15: ='5.일위대가'!E16 -> 대 | F15: ='5.일위대가'!F16 -> 0
B16: 9 | C16: ='5.일위대가'!C17 -> AC UPS | D16: ='5.일위대가'!D17 -> APC BACK-UPS 650 (BX650LI-GR) | E16: ='5.일위대가'!E17 -> 대 | F16: ='5.일위대가'!F17 -> 0
B17: 10 | C17: ='5.일위대가'!C18 -> Modbus RTU DI Board | D17: ='5.일위대가'!D18 -> KM6054[I/O 13ch] - Digital INPUT | E17: ='5.일위대가'!E18 -> EA | F17: ='5.일위대가'!F18 -> 0
B18: 11 | C18: ='5.일위대가'!C19 -> Modbus RTU AI Board | D18: ='5.일위대가'!D19 -> KM6412[I/O 8ch] - Analog INPUT | E18: ='5.일위대가'!E19 -> EA | F18: ='5.일위대가'!F19 -> 0
B19: 12 | C19: ='5.일위대가'!C21 -> NTC 저항식 온도센서 | D19: ='5.일위대가'!D21 -> FS-200N | E19: ='5.일위대가'!E21 -> EA | F19: ='5.일위대가'!F21 -> 0
B20: 13 | C20: ='5.일위대가'!C31 -> 합성수지 전선관(CD) | D20: ='5.일위대가'!D31 -> 16mm | E20: ='5.일위대가'!E31 -> M | F20: ='5.일위대가'!F31 -> 100
B21: 14 | C21: ='5.일위대가'!C32 -> 합성수지 전선관 커넥터 | D21: ='5.일위대가'!D32 -> 16mm | E21: ='5.일위대가'!E32 -> EA | F21: ='5.일위대가'!F32 -> 20
B22: 15 | C22: ='5.일위대가'!C33 -> 절연난연 PVC 시스케이블 | D22: ='5.일위대가'!D33 -> 0.6/1kv F-CV 3Cx1.5mm | E22: ='5.일위대가'!E33 -> M | F22: ='5.일위대가'!F33 -> 50
B23: 16 | C23: ='5.일위대가'!C34 -> 신호용 케이블 | D23: ='5.일위대가'!D34 -> 4C x 0.5mm | E23: ='5.일위대가'!E34 -> M | F23: ='5.일위대가'!F34 -> 60
B24: 17 | C24: ='5.일위대가'!C35 -> 신호용 케이블 | D24: ='5.일위대가'!D35 -> 6C x 0.5mm | E24: ='5.일위대가'!E35 -> M | F24: ='5.일위대가'!F35 -> 30
B25: 18 | C25: ='5.일위대가'!C36 -> 신호용 케이블 | D25: ='5.일위대가'!D36 -> 10C x 0.5mm | E25: ='5.일위대가'!E36 -> M | F25: ='5.일위대가'!F36 -> 10
B26: 19 | C26: ='5.일위대가'!C37 -> 소형계전기 | D26: ='5.일위대가'!D37 -> Relay AC24V 4a4c (SOCKET 포함) | E26: ='5.일위대가'!E37 -> EA | F26: ='5.일위대가'!F37 -> 0
B27: 20 | C27: ='5.일위대가'!C38 -> 소형계전기 | D27: ='5.일위대가'!D38 -> Relay DC24V 4a4c (SOCKET 포함) | E27: ='5.일위대가'!E38 -> EA | F27: ='5.일위대가'!F38 -> 3
B28: 21 | C28: ='5.일위대가'!C39 -> 소형계전기 | D28: ='5.일위대가'!D39 -> Relay AC220V 4a4c (SOCKET 포함) | E28: ='5.일위대가'!E39 -> EA | F28: ='5.일위대가'!F39 -> 3
B29: 22 | C29: ='5.일위대가'!C40 -> HI-BOX (Relay SET-UP) | D29: ='5.일위대가'!D40 -> 190(W) X 280 (H) X 180(D) | E29: ='5.일위대가'!E40 -> EA | F29: ='5.일위대가'!F40 -> 1
B30: 23 | C30: ='5.일위대가'!C41 -> HI-BOX (SGW 외부시공 방수용) | D30: ='5.일위대가'!D41 -> 300(W) X 400 (H) X 180(D) | E30: ='5.일위대가'!E41 -> EA | F30: ='5.일위대가'!F41 -> 0
B31: 24 | C31: ='5.일위대가'!C42 -> 수위감지센서 | D31: ='5.일위대가'!D42 -> YQ-1 A/B접점 | E31: ='5.일위대가'!E42 -> EA | F31: ='5.일위대가'!F42 -> 3
B32: 25 | C32: ='5.일위대가'!C43 -> 수위감지센서 무게추 | D32: ='5.일위대가'!D43 -> DSF-014 | E32: ='5.일위대가'!E43 -> EA | F32: ='5.일위대가'!F43 -> 2
B33: 26 | C33: ='5.일위대가'!C53 -> 넘버링튜브 | D33: ='5.일위대가'!D53 -> 1.5SQ 백색 | E33: M | F33: ='5.일위대가'!F53 -> 5
B34: 27 | C34: ='5.일위대가'!C54 -> 압착단자 | D34: ='5.일위대가'!D54 -> 15SQ x 3mm Y형 | E34: EA | F34: ='5.일위대가'!F54 -> 100
B35: 28 | C35: ='5.일위대가'!C55 -> 압착단자 | D35: ='5.일위대가'!D55 -> 15SQ x 3mm PIN형 | E35: EA | F35: ='5.일위대가'!F55 -> 100
B36: 29 | C36: 기타잡자재 | D36: 재료비의 3% 이내 | E36: 식 | F36: 1
B37: 30 | C37: 공구손료 | D37: 인건비의 3% 이내 | E37: 식 | F37: 1
B38: 31 | C38: 출장경비 | E38: 식 | F38: 1
B39: 32 | C39: 공사보험료 | D39: 안전관리비/산재보험료/고용보험료/국민건강보험료/국민연금보험료/노인장기요양 보험료 | E39: 식 | F39: 각1
B40: 33 | C40: 일반관리비/이윤 | E40: 식 | F40: 1

Sheet 9.공사업체 출장경비
B2: 공사업체 출장경비 기준산출내역
L3: ='3.공사예산내역서(갑)'!$H$4 -> (작성일자:`22년 01월 20일)
L4: (단위:원, VAT별도)
B5: 출발지 | C5: 도착지 | D5: 작업일수 | E5: 작업인원 | F5: 왕복 거리(Km) | G5: 왕복 유류비 | H5: 왕복 교통비 | I5: 숙박비 | J5: 합계 | K5: 출장경비 | L5: 비고
B6: 업체소제지 (성남) | D6: 1 | E6: 2 | F6: =F7*2 -> 0 | G6: =G7*2 -> 0 | H6: =H7*2 -> 0 | I6: =I7*2 -> 0 | J6: =((G6+H6)*D6)+I6 -> 0 | K6: 200000
B7: 1)제주도 지역은 별도협의 산출. | E7: 편도기준입력 | F7: 0 | G7: 0 | H7: 0 | I7: 0
B8: 2)차종은 중형 경유 기준임. (2020 그랜드 스타렉스, 2.5 디젤 어반 9인승 공인연비 자동 9.4 km/ℓ (4등급))
B9: 3)유류비는 작성일기준 단가적용
B10: 4)왕복 거리는 네이버 지도 추천 기준임.
B11: 5)작업공수 합계가 1일 초과할 경우 숙박비 적용 (1인 1실 50,000원)
B12: 6)숙박비는 별도협의에 따라 제외가능
B13: 7)출발지 기준 50Km 이상만 출장지역으로 인정
B14: 8)출장경비는 차량 감가상각비/유지관리비 반영하여 합계금액에 1.3배 적용함.
L16: 지역 | M16: 표준금액
L17: 경기도 | M17: 50000
L18: 충청북도 | M18: 100000
L19: 충청남도 | M19: 100000
L20: 강원도 | M20: 150000
L21: 경상북도 | M21: 150000
L22: 경상남도 | M22: 200000
L23: 전라남도 | M23: 200000
L24: 전라북도 | M24: 150000
B36: ※ 네이버 지도 추천거리 화면 캡처 후 그림형식>그림압축>전자메일 기준 적용

Sheet 10.정기점검 출장경비
B2: 정기점검 출장경비 기준산출내역
L3: ='3.공사예산내역서(갑)'!$H$4 -> (작성일자:`22년 01월 20일)
L4: (단위:원, VAT별도)
B5: 출발지 | C5: 도착지 | D5: 작업일수 | E5: 작업인원 | F5: 왕복 거리(Km) | G5: 왕복 유류비 | H5: 왕복 교통비 | I5: 숙박비 | J5: 합계 | K5: 출장경비 | L5: 비고
B6: 마포/부산/광주 | C6: ='9.공사업체 출장경비'!C6 -> 0 | D6: 1 | E6: 2 | F6: =F7*2 -> 0 | G6: =G7*2 -> 0 | H6: =H7*2 -> 0 | I6: =I7*2 -> 0 | J6: =((G6+H6)*D6)+I6 -> 0 | K6: 150000
B7: 1)제주도 지역은 별도협의 산출. | E7: 편도기준입력 | F7: 0 | G7: 0 | H7: 0 | I7: 0
B8: 2)차종은 준중형 경유 기준임. (2020 스포티지 더볼트, 2.0 디젤 공인연비 자동 13.8 km/ℓ)
B9: 3)유류비는 작성일기준 단가적용
B10: 4)왕복 거리는 네이버 지도 추천 기준임.
B11: 5)당일 공사기준으로 작업일수 1일 이상 시 숙박비/식대 적용 (1실 50,000원/식대 8,000원)
B12: 6)출장경비는 차량 감가상각비/유지관리비 반영하여 합계금액에 1.3배 적용함.
B34: ※ 네이버 지도 추천거리 화면 캡처 후 그림형식>그림압축>전자메일 기준 적용

Sheet 11.21년 원격관제SVC 비용
B1: ▣ '21년 원격관제(RMS/EMS)SVC 단가 산출Sheet | N1: * '21년 관제SVC 비용(원)
C2: NO | D2: 구 분 | E2: 비용내역 | F2: 총운영비(년) | G2: 운영비(월) | H2: SVC단가/ 발생건 | I2: 관제 Point | J2: 가중치(%) | K2: 운영비(월) | L2: 관제SVC 비용(월) | M2: 운영비(년) | N2: 관제SVC 비용(년) | O2: '21년 관제SVC 단가 기준정보
C3: 1 | D3: 클라우드(RMS/EMS) 이용료 | E3: RMS 클라우드 이용료 | F3: =SUM(O14) -> 187700000 | G3: =SUM(F3/12) -> 15641667 | H3: =SUM(G3/O4) -> 720.5153 | I3: ='1.구축견적'!I8 -> 20 | J3: =IF(I3=6,E29+0.5,IF(I3=7,E29+0.22,IF(I3=11,E30,IF(I3=21,E31+0.1,IF(I3=31,E32+0.07,IF(I3=51,E33+0.03,IF(I3<=5,E26,IF(I3<=10,E29,IF(I3<=20,E30,IF(I3<=30,E31,IF(I3<=50,E32,IF(I3<=100,E33,IF(I3<=200,E34,IF(I3<=300,E35,IF(I3<=400,E36,IF(I3<=500,E37,E37)))))))))))))))) -> 1.35 | K3: =SUM(I3*H3)*J3 -> 19453.913 | L3: =ROUNDDOWN((K6),0) -> 34888 | M3: =SUM(K3)*12 -> 233446.96 | N3: =ROUNDDOWN((M6),0) -> 418000 | O3: 관제 포인트/ 알람발생건수 | P3: 비용 항목
E4: 시스템 유지보수 인건비 | F4: =SUM(O15) -> 104300000 | G4: =SUM(F4/12) -> 8691666.7 | H4: =SUM(G4/O4) -> 400.37158 | K4: =SUM(I3*H4)*J3 -> 10810.033 | M4: =SUM(K4)*12 -> 129720.39 | O4: 21709 | P4: 원격관제 총Point('20년12월말 기준)
E5: 관제Point이용료/정보보안/사용자관리 등 운영인건비 | F5: =SUM(O19*I3)+23000000 -> 23020000 | G5: =SUM(23000000/12) -> 1916666.7 | H5: =SUM(G5/O4)+SUM(83) -> 171.28904 | K5: =SUM(I3*H5)*J3 -> 4624.804 | M5: =SUM(K5)*12 -> 55497.647 | O5: 55189 | P5: 년간 알람발생건('20년12월말 기준)
E6: 소 계 | F6: =SUM(F3:F5) -> 315020000 | G6: =SUM(G3:G5) -> 26250000 | H6: =SUM(H3:H5) -> 1292.1759 | K6: =SUM(K3:K5) -> 34888.75 | M6: =ROUNDDOWN((M3+M4+M5),-3) -> 418000 | O6: =SUM(O5)/12 -> 4599.0833 | P6: 월평균 발생건&발생률(월 발생알람/관제 총Point: 21.2%)
C7: 일반관리비 | E7: 0.06 | H7: =SUM(K6/I3) -> 1744.4375 | K7: =SUM(K6)*E7 -> 2093.325 | L7: =SUM(K7:K8) -> 3942.4287 | M7: =SUM(M6*E7) -> 25080 | N7: =SUM(M7:M8) -> 47234 | O7: =SUM(O5)/365 -> 151.20274 | P7: 일평균 발생건&발생률(일 발생알람/관제 총Point: 0.7%)
C8: 이 윤 | E8: 0.05 | K8: =SUM(K6+K7)*E8 -> 1849.1037 | M8: =SUM(M6+M7)*E8 -> 22154 | O8: 7 | P8: 관제 알람(1건) 대응/처리 평균시간(분)
C9: 원격관제(RMS/EMS) Cloud 이용료 합계 | L9: =IF(AND(I3>=100,I3<=117),160000,IF(AND(I3>=182,I3<=200),250000,IF(I3<=5,22000,IF(I3>=401,F37,IF(AND(I3>=201,I3<=400),F36,SUM(L2:L8)))))) -> 38830.429 | N9: =SUM(L9)*12 -> 465965.14 | O9: =SUM(O16)/365 -> 2356164.4 | P9: 관제 Monotoring 인건비/1일
C10: 2 | D10: 관제서비스 비용 (Monitoring/Reporting) | E10: 관제 모니터링/분석 | F10: =SUM(O16) -> 860000000 | G10: =SUM(F10/12) -> 71666667 | H10: =SUM(I3*21.2%) -> 4.24 | K10: =IF(I3=5,SUM(H10*O12)-2000,IF(I3=6,SUM(H10*O12)+1000,SUM(H10*O12))) -> 48563.166 | L10: =ROUNDDOWN((K11+K14+K18),0) -> 55240 | M10: =SUM(K10)*12 -> 582757.99 | N10: =ROUNDDOWN((M11+M14+M18),0) -> 662890 | O10: =SUM(O9)/24 -> 98173.516 | P10: 알람 대응/처리 인건비(1hr)
E11: 소 계 | F11: =SUM(F10) -> 860000000 | G11: =SUM(F11/12) -> 71666667 | H11: =SUM(H10) -> 4.24 | K11: =SUM(K10) -> 48563.166 | M11: =SUM(M10) -> 582757.99 | O11: =SUM(O10)/60 -> 1636.2253 | P11: 알람 대응/처리 인건비(1분)
D12: 임대비용/수광비 | E12: 관제센터 임대관리비 | F12: =SUM(O17) -> 299909664 | G12: =SUM(F12)/12 -> 24992472 | H12: =SUM(G12/O4) -> 1151.2493 | K12: =SUM(H12*H10) -> 4881.2972 | M12: =SUM(K12)*12 -> 58575.567 | O12: =SUM(O11)*O8 -> 11453.577 | P12: 알람 대응/처리 인건비(1건)
E13: 에너지(전기) 비용 | F13: =SUM(O18) -> 9450000 | G13: =SUM(F13)/12 -> 787500 | H13: =SUM(G13/O4) -> 36.275278 | K13: =SUM(H13*H10) -> 153.80718 | M13: =SUM(K13)*12 -> 1845.6861 | O13: 69 | P13: 관제대응 통신비 단가(1통화)
E14: 소 계 | F14: =SUM(F12:F13) -> 309359664 | G14: =SUM(F14/12) -> 25779972 | H14: =SUM(H12:H13) -> 1187.5246 | K14: =SUM(K12:K13) -> 5035.1044 | M14: =SUM(M12:M13) -> 60421.253 | O14: 187700000 | P14: AWS Cloud 이용료(년)
D15: 기타비용 | E15: 통신비용 | F15: 3750000 | G15: =SUM(F15)/12 -> 312500 | H15: =SUM(O13) -> 69 | K15: =SUM(H15*H10) -> 292.56 | M15: =SUM(K15)*12 -> 3510.72 | O15: 104300000 | P15: RMS Platform 유지보수 인건비(년)
E16: 감가상각(PC/SW 등) | F16: 71000000 | G16: =SUM(F16)/12 -> 5916666.7 | H16: =SUM(G16/O4) -> 272.54441 | K16: =SUM(H16*H10) -> 1155.5883 | M16: =SUM(K16)*12 -> 13867.06 | O16: 860000000 | P16: 관제(RMS) 인건비(월급여+상여+퇴직급여+복리후생비 포함)
E17: 소모품비 | F17: 1876540 | G17: =SUM(F17)/12 -> 156378.33 | H17: =SUM(G17/O4) -> 7.2033872 | K17: =SUM($I$3*H17)*$J$3 -> 194.49146 | M17: =SUM(K17)*12 -> 2333.8975 | O17: 299909664 | P17: 관제센터(IOC) 임대비용(년)
E18: 소 계 | F18: =SUM(F15:F16) -> 74750000 | G18: =SUM(F18/12) -> 6229166.7 | H18: =SUM(H15:H16) -> 341.54441 | K18: =SUM(K15:K17) -> 1642.6398 | M18: =SUM(K18)*12 -> 19711.677 | O18: 9450000 | P18: 관제센터(IOC) 에너지 사용료(년)
C19: 일반관리비 | E19: 0.06 | H19: =SUM(K11+K14+K18)/I3 -> 2762.0455 | I19: ↑ | K19: =SUM(K11+K14+K18)*E19 -> 3314.4546 | L19: =SUM(K19:K20) -> 6242.2228 | M19: =SUM(M11+M14+M18)*E19 -> 39773.455 | N19: =SUM(M19:M20) -> 74906.674 | O19: 1000 | P19: 관제 1Point 이용료(3년 감가상각)/년
C20: 이 윤 | E20: 0.05 | I20: 관제Point 입력 | K20: =SUM(K11+K14+K18+K19)*E20 -> 2927.7682 | M20: =SUM(M11+M14+M18+M19)*E20 -> 35133.219 | O20: * 관제 운영비 산출 기준정보 1. RMS시스템 이용료는 클라우드 이용료,유지보수비,관리비를 포함(2.9억/년) 적용함. 2. 원격관제SVC 인건비(Monitoring(9명), Data분석&Report(2명), 관리자(1명)) 3. 원격관제 Monitoring 알람 발생율은 월 평균 8.3%임. 4. 원관제SVC 비용은 시스템 이용료, 유지보수 비용, Monitoring비용, 임대관리비, 수광비를 반영하여 산출한 비용임.
C21: 원격관제(RMS) Monitoring 비용 합계 | L21: =SUM(L10:L20) -> 61482.223 | N21: =SUM(N10:N20) -> 737796.67
C22: 원격관제(시스템 이용료+관제비용) 합계 | L22: =ROUNDDOWN((L9+L21),-3) -> 100000 | N22: =ROUNDDOWN((N9+N21),-3) -> 1203000
B24: ■ 관제 Point별 서비스 기준 단가
C25: 관제Point | E25: 가중치(%) | F25: 클라우드 이용료(월) | G25: RMS Monitoring 비용(월) | H25: 원격관제 서비스 비용합계(월) | K25: 비 고
C26: 1 ~ 5 | E26: 0 | F26: 22000 | G26: 3,060 ~ 13,090 | H26: 25,000 ~ 35,000 | K26: - 관제Svc 단가는 '20년 운영비용을 기준으로 '21년도 관제SVC 비용 산출에 적용한다. - 관제Svc 비용은 클라우드 시스템 이용료와 관제(Monitoring) 비용으로 구분 산출한다. - 관제Svc 비용은 관제Point 수량을 기준으로 서비스 단가가 산출되며, : EMS(에너지 Data수집)는 클라우드 시스템 이용료를 적용, : RMS(원격감시)는 클라우드 시스템 이용료와 원격관제 Monitoring 비용을 합산하여 산출한다. - 관제Svc 단가는 관제Point 구간별 가중치를 적용하여 최대한 산출비용 오차를 줄이고자 함. - 관제Svc 비용 기준은 Monitoring 서비스 기준 비용이며, 원격제어 서비스 제공시 관제비용은 별도 적용해야 한다.
C27: 6 | E27: 2 | F27: 17250 | G27: 19,590 | H27: 36,000
C28: 7 | E28: 1.75 | F28: 17315 | G28: 21,539 | H28: 38,000
C29: 8 ~ 10 | E29: 1.5 | F29: 17,250 ~ 21,570 | G29: 24,600 ~ 30,750 | H29: 41,000 ~ 52,000
C30: 11 ~ 20 | E30: 1.35 | F30: 21,350 ~ 38,830 | G30: 33,800 ~ 67,480 | H30: 55,000 ~ 100,000
C31: 21 ~ 30 | E31: 1.15 | F31: 37,750 ~ 49,600 | G31: 64,540 ~ 92,170 | H31: 102,000 ~ 141,000
C32: 31 ~ 50 | E32: 1 | F32: 47,700 ~ 71,900 | G32: 95,228 ~ 153,560 | H32: 142,000 ~ 225,000
C33: 51 ~ 100 | E33: 0.945 | F33: 71,500 ~ 160,000 | G33: 156,620 ~ 307,090 | H33: 228,000 ~ 467,000
C34: 101 ~ 200 | E34: 0.75 | F34: 160,000 ~ 250,000 | G34: 310,000 ~ 613,870 | H34: 470,000 ~ 863,000
C35: 201 ~ 300 | E35: 0 | F35: 250000 | G35: 615,730 ~ 919,000 | H35: 825,000 ~ 1,168,000
C36: 301 ~ 400 | E36: 0 | F36: 250000 | G36: 922,060 ~ 1,145,000 | H36: 1,112,000 ~ 1,475,000
C37: 401 ~ 500 | E37: 0 | F37: 300000 | G37: 1,228,400 ~ 1,531,000 | H37: 1,528,000 ~ 1,831,000
C38: 501 ~ 600 | E38: 0 | F38: 300000 | G38: 1,534,730 ~ 1,838,000 | H38: 1,834,000 ~ 2,137,000
C39: 601 ~ | E39: 별도협의

Sheet 12.정기점검비 산출근거
B2: 건물기준 | C2: 1Point 점검작업 M/P 기준 (2인 1조) | E2: 1Point M/P | F2: Point | G2: Total M/P | H2: 적용노임 (H/W시험사) | I2: 산출금액
B3: 대형(10,000㎡ 이상) | C3: 0.066 | E3: {=_xlfn.IFS('1.구축견적'!Q11<3000,"0.025",AND('1.구축견적'!Q11>=3000,'1.구축견적'!Q11<=9999),"0.041",'1.구축견적'!Q11>=10000,"0.066")} -> 0.041 | F3: ='1.구축견적'!$I$8 -> 20 | G3: =E3*F3 -> 0.82 | H3: 332268 | I3: =H3*G3 -> 272459.76
B4: 중형(3,000 ~ 10,000㎡) | C4: 0.041
B5: 소형(3,000㎡ 이하) | C5: 0.025

Sheet 첨부2_출장경비
C2: 출장경비 기준산출내역
K3: (작성일자:`19년 01월 21일)
K4: (단위:원, VAT별도)
C5: 권역 | D5: 출발지 | E5: 도착 기준점 | F5: 왕복 거리(Km) | G5: 왕복 유류비 | H5: 왕복 교통비 | I5: 합계 | J5: 출장경비 | K5: 비고
C6: 경기도 | D6: 성남시 | E6: 연천군청 | F6: 200 | G6: 30000 | H6: 8600 | I6: =G6+H6 -> 38600 | J6: 50000 | K6: ※ 경기도 제외지역 공사업체 사업장주소 기준 50Km 미만 소재지 : 경기도 성남시 ※ 출장경비 산출기준 (왕복유류비+교통비) x 1.3
C7: 강원도 | E7: 삼척시청 | F7: 480 | G7: 60000 | H7: 24600 | I7: =G7+H7 -> 84600 | J7: 100000
C8: 충청남도 | E8: 서천군청 | F8: 360 | G8: 45000 | H8: 21800 | I8: =G8+H8 -> 66800 | J8: 100000
C9: 충청북도 | E9: 장수군청 | F9: 466 | G9: 60000 | H9: 24600 | I9: =G9+H9 -> 84600 | J9: 100000
C10: 경상북도 | E10: 경주시청 | F10: 620 | G10: 80000 | H10: 34000 | I10: =G10+H10 -> 114000 | J10: 150000
C11: 경상남도 | E11: 거제시청 | F11: 760 | G11: 95000 | H11: 36600 | I11: =G11+H11 -> 131600 | J11: 200000
C12: 전라북도 | E12: 순창군청 | F12: 500 | G12: 65000 | H12: 31800 | I12: =G12+H12 -> 96800 | J12: 150000
C13: 전라남도 | E13: 완도군청 | F13: 830 | G13: 110000 | H13: 38600 | I13: =G13+H13 -> 148600 | J13: 200000
C14: 1)제주도 지역은 별도협의.
C15: 2)도착기준점은 권역별 최장 거리지역 기준임.
C16: 3)차종은 중형 경유 기준임.
C17: 4)유류비는 작성일기준 단가적용
