Workbook
Name _________________PRN2: [1]내역서!#REF!
Name _________________PRN3: [1]내역서!#REF!
Name _________________PRN4: [1]내역서!#REF!
Name _________________PRN6: [1]내역서!#REF!
Name _________________PRN7: [1]내역서!#REF!
Name ________________PRN2: [1]내역서!#REF!
Name ________________PRN3: [1]내역서!#REF!
Name ________________PRN4: [1]내역서!#REF!
Name ________________PRN6: [1]내역서!#REF!
Name ________________PRN7: [1]내역서!#REF!
Name _______________PRN2: [1]내역서!#REF!
Name _______________PRN3: [1]내역서!#REF!
Name _______________PRN4: [1]내역서!#REF!
Name _______________PRN6: [1]내역서!#REF!
Name _______________PRN7: [1]내역서!#REF!
Name ______________PRN2: [1]내역서!#REF!
Name ______________PRN3: [1]내역서!#REF!
Name ______________PRN4: [1]내역서!#REF!
Name ______________PRN6: [1]내역서!#REF!
Name ______________PRN7: [1]내역서!#REF!
Name _____________PRN2: [1]내역서!#REF!
Name _____________PRN3: [1]내역서!#REF!
Name _____________PRN4: [1]내역서!#REF!
Name _____________PRN6: [1]내역서!#REF!
Name _____________PRN7: [1]내역서!#REF!
Name ____________PRN2: [1]내역서!#REF!
Name ____________PRN3: [1]내역서!#REF!
Name ____________PRN4: [1]내역서!#REF!
Name ____________PRN6: [1]내역서!#REF!
Name ____________PRN7: [1]내역서!#REF!
Name ___________PRN2: [1]내역서!#REF!
Name ___________PRN3: [1]내역서!#REF!
Name ___________PRN4: [1]내역서!#REF!
Name ___________PRN6: [1]내역서!#REF!
Name ___________PRN7: [1]내역서!#REF!
Name __________PRN2: [1]내역서!#REF!
Name __________PRN3: [1]내역서!#REF!
Name __________PRN4: [1]내역서!#REF!
Name __________PRN6: [1]내역서!#REF!
Name __________PRN7: [1]내역서!#REF!
Name _________PRN2: [1]내역서!#REF!
Name _________PRN3: [1]내역서!#REF!
Name _________PRN4: [1]내역서!#REF!
Name _________PRN6: [1]내역서!#REF!
Name _________PRN7: [1]내역서!#REF!
Name ________PRN2: [1]내역서!#REF!
Name ________PRN3: [1]내역서!#REF!
Name ________PRN4: [1]내역서!#REF!
Name ________PRN6: [1]내역서!#REF!
Name ________PRN7: [1]내역서!#REF!
Name _______DOG1: #REF!
Name _______DOG2: #REF!
Name _______DOG22: #REF!
Name _______DOG3: #REF!
Name _______DOG33: #REF!
Name _______DOG4: #REF!
Name _______IL1: #REF!
Name _______PI48: #REF!
Name _______PI60: #REF!
Name _______PRN2: [1]내역서!#REF!

Sheet 1.구축견적
B2: =CONCATENATE(P6,Q7,R7) -> 1. 펄어비스 안양오피스 원격감시시스템 구축견적
B4: 원격감시 Monitoring service 시스템 구축 비용 | H4: 원격감시 Monitoring service 운영비용(월)
B6: 구분 | C6: 수량 | D6: 단가 | E6: 합계 | H6: 구분 | I6: 개소/Point | K6: 통신비용 | L6: 이용/유지비용 | M6: 합계 | P6: 1. | Q6: 현장명 입력 | S6: 월 | U6: 일 | V6: 일)
B7: 원격감시 구축공사 | C7: 1 | D7: ='3.공사예산내역서(갑)'!G27 -> 3747000 | E7: =SUM(C7*D7) -> 3747000 | H7: 통신비 | I7: 3 | J7: 개소 | K7: 15000 | M7: =I7*K7 -> 45000 | P7: 2. | Q7: 펄어비스 안양오피스 | R7: 원격감시시스템 구축견적 | S7: 10 | T7: 월 | U7: 19
B8: 관제 PC | C8: 0 | D8: 0 | E8: =SUM(C8*D8) -> 0 | H8: 원격관제 SVC 비용 | I8: =COUNTA('2.관제점리스트'!B:B)-2 -> 13 | J8: Point | L8: 69000 | M8: =SUM(K8:L8) -> 69000 | P8: 공사명 : | Q8: =Q7 -> 펄어비스 안양오피스 | R8: 설비관제점 List
B9: Engineering | C9: 0 | E9: =SUM(C9*D9) -> 0 | H9: 정기점검비 | I9: =I8 -> 13 | J9: Point | L9: 186000 | M9: =L9/12 -> 15500 | P9: (작성일자:`22년 | Q9: =Q7 -> 펄어비스 안양오피스 | R9: 원격감시시스템 구축공사
B10: 구축비 계 | E10: =SUM(E7:E9) -> 3747000 | H10: 유지보수비 | I10: =I8 -> 13 | J10: Point | L10: 739000 | M10: =L10/12 -> 61583.333 | Q10: 건물 연면적 입력(㎡)
B11: ※ 원격감시 구축공사는 원격감시시스템 자재, 인건비 등 현장 구축 공사 비용임. ※ Engineering 비용은 S&I 전문구축 고급인력 투입비용임 (프로그램 세팅, 시운전 등) | H11: 총합계 | M11: =ROUND(SUM(M7:M10),-3) -> 191000 | Q11: 11395
H12: ※ 통신비는 Smart Gateway 1개소당 U+ LTE 무선 라우터 설치기준 ※ 원격관제 SVC 비용은는 AWS solution 서버사용, 통합운영센터 24시간 이중감시 서비스 합계 금액임 ※ 정기점검은 반기1회 원격감시시스템 장비 점검 및 연동 test 수행 ※ 유지보수비는 원격감시시스템 부품 보수 및 고장 시 교체 비용임 ※ 정기점검 및 유지보수비 외부사업장 일 경우 적용 (FM시설관리 사업장에 대한 장비점검 및 보수비용은 운영센터와 별도협의)
B18: 원격감시 Monitoring service 비용
M19: 단위: 부가세별도,원
B20: 구분 | D20: 월비용 | F20: 년간비용 | I20: 비고
B21: 구축비용 | D21: =ROUND(E10/24,-3) -> 156000 | F21: =D21*12 -> 1872000 | I21: 원격감시 구축공사 (감가상각 2년 기준)
B22: 운영유지비 | D22: =M11 -> 191000 | F22: =D22*12 -> 2292000 | I22: 통신비, 24시간 통합운영센터 이중감시
B23: 비용계 | D23: =D21+D22 -> 347000 | F23: =D23*12 -> 4164000

Sheet 2.관제점리스트
B2: =CONCATENATE('1.구축견적'!P7,'1.구축견적'!Q8,'1.구축견적'!R8) -> 2. 펄어비스 안양오피스 설비관제점 List
B4: No. | C4: 인출위치 | E4: SETUP_BOX | F4: 인출장비명 | G4: 관제명 | H4: 기타
B5: 1 | C5: 1F | D5: 방재실 | E5: SGW1 | F5: 화재수신반 | G5: 화재수신반 통합화재신호
B6: 2 | G6: 화재수신반 연동정지 스위치 조작
B7: 3 | C7: B2F | D7: 기계실 | E7: SGW2 | F7: LP-M | G7: T-1 저수조 고수위
B8: 4 | G8: T-1 저수조 저수위
B9: 5 | G9: P-2 B2F 물탱크실 배수 집수정 고수위
B10: 6 | G10: P-3-1 B2F 휀룸 배수 집수정 고수위
B11: 7 | G11: P-3-2 B2F 창고1 배수 집수정 고수위
B12: 8 | G12: P-3-3 B2F 창고2 배수 집수정 고수위
B13: 9 | G13: P-4 B2F 화장실 하부 PIT 오배수 펌프 고수위
B14: 10 | E14: SED1 | F14: 부스터펌프 제어반 | G14: P-1 급수 부스터펌프 이상경보
B15: 11 | D15: 발전기실 | E15: SGW3 | F15: 발전기 제어반 | G15: 발전기 UVR 정전신호
B16: 12 | G16: 발전기 가동신호
B17: 13 | G17: 발전기 이상

Sheet 3.공사예산내역서(갑)
B2: 공사예산내역서(갑)
B4: =CONCATENATE('1.구축견적'!P8,'1.구축견적'!Q9,'1.구축견적'!R9) -> 공사명 : 펄어비스 안양오피스 원격감시시스템 구축공사 | H4: =CONCATENATE('1.구축견적'!P9,'1.구축견적'!S7,'1.구축견적'!T7,'1.구축견적'!U7,'1.구축견적'!V6) -> (작성일자:`22년 10월 19일)
H5: (단위:원, VAT별도)
B6: 구 분 | C6: 공 사 항 목 | D6: 자 재 비 | E6: 인 건 비 | F6: 기계/기타경비 | G6: 합 계 | H6: 비 고
B7: 직접공사비
C8: 원격감시시시스템 구축공사 | D8: ='4.공사예산내역서(을)'!H8+'4.공사예산내역서(을)'!H9+'4.공사예산내역서(을)'!H10 -> 2019700 | E8: ='4.공사예산내역서(을)'!J8+'4.공사예산내역서(을)'!J9+'4.공사예산내역서(을)'!J10 -> 1080209.8 | G8: =D8+E8+F8 -> 3099909.8 | H8: 내역서 (을) 1~3항
C9: 잡자재비 / 공구손료 | D9: ='4.공사예산내역서(을)'!H15 -> 60591 | F9: ='4.공사예산내역서(을)'!L13 -> 32406.294 | G9: =D9+E9+F9 -> 92997.294 | H9: 내역서 (을) 4~5항
C10: 출장경비 | F10: ='4.공사예산내역서(을)'!L14 -> 0 | G10: =D10+E10+F10 -> 0 | H10: 내역서 (을) 6항
C12: 소 계 | D12: =SUM(D7:D11) -> 2080291 | E12: =SUM(E7:E11) -> 1080209.8 | F12: =SUM(F7:F11) -> 32406.294 | G12: =SUM(G7:G11) -> 3192907.1
B13: 간접비
C14: 안전 관리비 (자재비+인건비의 2.93%) | G14: =SUM(D12+E12)*2.93% -> 92602.674
C15: 산재 보험료 (인건비의 3.70%) | G15: =E12*3.7% -> 39967.763
C16: 고용 보험료 (인건비의 1.01%) | G16: =E12*1.01% -> 10910.119
C17: 국민건강 보험료 (인건비의 3.495%) | G17: =E12*3.495% -> 37753.333
C18: 국민연금 보험료 (인건비의 4.5%) | G18: =E12*4.5% -> 48609.442
C19: 노인장기요양 보험료 (건강보험료의 12.27%) | G19: =G17*12.27% -> 4632.334
C21: 소 계 | G21: =SUM(G13:G20) -> 234475.66
B23: 일반 관리비 | C23: (직접공사비+간접공사비)의 5% | G23: =SUM(G12,G21)*5% -> 171369.14
B24: 이 윤 | C24: (인건비+간접공사비+일반관리비)의 10% | G24: =SUM(E12,G21,G23)*10% -> 148605.46
C26: 소 계 | G26: =SUM(G22:G25) -> 319974.6
B27: 공 사 금 액 | C27: 합 계 | D27: =SUM(D12) -> 2080291 | E27: =SUM(E12) -> 1080209.8 | F27: =SUM(F12) -> 32406.294 | G27: =ROUNDDOWN(SUM(G26,G21,G12),-3) -> 3747000 | H27: (▶천단위 절삭)

Sheet 4.공사예산내역서(을)
B2: 공사예산내역서(을)
B4: ='3.공사예산내역서(갑)'!$B$4 -> 공사명 : 펄어비스 안양오피스 원격감시시스템 구축공사 | N4: ='3.공사예산내역서(갑)'!$H$4 -> (작성일자:`22년 10월 19일)
N5: (단위 : 원,VAT별도)
B6: NO | C6: 항 목 | D6: 규 격 | E6: 단위 | F6: 수량 | G6: 자 재 비 | I6: 인 건 비 | K6: 기계/기타경비 | M6: 합 계 | N6: 비 고
G7: 단가 | H7: 금액 | I7: 단가 | J7: 금액 | K7: 단가 | L7: 금액
B8: 1 | C8: 원격감시시스템 장비설치 | E8: 식 | F8: 1 | G8: ='5.일위대가'!H28 -> 1870000 | H8: =G8*F8 -> 1870000 | I8: ='5.일위대가'!K28 -> 548167.38 | J8: =I8*F8 -> 548167.38 | M8: =SUM(H8,J8,L8) -> 2418167.4 | N8: ▶일위대가 참조
B9: 2 | C9: 원격감시시스템 배관/배선작업 | E9: 식 | F9: 1 | G9: ='5.일위대가'!H50 -> 142800 | H9: =G9*F9 -> 142800 | I9: ='5.일위대가'!K50 -> 444594.44 | J9: =I9*F9 -> 444594.44 | M9: =SUM(H9,J9,L9) -> 587394.44 | N9: ▶일위대가 참조
B10: 3 | C10: 원격감시시스템 연동작업 | E10: 식 | F10: 1 | G10: ='5.일위대가'!H56 -> 6900 | H10: =G10*F10 -> 6900 | I10: ='5.일위대가'!K56 -> 87448 | J10: =I10*F10 -> 87448 | M10: =SUM(H10,J10,L10) -> 94348 | N10: ▶일위대가 참조
D11: 소 계 | H11: =SUM(H8:H10) -> 2019700 | J11: =SUM(J8:J10) -> 1080209.8 | M11: =SUM(M8:M10) -> 3099909.8
B12: 4 | C12: 잡자재비 | D12: 자재비 계의 3% 이내 | E12: % | F12: 0.03 | H12: =H11*F12 -> 60591 | M12: =SUM(H12,J12,L12) -> 60591
B13: 5 | C13: 공구손료 | D13: 인건비 계의 3% 이내 | E13: % | F13: 0.03 | L13: =J11*F13 -> 32406.294 | M13: =SUM(H13,J13,L13) -> 32406.294
B14: 6 | C14: 출장경비 | E14: 식 | F14: 1 | K14: ='9.공사업체 출장경비'!K6 -> 0 | L14: =K14*F14 -> 0 | M14: =SUM(H14,J14,L14) -> 0
D15: 소 계 | H15: =SUM(H12:H14) -> 60591 | J15: =SUM(J12:J13) -> 0 | L15: =SUM(L12:L14) -> 32406.294 | M15: =SUM(M12:M14) -> 92997.294
D16: 합 계 | H16: =SUM(H11,H15) -> 2080291 | J16: =SUM(J11,J15) -> 1080209.8 | L16: =SUM(L11,L15) -> 32406.294 | M16: =SUM(M15,M11) -> 3192907.1

Sheet 5.일위대가
B2: 일위대가
B4: ='3.공사예산내역서(갑)'!$B$4 -> 공사명 : 펄어비스 안양오피스 원격감시시스템 구축공사 | M4: ='3.공사예산내역서(갑)'!$H$4 -> (작성일자:`22년 10월 19일)
M5: (단위 : 원,VAT별도)
B6: NO | C6: 항 목 | D6: 규 격 | E6: 단위 | F6: 수량 | G6: 자 재 비 | I6: 인 건 비 | L6: 합 계 | M6: 비 고
G7: 단가 | H7: 금액 | I7: M/P | J7: 단가 | K7: 금액
B8: 1. 원격감시시스템 장비설치
C9: Smart Gateway | D9: WI-SUN/LECIM, S&I RMS연동, DI 8CH | E9: 대 | F9: 3 | G9: 420000 | H9: =F9*G9 -> 1260000 | L9: =H9+K9 -> 1260000 | M9: 개별자산관리 대상
C10: Smart End Device | D10: WI-SUN/LECIM, 4CH I/O | E10: 대 | F10: 1 | G10: 210000 | H10: =F10*G10 -> 210000 | L10: =H10+K10 -> 210000
C11: Smart DI Module | D11: DI INPUT [I/O 4ch] | E11: EA | F11: 0 | G11: 25000 | H11: =F11*G11 -> 0 | L11: =H11+K11 -> 0 | M11: 단순설치 자재납품 건
C12: Smart DO Module | D12: Relay OUTPUT [I/O 4ch] | E12: EA | F12: 0 | G12: 25000 | H12: =F12*G12 -> 0 | L12: =H12+K12 -> 0 | M12: 단순설치 자재납품 건
C13: Smart AI Module | D13: VDC/ADC INPUT [I/O 4ch] | E13: EA | F13: 0 | G13: 25000 | H13: =F13*G13 -> 0 | L13: =H13+K13 -> 0 | M13: 단순설치 자재납품 건
C14: Smart LED Detector Device | D14: Arduino Nano 10CH Board | E14: 대 | F14: 1 | G14: 350000 | H14: =G14*F14 -> 350000 | L14: =H14+K14 -> 350000
C15: Smart CDS Sensor Module | D15: High sensitivity CDS/3D Printing Cap | E15: 대 | F15: 5 | G15: 10000 | H15: =G15*F15 -> 50000 | L15: =H15+K15 -> 50000
C16: Mini DC-UPS | D16: MPS-L24 / DC24V 3.0A Adapter 포함 | E16: 대 | F16: 0 | G16: 230000 | H16: =F16*G16 -> 0 | L16: =H16+K16 -> 0 | M16: 단순설치 자재납품 건
C17: AC UPS | D17: APC BACK-UPS 650 (BX650LI-GR) | E17: 대 | F17: 0 | G17: 110000 | H17: =F17*G17 -> 0 | L17: =H17+K17 -> 0 | M17: 단순설치 자재납품 건
C18: Modbus RTU DI Board | D18: KM6054[I/O 13ch] - Digital INPUT | E18: EA | F18: 0 | G18: 107800 | H18: =F18*G18 -> 0 | L18: =H18+K18 -> 0 | M18: 단순교체 자재납품 건
C19: Modbus RTU AI Board | D19: KM6412[I/O 8ch] - Analog INPUT | E19: EA | F19: 0 | G19: 107800 | H19: =F19*G19 -> 0 | L19: =H19+K19 -> 0 | M19: 단순교체 자재납품 건
C20: NTC 저항식 온도센서 | D20: FS-200N | E20: EA | F20: 0 | G20: 5000 | H20: =F20*G20 -> 0 | L20: =H20+K20 -> 0 | M20: 단순교체 자재납품 건
C21: Smart Gateway 설치 | D21: 내선전공 | E21: 인 | I21: ='7.MP산출근거'!O9 -> 0.125 | J21: ='7.MP산출근거'!D42 -> 259089 | K21: =F9*I21*J21 -> 97158.375 | L21: =H21+K21 -> 97158.375 | M21: MP산출근거 1항 참조 | O21: =I21*F9 -> 0.375
C22: Smart End Device 설치 | D22: 내선전공 | E22: 인 | I22: ='7.MP산출근거'!O11 -> 0.125 | J22: ='7.MP산출근거'!D42 -> 259089 | K22: =F10*I22*J22 -> 32386.125 | L22: =H22+K22 -> 32386.125 | M22: MP산출근거 2항 참조
C23: Smart LED Detector Device 설치 | D23: 내선전공 | E23: 인 | I23: ='7.MP산출근거'!O15 -> 0.25 | J23: ='7.MP산출근거'!D42 -> 259089 | K23: =F14*I23*J23 -> 64772.25 | L23: =H23+K23 -> 64772.25 | M23: MP산출근거 4항 참조
C24: Smart CDS Sensor Module 설치 | D24: H/W 시험사 | E24: 인 | I24: ='7.MP산출근거'!O17 -> 0.0625 | J24: ='7.MP산출근거'!D46 -> 349792 | K24: =F15*I24*J24 -> 109310 | L24: =H24+K24 -> 109310 | M24: MP산출근거 5항 참조
C25: Smart Gateway SET-UP | D25: S/W 시험사 | E25: 인 | I25: ='7.MP산출근거'!O21 -> 0.0625 | J25: ='7.MP산출근거'!D47 -> 391265 | K25: =F9*I25*J25 -> 73362.188 | L25: =H25+K25 -> 73362.188 | M25: MP산출근거 6항 참조 | O25: =I25*F9 -> 0.1875
C26: Smart End Device SET-UP | D26: S/W 시험사 | E26: 인 | I26: ='7.MP산출근거'!O23 -> 0.0625 | J26: ='7.MP산출근거'!D47 -> 391265 | K26: =F10*I26*J26 -> 24454.062 | L26: =H26+K26 -> 24454.062 | M26: MP산출근거 7항 참조
C27: Smart LED Detector Device SET-UP | D27: S/W 시험사 | E27: 인 | I27: ='7.MP산출근거'!O27 -> 0.375 | J27: ='7.MP산출근거'!D47 -> 391265 | K27: =F14*I27*J27 -> 146724.38 | L27: =H27+K27 -> 146724.38 | M27: MP산출근거 9항 참조
D28: 소 계 | H28: =SUM(H8:H27) -> 1870000 | K28: =SUM(K8:K27) -> 548167.38 | L28: =SUM(L8:L27) -> 2418167.4
B29: 2. 원격감시시스템 배관/배선작업
C30: 합성수지 전선관(CD) | D30: 16mm | E30: M | F30: 60 | G30: 300 | H30: =F30*G30 -> 18000 | L30: =H30+K30 -> 18000
C31: 합성수지 전선관 커넥터 | D31: 16mm | E31: EA | F31: 20 | G31: 200 | H31: =F31*G31 -> 4000 | L31: =H31+K31 -> 4000
C32: 절연난연 PVC 시스케이블 | D32: 0.6/1kv F-CV 3Cx1.5mm | E32: M | F32: 30 | G32: 1100 | H32: =F32*G32 -> 33000 | L32: =H32+K32 -> 33000
C33: 신호용 케이블 | D33: 4C x 0.5mm | E33: M | F33: 30 | G33: 650 | H33: =F33*G33 -> 19500 | L33: =H33+K33 -> 19500
C34: 신호용 케이블 | D34: 6C x 0.5mm | E34: M | F34: 10 | G34: 1930 | H34: =F34*G34 -> 19300 | L34: =H34+K34 -> 19300
C35: 신호용 케이블 | D35: 10C x 0.5mm | E35: M | F35: 10 | G35: 4900 | H35: =F35*G35 -> 49000 | L35: =H35+K35 -> 49000
C36: 소형계전기 | D36: Relay AC24V 4a4c (SOCKET 포함) | E36: EA | F36: 0 | G36: 5000 | H36: =F36*G36 -> 0 | L36: =H36+K36 -> 0 | M36: 자재납품(단순설치용)
C37: 소형계전기 | D37: Relay DC24V 4a4c (SOCKET 포함) | E37: EA | F37: 0 | G37: 5000 | H37: =F37*G37 -> 0 | L37: =H37+K37 -> 0 | M37: 자재납품(단순설치용)
C38: 소형계전기 | D38: Relay AC220V 4a4c (SOCKET 포함) | E38: EA | F38: 0 | G38: 5000 | H38: =F38*G38 -> 0 | L38: =H38+K38 -> 0 | M38: 자재납품(단순설치용)
C39: HI-BOX (Relay SET-UP) | D39: 190(W) X 280 (H) X 180(D) | E39: EA | F39: 0 | G39: 15000 | H39: =F39*G39 -> 0 | L39: =H39+K39 -> 0 | M39: 자재납품(단순설치용)
C40: HI-BOX (SGW 외부시공 방수용) | D40: 300(W) X 400 (H) X 180(D) | E40: EA | F40: 0 | G40: 25000 | H40: =F40*G40 -> 0 | L40: =H40+K40 -> 0
C41: 수위감지센서 | D41: YQ-1 A/B접점 | E41: EA | F41: 0 | G41: 13000 | H41: =F41*G41 -> 0 | L41: =H41+K41 -> 0
C42: 수위감지센서 무게추 | D42: DSF-014 | E42: EA | F42: 0 | G42: 15000 | H42: =F42*G42 -> 0 | L42: =H42+K42 -> 0
...

Sheet 6.일위대가 산출근거
B2: 일위대가 산출근거
B6: 1. 옥내배선 | H6: (M당)
B7: 품 명/직 종 | C7: 단가 | D7: 6㎟ 이하 | F7: 16㎟ 이하 | H7: 비고
D8: M/P | E8: 금액 | F8: M/P | G8: 금액
B9: 내선전공 | C9: ='7.MP산출근거'!$D$42 -> 259089 | D9: 0.01 | E9: =C9*D9 -> 2590.89 | F9: 0.023 | G9: =C9*F9 -> 5959.047
B10: 합 계 | E10: =E9 -> 2590.89 | G10: =G9 -> 5959.047
B11: 1) 옥내케이블 관내배선은 "전력케이블 구내설치" 준용
B12: 2) 통신장비 전원인입용 단순공사로 품셈의 50% 적용.
B14: 2. 제어용 케이블 설치 | L14: (M당)
B15: 품 명/직 종 | C15: 단가 | D15: 4C 2.5㎟ 이하 | F15: 6C 2.5㎟ 이하 | H15: 10C 2.5㎟ 이하 | J15: 20C 2.5㎟ 이하 | L15: 비고
D16: M/P | E16: 금액 | F16: M/P | G16: 금액 | H16: M/P | I16: 금액 | J16: M/P | K16: 금액
B17: 저압케이블전공 | C17: ='7.MP산출근거'!D43 -> 272282 | D17: 0.026 | E17: =C17*D17 -> 7079.332 | F17: 0.035 | G17: =C17*F17 -> 9529.87 | H17: 0.048 | I17: =C17*H17 -> 13069.536 | J17: 0.074 | K17: =C17*J17 -> 20148.868
B18: 합 계 | E18: =E17 -> 7079.332 | G18: =G17 -> 9529.87 | I18: =I17 -> 13069.536 | K18: =K17 -> 20148.868
B19: 1) 다음 작업 포함기준
B20: ① 케이블 부설 정돈, 청소.
B21: ② 단자처리, 도입선 넣기, 결선, Mark 취부 포함.
B22: 2) 통신장비 신호선 인입용 단순공사로 품셈의 50% 적용.
B24: 3. 전선관 배관 | P24: (M당)
B25: 품 명/직 종 | C25: 단가 | D25: 합성수지 16mm | F25: 합성수지 22mm | H25: 후강 16mm | J25: 후강 22㎜ | L25: 금속가요 16mm | N25: 금속가요 22㎜ | P25: 비고
D26: M/P | E26: 금액 | F26: M/P | G26: 금액 | H26: M/P | I26: 금액 | J26: M/P | K26: 금액 | L26: M/P | M26: 금액 | N26: M/P | O26: 금액
B27: 내선전공 | C27: ='7.MP산출근거'!$D$42 -> 259089 | D27: 0.05 | E27: =$C$27*D27 -> 12954.45 | F27: 0.06 | G27: =$C$27*F27 -> 15545.34 | H27: 0.08 | I27: =$C$27*H27 -> 20727.12 | J27: 0.11 | K27: =$C$27*J27 -> 28499.79 | L27: 0.044 | M27: =$C$27*L27 -> 11399.916 | N27: 0.059 | O27: =$C$27*N27 -> 15286.251
B28: 합 계 | E28: =E27 -> 12954.45 | G28: =G27 -> 15545.34 | I28: =I27 -> 20727.12 | K28: =K27 -> 28499.79 | M28: =M27 -> 11399.916 | O28: =O27 -> 15286.251
B29: 1) 폴리에틸렌 전선관 및 합성수지제 가요전선관(CD관)은 합성수지 전선관 품의 80% 다만, 지름이 100mm 이상의 직관은 100%
B30: 2) 소모 재료비는 본품에 포함되어 있다.
B31: 3) 계수, 보조재의 제작 및 설치품 포함한다.
B32: 4) 통신장비 전원인입용 노출배관 단순공사로 품셈의 30% 적용.
B34: 4. 차단기 및 개폐기 설치 | F34: (개)
B35: 품 명/직 종 | C35: 단가 | D35: 배선용차단기 30AF | F35: 비고
D36: M/P | E36: 금액
B37: 내선전공 | C37: ='7.MP산출근거'!$D$42 -> 259089 | D37: 0.19 | E37: =C37*D37 -> 49226.91
B38: 합 계 | E38: =E37 -> 49226.91
B39: 1) 3P 단투 기준, 1P 50%, 2P 70%, 4P는 130%
B40: 2) 접속, 시험 품 포함
B41: 3) 철거 50%, 재사용 철거 80%
B42: 4) 통신장비 전원인입용 단순공사로 품셈의 50% 적용.
B44: 5. 금속덕트 설치 | F44: (M당)
B45: 품 명/직 종 | C45: 단가 | D45: 60mm x 30mm 이하 | F45: 비고
D46: M/P | E46: 금액
B47: 내선전공 | C47: ='7.MP산출근거'!$D$42 -> 259089 | D47: 0.15 | E47: =$C$47*D47 -> 38863.35
B48: 합 계 | E48: =E47 -> 38863.35
...

Sheet 7.MP산출근거
B2: M/P 산출근거
B4: ='3.공사예산내역서(갑)'!$B$4 -> 공사명 : 펄어비스 안양오피스 원격감시시스템 구축공사 | Q4: ='3.공사예산내역서(갑)'!$H$4 -> (작성일자:`22년 10월 19일)
B6: 공 정 | D6: 품 명(직 종) | E6: 인원 | F6: 소요시간(분) | G6: 산출식 | O6: M/P | P6: 비 고
B7: ▶ OOO 원격감시시스템 설치공사
C8: 원격감시시스템 장비설치
B9: 1 | C9: Smart Gateway | D9: 내선전공 | E9: 2 | F9: 30 | G9: ( | H9: =E9 -> 2 | I9: 인 Ⅹ | J9: =F9 -> 30 | K9: 분/ | L9: 480 | M9: 분 ) = | N9: =H9*J9/L9 -> 0.125 | O9: =N9 -> 0.125
C10: (전원포설 작업포함)
B11: 2 | C11: Smart End Device | D11: 내선전공 | E11: 2 | F11: 30 | G11: ( | H11: =E11 -> 2 | I11: 인 Ⅹ | J11: =F11 -> 30 | K11: 분/ | L11: 480 | M11: 분 ) = | N11: =H11*J11/L11 -> 0.125 | O11: =N11 -> 0.125
C12: (전원포설 작업포함)
B13: 3 | C13: Smart Mesh Router | D13: 내선전공 | E13: 1 | F13: 20 | G13: ( | H13: =E13 -> 1 | I13: 인 Ⅹ | J13: =F13 -> 20 | K13: 분/ | L13: 480 | M13: 분 ) = | N13: =H13*J13/L13 -> 0.041666667 | O13: =N13 -> 0.041666667
C14: (전원포설 작업포함)
B15: 4 | C15: Smart LED Detector Device | D15: 내선전공 | E15: 1 | F15: 120 | G15: ( | H15: =E15 -> 1 | I15: 인 Ⅹ | J15: =F15 -> 120 | K15: 분/ | L15: 480 | M15: 분 ) = | N15: =H15*J15/L15 -> 0.25 | O15: =N15 -> 0.25
C16: (전원포설 작업포함)
B17: 5 | C17: Smart CDS Sensor Module | D17: H/W 시험사 | E17: 1 | F17: 30 | G17: ( | H17: =E17 -> 1 | I17: 인 Ⅹ | J17: =F17 -> 30 | K17: 분/ | L17: 480 | M17: 분 ) = | N17: =H17*J17/L17 -> 0.0625 | O17: =N17 -> 0.0625
C18: (전원포설 작업포함)
O19: =SUM(O7:O18) -> 0.60416667
C20: 원격감시시스템 SET-UP
B21: 6 | C21: Smart Gateway | D21: S/W 시험사 | E21: 1 | F21: 30 | G21: ( | H21: =E21 -> 1 | I21: 인 Ⅹ | J21: =F21 -> 30 | K21: 분/ | L21: 480 | M21: 분 ) = | N21: =H21*J21/L21 -> 0.0625 | O21: =N21 -> 0.0625
C22: (GUI 셋팅, SERVER 연동 작업포함)
B23: 7 | C23: Smart End Device | D23: S/W 시험사 | E23: 1 | F23: 30 | G23: ( | H23: =E23 -> 1 | I23: 인 Ⅹ | J23: =F23 -> 30 | K23: 분/ | L23: 480 | M23: 분 ) = | N23: =H23*J23/L23 -> 0.0625 | O23: =N23 -> 0.0625
C24: (GUI 셋팅, SERVER 연동 작업포함)
B25: 8 | C25: Smart Mesh Router | D25: S/W 시험사 | E25: 1 | F25: 30 | G25: ( | H25: =E25 -> 1 | I25: 인 Ⅹ | J25: =F25 -> 30 | K25: 분/ | L25: 480 | M25: 분 ) = | N25: =H25*J25/L25 -> 0.0625 | O25: =N25 -> 0.0625
C26: (GUI 셋팅, 로컬연동 작업포함)
B27: 9 | C27: Smart LED Detector Device | D27: S/W 시험사 | E27: 1 | F27: 180 | G27: ( | H27: =E27 -> 1 | I27: 인 Ⅹ | J27: =F27 -> 180 | K27: 분/ | L27: 480 | M27: 분 ) = | N27: =H27*J27/L27 -> 0.375 | O27: =N27 -> 0.375
C28: (Arduino 셋팅, 로컬연동 작업포함)
O29: =SUM(O20:O28) -> 0.5625
C30: 빌딩자동제어 연동작업
B31: 10 | C31: 회로결선 및 연동 테스트 | D31: H/W 시험사 | E31: 1 | F31: 30 | G31: ( | H31: =E31 -> 1 | I31: 인 Ⅹ | J31: =F31 -> 30 | K31: 분/ | L31: 480 | M31: 분 ) = | N31: =H31*J31/L31 -> 0.0625 | O31: =N31 -> 0.0625
O32: =SUM(O30:O31) -> 0.0625
B33: ▣대가 산출기준
B34: 1)상기 인건비는 `22년 하반기 노임(공사부문)단가 기준함.
B35: 2)1일 8시간(480분) 기준함.
B36: 3)자재비는 한국물가정보 및 MRO 단가 기준임.
B37: 4)잡자재 및 공구손료는 별도 계산함.
B38: 6)상기 7항은 원격감시시스템 장비수량 별 기준작업임.
B40: ▣인건비 근거 | P40: (단위:원,VAT별도)
C41: 직 종 | D41: 단 가 | E41: 해설
C42: 내선전공 | D42: 259089 | E42: 옥내전선관, 배선 및 등기구류 설비의 시공 및 보수에 종사하는 사람
C43: 저압케이블전공 | D43: 272282 | E43: 저압케이블 및 제어용 케이블 설비의 시공 및 보수에 종사하는 사람(교류 600V이하, 직류 750V이하)
C44: 계장공 | D44: 268571 | E44: 기계, 급배수, 전기, 가스, 위생, 냉난방 및 기타공사에 있어서 계기(공업제어장치, 공업계측 및 컴퓨터, 자동제어장치 등)를 전문으로 설치, 부착 및 점검하는 사람
...

Sheet 8.공사물량산출서
B2: 물량산출서
B4: ='3.공사예산내역서(갑)'!$B$4 -> 공사명 : 펄어비스 안양오피스 원격감시시스템 구축공사 | I4: ='3.공사예산내역서(갑)'!$H$4 -> (작성일자:`22년 10월 19일)
B6: NO | C6: 항 목 | D6: 규 격 | E6: 단 위 | F6: 수 량 | G6: 산출근거 | I6: 비 고
C7: 1.원격감시시시스템 구축공사
B8: 1 | C8: ='5.일위대가'!C9 -> Smart Gateway | D8: ='5.일위대가'!D9 -> WI-SUN/LECIM, S&I RMS연동, DI 8CH | E8: ='5.일위대가'!E9 -> 대 | F8: ='5.일위대가'!F9 -> 3
B9: 2 | C9: ='5.일위대가'!C10 -> Smart End Device | D9: ='5.일위대가'!D10 -> WI-SUN/LECIM, 4CH I/O | E9: ='5.일위대가'!E10 -> 대 | F9: ='5.일위대가'!F10 -> 1
B10: 3 | C10: ='5.일위대가'!C11 -> Smart DI Module | D10: ='5.일위대가'!D11 -> DI INPUT [I/O 4ch] | E10: ='5.일위대가'!E11 -> EA | F10: ='5.일위대가'!F11 -> 0
B11: 4 | C11: ='5.일위대가'!C12 -> Smart DO Module | D11: ='5.일위대가'!D12 -> Relay OUTPUT [I/O 4ch] | E11: ='5.일위대가'!E12 -> EA | F11: ='5.일위대가'!F12 -> 0
B12: 5 | C12: ='5.일위대가'!C13 -> Smart AI Module | D12: ='5.일위대가'!D13 -> VDC/ADC INPUT [I/O 4ch] | E12: ='5.일위대가'!E13 -> EA | F12: ='5.일위대가'!F13 -> 0
B13: 6 | C13: ='5.일위대가'!C14 -> Smart LED Detector Device | D13: ='5.일위대가'!D14 -> Arduino Nano 10CH Board | E13: ='5.일위대가'!E14 -> 대 | F13: ='5.일위대가'!F14 -> 1
B14: 7 | C14: ='5.일위대가'!C15 -> Smart CDS Sensor Module | D14: ='5.일위대가'!D15 -> High sensitivity CDS/3D Printing Cap | E14: ='5.일위대가'!E15 -> 대 | F14: ='5.일위대가'!F15 -> 5
B15: 8 | C15: ='5.일위대가'!C16 -> Mini DC-UPS | D15: ='5.일위대가'!D16 -> MPS-L24 / DC24V 3.0A Adapter 포함 | E15: ='5.일위대가'!E16 -> 대 | F15: ='5.일위대가'!F16 -> 0
B16: 9 | C16: ='5.일위대가'!C17 -> AC UPS | D16: ='5.일위대가'!D17 -> APC BACK-UPS 650 (BX650LI-GR) | E16: ='5.일위대가'!E17 -> 대 | F16: ='5.일위대가'!F17 -> 0
B17: 10 | C17: ='5.일위대가'!C18 -> Modbus RTU DI Board | D17: ='5.일위대가'!D18 -> KM6054[I/O 13ch] - Digital INPUT | E17: ='5.일위대가'!E18 -> EA | F17: ='5.일위대가'!F18 -> 0
B18: 11 | C18: ='5.일위대가'!C19 -> Modbus RTU AI Board | D18: ='5.일위대가'!D19 -> KM6412[I/O 8ch] - Analog INPUT | E18: ='5.일위대가'!E19 -> EA | F18: ='5.일위대가'!F19 -> 0
B19: 12 | C19: ='5.일위대가'!C20 -> NTC 저항식 온도센서 | D19: ='5.일위대가'!D20 -> FS-200N | E19: ='5.일위대가'!E20 -> EA | F19: ='5.일위대가'!F20 -> 0
B20: 13 | C20: ='5.일위대가'!C30 -> 합성수지 전선관(CD) | D20: ='5.일위대가'!D30 -> 16mm | E20: ='5.일위대가'!E30 -> M | F20: ='5.일위대가'!F30 -> 60
B21: 14 | C21: ='5.일위대가'!C31 -> 합성수지 전선관 커넥터 | D21: ='5.일위대가'!D31 -> 16mm | E21: ='5.일위대가'!E31 -> EA | F21: ='5.일위대가'!F31 -> 20
B22: 15 | C22: ='5.일위대가'!C32 -> 절연난연 PVC 시스케이블 | D22: ='5.일위대가'!D32 -> 0.6/1kv F-CV 3Cx1.5mm | E22: ='5.일위대가'!E32 -> M | F22: ='5.일위대가'!F32 -> 30
B23: 16 | C23: ='5.일위대가'!C33 -> 신호용 케이블 | D23: ='5.일위대가'!D33 -> 4C x 0.5mm | E23: ='5.일위대가'!E33 -> M | F23: ='5.일위대가'!F33 -> 30
B24: 17 | C24: ='5.일위대가'!C34 -> 신호용 케이블 | D24: ='5.일위대가'!D34 -> 6C x 0.5mm | E24: ='5.일위대가'!E34 -> M | F24: ='5.일위대가'!F34 -> 10
B25: 18 | C25: ='5.일위대가'!C35 -> 신호용 케이블 | D25: ='5.일위대가'!D35 -> 10C x 0.5mm | E25: ='5.일위대가'!E35 -> M | F25: ='5.일위대가'!F35 -> 10
B26: 19 | C26: ='5.일위대가'!C36 -> 소형계전기 | D26: ='5.일위대가'!D36 -> Relay AC24V 4a4c (SOCKET 포함) | E26: ='5.일위대가'!E36 -> EA | F26: ='5.일위대가'!F36 -> 0
B27: 20 | C27: ='5.일위대가'!C37 -> 소형계전기 | D27: ='5.일위대가'!D37 -> Relay DC24V 4a4c (SOCKET 포함) | E27: ='5.일위대가'!E37 -> EA | F27: ='5.일위대가'!F37 -> 0
B28: 21 | C28: ='5.일위대가'!C38 -> 소형계전기 | D28: ='5.일위대가'!D38 -> Relay AC220V 4a4c (SOCKET 포함) | E28: ='5.일위대가'!E38 -> EA | F28: ='5.일위대가'!F38 -> 0
B29: 22 | C29: ='5.일위대가'!C39 -> HI-BOX (Relay SET-UP) | D29: ='5.일위대가'!D39 -> 190(W) X 280 (H) X 180(D) | E29: ='5.일위대가'!E39 -> EA | F29: ='5.일위대가'!F39 -> 0
B30: 23 | C30: ='5.일위대가'!C40 -> HI-BOX (SGW 외부시공 방수용) | D30: ='5.일위대가'!D40 -> 300(W) X 400 (H) X 180(D) | E30: ='5.일위대가'!E40 -> EA | F30: ='5.일위대가'!F40 -> 0
B31: 24 | C31: ='5.일위대가'!C41 -> 수위감지센서 | D31: ='5.일위대가'!D41 -> YQ-1 A/B접점 | E31: ='5.일위대가'!E41 -> EA | F31: ='5.일위대가'!F41 -> 0
B32: 25 | C32: ='5.일위대가'!C42 -> 수위감지센서 무게추 | D32: ='5.일위대가'!D42 -> DSF-014 | E32: ='5.일위대가'!E42 -> EA | F32: ='5.일위대가'!F42 -> 0
B33: 26 | C33: ='5.일위대가'!C52 -> 넘버링튜브 | D33: ='5.일위대가'!D52 -> 1.5SQ 백색 | E33: M | F33: ='5.일위대가'!F52 -> 3
B34: 27 | C34: ='5.일위대가'!C53 -> 압착단자 | D34: ='5.일위대가'!D53 -> 15SQ x 3mm Y형 | E34: EA | F34: ='5.일위대가'!F53 -> 100
B35: 28 | C35: ='5.일위대가'!C54 -> 압착단자 | D35: ='5.일위대가'!D54 -> 15SQ x 3mm PIN형 | E35: EA | F35: ='5.일위대가'!F54 -> 100
B36: 29 | C36: 기타잡자재 | D36: 재료비의 3% 이내 | E36: 식 | F36: 1
B37: 30 | C37: 공구손료 | D37: 인건비의 3% 이내 | E37: 식 | F37: 1
B38: 31 | C38: 출장경비 | E38: 식 | F38: 1
B39: 32 | C39: 공사보험료 | D39: 안전관리비/산재보험료/고용보험료/국민건강보험료/국민연금보험료/노인장기요양 보험료 | E39: 식 | F39: 각1
B40: 33 | C40: 일반관리비/이윤 | E40: 식 | F40: 1

Sheet 9.공사업체 출장경비
B2: 공사업체 출장경비 기준산출내역
L3: ='3.공사예산내역서(갑)'!$H$4 -> (작성일자:`22년 10월 19일)
L4: (단위:원, VAT별도)
B5: 출발지 | C5: 도착지 | D5: 작업일수 | E5: 작업인원 | F5: 왕복 거리(Km) | G5: 왕복 유류비 | H5: 왕복 교통비 | I5: 숙박비 | J5: 합계 | K5: 출장경비 | L5: 비고
B6: 업체소제지 (성남) | C6: 경기 안양시 동안구 시민대로327번길 24 | D6: 1 | E6: 2 | F6: =F7*2 -> 0 | G6: =G7*2 -> 0 | H6: =H7*2 -> 0 | I6: =I7 -> 0 | J6: =((G6+H6)*D6)+I6 -> 0 | K6: =ROUNDUP(J6*1.3,-3) -> 0
B7: 1)제주도 지역은 별도협의 산출. | E7: 편도기준입력 | F7: 0 | G7: 0 | H7: 0
B8: 2)차종은 중형 경유 기준임. (2020 그랜드 스타렉스, 2.5 디젤 어반 9인승 공인연비 자동 9.4 km/ℓ (4등급))
B9: 3)유류비는 작성일기준 단가적용
B10: 4)왕복 거리는 네이버 지도 추천 기준임.
B11: 5)작업공수 합계가 1일 초과할 경우 숙박비 적용 (2인 1실 50,000원)
B12: 6)숙박비는 별도협의에 따라 제외가능
B13: 7)출발지 기준 50Km 이상만 출장지역으로 인정
B14: 8)출장경비는 차량 감가상각비/유지관리비 반영하여 합계금액에 1.3배 적용함.
B36: ※ 네이버 지도 추천거리 화면 캡처 후 그림형식>그림압축>전자메일 기준 적용

Sheet 첨부2_출장경비
C2: 출장경비 기준산출내역
K3: (작성일자:`19년 01월 21일)
K4: (단위:원, VAT별도)
C5: 권역 | D5: 출발지 | E5: 도착 기준점 | F5: 왕복 거리(Km) | G5: 왕복 유류비 | H5: 왕복 교통비 | I5: 합계 | J5: 출장경비 | K5: 비고
C6: 경기도 | D6: 성남시 | E6: 연천군청 | F6: 200 | G6: 30000 | H6: 8600 | I6: =G6+H6 -> 38600 | J6: 50000 | K6: ※ 경기도 제외지역 공사업체 사업장주소 기준 50Km 미만 소재지 : 경기도 성남시 ※ 출장경비 산출기준 (왕복유류비+교통비) x 1.3
C7: 강원도 | E7: 삼척시청 | F7: 480 | G7: 60000 | H7: 24600 | I7: =G7+H7 -> 84600 | J7: 100000
C8: 충청남도 | E8: 서천군청 | F8: 360 | G8: 45000 | H8: 21800 | I8: =G8+H8 -> 66800 | J8: 100000
C9: 충청북도 | E9: 장수군청 | F9: 466 | G9: 60000 | H9: 24600 | I9: =G9+H9 -> 84600 | J9: 100000
C10: 경상북도 | E10: 경주시청 | F10: 620 | G10: 80000 | H10: 34000 | I10: =G10+H10 -> 114000 | J10: 150000
C11: 경상남도 | E11: 거제시청 | F11: 760 | G11: 95000 | H11: 36600 | I11: =G11+H11 -> 131600 | J11: 200000
C12: 전라북도 | E12: 순창군청 | F12: 500 | G12: 65000 | H12: 31800 | I12: =G12+H12 -> 96800 | J12: 150000
C13: 전라남도 | E13: 완도군청 | F13: 830 | G13: 110000 | H13: 38600 | I13: =G13+H13 -> 148600 | J13: 200000
C14: 1)제주도 지역은 별도협의.
C15: 2)도착기준점은 권역별 최장 거리지역 기준임.
C16: 3)차종은 중형 경유 기준임.
C17: 4)유류비는 작성일기준 단가적용
